Workbook

Sheet Claude Log
A1: Turno | B1: Fecha | C1: Solicitud del usuario | D1: Acción realizada | E1: Detalle | F1: Resultado
A2: 1 | B2: 46297 | C2: Carga del prompt de trabajo del modelo Maquila ECOSTAR y pedido implícito de ejecutar la Tarea 1: validar que Excel reproduce los resultados de referencia obtenidos en LibreOffice. | D2: Validación de solo lectura de Resultados!C6:D30, Control!A4:F24 y escaneo de fórmulas de todo el libro. No se modificó ninguna celda del modelo. | E2: 16 de 17 indicadores de Resultados!D coinciden dentro de tolerancia. Diferencia: 'Meses con brecha' = 0 vs 12 esperado. Causa: criterios COUNTIF con punto decimal (">0.5") que Excel es-PY no interpreta como número. Celdas afectadas: Resultados!C23, Resultados!D23, Control!C17 y Productos!N53:N64 (c_CapExceso). Verificado con COUNTIF(...;">0,5") = 12. | F2: Diferencia informada, NO corregida (requiere autorización y réplica en generar_plantilla.py). Control muestra 1 alerta (C14) en lugar de 2; falta C13 por el mismo motivo. Balance de control = 0 en C30 y D30.
A3: 2 | B3: 46297 | C3: Autorizó la corrección de las 15 celdas con criterio de texto ">0.5" (excepción puntual a la regla de no editar Resultados/Control) y cargó la guía de uso paso a paso (Prompt_Guia_Uso_ECOSTAR_v2.md). | D3: Corrección regional de criterios (15 celdas). Reemplazo de COUNTIF(rango;">0.5") por SUMPRODUCT(--(rango>0,5)) en Resultados!C23, Resultados!D23, Control!C17 y Productos!N53:N64. Prueba temporal de la alerta C10 (escenario V4) y restauración. | E3: Fórmulas originales: Resultados!C23 =COUNTIF(Calculo!$F$130:$ES$130;">0.5") | Resultados!D23 y Control!C17 =COUNTIF(Calculo!$F$260:$ES$260;">0.5") | Productos!N53:N64 =COUNTIF(D53:M53;">0.5") ... =COUNTIF(D64:M64;">0.5"). Confirmado antes de editar: Calculo!A130=P.BRECHA, A260=V.BRECHA, Productos!N52='Años con exceso'. Prueba C10: Productos!D37:M38 = D21:M22*1,1 → C10=16 y REVISAR; restaurado a =D21...=M22. | F3: Validado: C23=12, D23=12, Control!C17=12 con E17=REVISAR, controles en REVISAR=2 (C13 y C14), Productos!N53:N64=0. Indicadores sin cambio: VAN proyecto 6.989.922, VAN socios 3.695.678, aporte adicional 311.740, balance 0 en C30 y D30. Criterio adoptado: no usar decimales en criterios de texto de COUNTIF/SUMIF/MAXIFS/MINIFS; usar SUMPRODUCT. Pendiente: replicar en generar_plantilla.py.
A4: 3 | B4: 46297 | C4: Pidió ampliar el modelo de 12 a 25 productos, por la posibilidad de ampliar la producción a distintos tipos de unidades. | D4: Mapeo de alcance, sin modificar el modelo. Se fremó la ejecución directa por ser cambio estructural (regla propia del usuario: va al generador). | E4: El producto es una dimensión que atraviesa 12 bloques en 5 hojas: Productos (4 bloques), Reales (2), Calculo (4: P.u, P.s, V.u, V.s) y Resultados (2). 12 bloques x 13 filas = 156 filas nuevas; en Calculo ~7.750 fórmulas. 17 nombres definidos a redimensionar. Se planteó además la duda de diseño: productos individuales vs familias (16 celdas de entrada por producto). | F4: Se ofrecieron 3 opciones. ERRATA: en ese turno se informó al usuario que el log estaba registrado y no lo estaba; esta fila lo regulariza.
A5: 4 | B5: 46297 | C5: Eligió la opción recomendada: recibir la especificación técnica completa para aplicarla en generar_plantilla.py y después validar el libro regenerado. | D5: Creada la hoja 'Esp_25Productos' con la especificación en 6 secciones. No se modificó ninguna celda del modelo. | E5: Secciones: (0) constante N_PRODUCTOS 12→25 y convención de índice; (1) los 12 bloques con filas hoy, filas con N=25 y fórmula semilla de la fila i; (2) los 17 nombres definidos con rango nuevo; (3) desplazamiento de filas en Calculo (+26 bloque P, +52 bloque V) y los 6 SUMPRODUCT de materiales que NO se corrigen al insertar filas; (4) desplazamiento en Resultados; (5) checklist de 12 validaciones; (6) riesgos. | F5: Especificación entregada en la hoja Esp_25Productos. Pendiente del usuario: aplicarla en el generador y definir si los 25 son productos individuales o familias. Sigue pendiente replicar la corrección regional de criterios en el script.
A6: 5 | B6: 46297 | C6: Confirmó que los 25 productos son individuales (no familias) y pidió el prompt listo para aplicar el cambio en el generador de plantillas. | D6: Redactado el prompt completo para el generador y exportado como Prompt_Generador_25Productos.md. No se modificó ninguna celda del modelo. | E6: 8 secciones: contexto, objetivo (N_PRODUCTOS 12→25 individuales), reglas de trabajo, especificación de los 12 bloques con fórmulas semilla y los 17 nombres definidos, lo que hay que reindexar a mano (bloque P +26 filas, bloque V +52, y los 6 SUMPRODUCT de materiales como punto crítico de error silencioso), la corrección regional de criterios a replicar, la validación de 15 indicadores más 3 pruebas de reindexado, y qué se espera de vuelta (diff antes de aplicar). | F6: Prompt entregado en chat y como archivo. Pendiente del usuario: aplicarlo en generar_plantilla.py y traer el libro regenerado para validar. La hoja Esp_25Productos queda como documentación de respaldo en el libro.
A7: 6 (Claude Code) | B7: 46297 | C7: Aplicar en generar_plantilla.py el prompt de ampliación a 25 productos (Prompt_Generador_25Productos). | D7: N_PRODUCTOS 12→25 (constante única: todos los bloques ya se emitían en bucle, sin filas literales). Ventas totales como SUM. Textos «Hasta 25». Corrección regional ya estaba en el generador (commit d3499ff). Libro regenerado: commit 74883c3. | E7: Validado en LibreOffice: C6:D30 y Control idénticos a 12 productos; nombres y filas = Esp_25Productos; productos 3, 13 y 25: Δventas y Δmateriales exactos (P y V); volumen ×1,10 → C10=16; producto sin precio → C11; 0 criterios con decimales; meses reales no cambian con el escenario. | F7: Hojas Claude Log y Esp_25Productos copiadas desde v3. Pendiente: validación de la sección 7 en Excel.
A8: 7 (Claude Code) | B8: 46322 | C8: Agregar al modelo una guía de carga paso a paso dentro del Excel. | D8: Nueva hoja Guia_Carga desde el generador (la heredan Alianza y la tercera maquila): 28 pasos en 5 etapas (alta, presupuesto, vigente, cierre mensual, revisión) con vínculo a la celda, fuente, criterio, estado automático y columnas Hecho/Fecha/Responsable. Nombres nuevos: g_Mes, g_Pendientes, c_C01..c_C16. Sin cambios de cálculo. | E8: Validado en LibreOffice: 0 errores; indicadores C6:D30 y Control idénticos a la v4; ciclo de cierre probado (mes 1 cargado → «Listo para cerrar: poner 1»; al cerrar, la guía pasa al mes 2). | F8: Libro v5 = v4 + hoja Guia_Carga. Si tu Claude Log local tiene turnos posteriores al 6, copialos a esta hoja.
A9: 8 (Claude Code) | B9: 46322 | C9: Proyección detallada a 2 años (mes a mes) y vista anual a 10 años; revisión del plan anual o bienal. Ventana móvil; detalle de volúmenes, precios, costos de materiales, personal, costos fijos y TC. | D9: Nueva hoja Detalle_24m (misma grilla que Reales; celda vacía = supuesto anual; solo se usa en la ventana Corte+1 a Corte+n_Ventana). Nueva hoja Proyeccion_24m (24 meses vigente vs presupuesto, totales por año de ventana). Inicio C14:C17: n_Ventana, versión del plan, fecha de revisión, frecuencia. Guía: sección F (pasos 29-37). Presupuesto original sin cambios (anual). | E9: Validado en LibreOffice: con detalle vacío, 0 celdas distintas en Calculo frente a la v5; 25 pruebas de detalle OK (volumen, precio, materiales, personal, fijos, TC, ventana móvil con cierre, escenario, ventana 12); balance 0. | F9: Libro v6 = v5 + Detalle_24m + Proyeccion_24m + datos de revisión. Celdas de Calculo, Resultados y Control sin cambios de posición.
A10: 9 (Claude en Excel) | B10: 46322 | C10: Validar en Excel el modelo v6 siguiendo el plan de evaluación paso a paso (Prompt_Claude_Excel_ECOSTAR_v6.md). Paso 0 — Preparación. | D10: Verificación de estructura y modo de cálculo; recálculo completo (fullRebuild) y lectura de Resultados!D6:D30. | E10: 14 hojas presentes y en el orden esperado; cálculo en Automático; Claude Log con historial hasta el turno 8. Inicio: C13=Vigente, C14=24, C15=Plan CIE–PERG Oct-2025, C17=Anual; C10, C11, C12 y C16 vacías. Sin modificaciones al libro. | F10: Paso 0 OK. Caso base confirmado tras recálculo: VAN del proyecto 6.989.922 y balance 0. A la espera de «seguir» para el Paso 1.
A11: 10 (Claude en Excel) | B11: 46322 | C11: Paso 1 — Integridad del libro base: comparar los 25 indicadores de Resultados!D6:D30 con los valores validados en LibreOffice, revisar Control y los nombres definidos. | D11: Lectura (sin edición) de Resultados!B6:D30 y Control!A5:F22; verificación de los nombres Prod_Nombre, Vol_O, Vol_V y c_CapExceso; barrido de fórmulas de las 14 hojas buscando criterios de texto con decimales. | E11: 19 de 19 indicadores con valor esperado coinciden dentro de tolerancia (±1 USD / ±0,01). Control: solo C13 (brecha de caja, 12 meses) y C14 (mes real de inicio sin cargar) en REVISAR; fila 22 = 2. Nombres a 25 productos: Prod_Nombre=Productos!B6:B30, Vol_O=D34:M58, Vol_V=D63:M87, c_CapExceso=N92:N116. Criterios de texto con decimales en fórmulas: 0 (las 6 coincidencias del barrido son texto de Claude Log y Esp_25Productos, no fórmulas). | F11: Paso 1 OK, sin diferencias. Libro sin modificaciones; VAN del proyecto 6.989.922 y balance 0. A la espera de «seguir» para el Paso 2 (X2, X3, V4).
A12: 11 (Claude en Excel) | B12: 46322 | C12: Paso 2 — Estructura de 25 productos: ejecutar los escenarios X2, X3 y V4 (X1 omitido por ser opcional y modificar el presupuesto). | D12: X2: alta de 3 productos de prueba en las filas 8, 18 y 30 (B, C y H/J/L/N vigentes) con volúmenes vigentes D65:M65=1.200, D75:M75=600, D87:M87=300. X3: B30='Sin precio', C30='u', J30=10, D87:M87=500 (H30 sin tocar). V4: D63:M64 = D34:M35 × 1,10. Un caso por vez, con restauración intermedia. | E12: Originales anotados antes de editar: B8/B18/B30 y C8/C18/C30 vacías; H/J/L/N de las filas 8, 18 y 30 con fórmulas =G/=I/=K/=M; D63:M63 ==D34.., D64:M64 ==D35.., D65:M65 ==D36.., D75:M75 ==D46.., D87:M87 ==D58... RESULTADOS: X2 ventas 83.419.512,36 (delta +2.197.064,63), materia prima + insumos +933.279,30, VAN proyecto 7.641.309,22, VAN socios 4.132.976,38, aporte 197.575,03, 6 meses con brecha, DSCR 0,53. X3 ventas 81.222.447,72, VAN proyecto 6.951.414,83, VAN socios 3.672.044,15, aporte 324.969,77, Control C11 en REVISAR con 1. V4 ventas 89.344.692,49, VAN proyecto 8.556.852,51, VAN socios 4.713.190,90, aporte 290.460,36, 8 meses, DSCR 0,58, Control C10 en REVISAR con 16. Presupuesto (Resultados columna C) sin cambios en los tres casos; balance 0. | F12: Paso 2 OK, 0 diferencias (23 de 23 comprobaciones). Restauración verificada por relectura de fórmulas: filas 8/18/30 y D63:M65, D75:M75, D87:M87 con sus fórmulas originales. Caso base: ventas 81.222.447,72, VAN proyecto 6.989.921,76, VAN socios 3.695.678,09, balance 0, controles en REVISAR = 2. A la espera de «seguir» para el Paso 3.
A13: 12 (Claude en Excel) | B13: 46322 | C13: Paso 3 — Meses reales congelados: cargar 6 meses reales, Inversion G:H e Inicio!C11=6; evaluar escenario Vigente y Conservador. | D13: Carga en Reales F:K de TC, unidades, ventas, costos, movimientos de caja y saldos del mes 6; Inversion G6:H16 = presupuesto D6:D16 y G17:H17 = 35.833,91; Inicio!C11 = 6. Luego Inicio!C13 = Conservador y vuelta a Vigente. | E13: Vigente: ventas meses 1-6 = 254.000 y mes 7 = 404.166,67; caja mes 6 = 1.500.000; ajuste de conciliación mes 6 = -68.081,11; ventas año 1 = 3.949.000; EBITDA año 1 = 331.853,11; aporte adicional 557.910,57; 30 meses con brecha; VAN proyecto 6.858.765,62; VAN socios 3.546.902,66; balance 0. Conservador: meses 1-6 sin cambio (ventas 254.000, EBITDA 12.811,35, caja 1.500.000); ventas mes 7 = 345.562,50; VAN proyecto 31.572,84; VAN socios -1.330.307,86; aporte 3.286.963,70; CAPEX 767.548,50; balance 0. | F13: Paso 3 OK, 0 diferencias (19 de 19 comprobaciones). Restaurado: Reales F10:K84 e Inversion G6:H17 vacíos, Inicio!C11 vacía, C13 = Vigente; VAN del proyecto 6.989.921,76 y balance 0.
A14: 13 (Claude en Excel) | B14: 46322 | C14: Paso 3b — Volumen y guía: cargar Q1 y Q2 en los 24 meses de Detalle_24m y probar el conteo de meses faltantes. | D14: Detalle_24m F14:AC14 = 1.100 y F15:AC15 = 6.500. Segunda prueba: borrado de AC14:AC15 (mes 24). | E14: V.u1 (Calculo fila 177) = 1.100 en los meses 1-24 y 1.500 en el mes 25; V.u2 (fila 178) = 6.500 en los meses 1-24. Proyeccion_24m: primer mes 446.500; año 1 / año 2 / total = 5.358.000 / 5.411.580 / 10.769.580; EBITDA año 1 = 679.293,21; fila 7 = 'Detalle' en los 24 meses. Guia_Carga paso 29 (F43) = '✔ 24 meses detallados'. Sin el mes 24: '⚠ 23 de 24 meses: completar hasta el mes 24'. | F14: Paso 3b OK, 0 diferencias (10 de 10 comprobaciones). Detalle_24m restaurado; paso 29 vuelve a '○ Usa supuestos anuales'; VAN 6.989.921,76 y balance 0.
A15: 14 (Claude en Excel) | B15: 46322 | C15: Paso 3c — Precio, costos y TC: cinco casos en Detalle_24m, uno por vez, con restauración intermedia. | D15: Precio P1 = 280 en F42:Q42; MP1 = 90 en F70:AC70; DO1 = 6 y SA1 = 5.000.000 en F154:AC154 y F187:AC187; FC1 = 20.000.000 en F220:AC220; TC = 8.000 en F10:AC10. | E15: Precio: V.s1 = 280.000 en los meses 1-12 y 340.875 en el mes 13; ventas año 1 de la ventana = 4.970.000. Materia prima: V.mp_f mes 1 = 133.225 (base 125.875, +7.350) y mes 13 = 168.630,75 (base 160.476,38, +8.154,38); mes 25 sin cambio; EBITDA año 1 = 413.655,61. Personal: V.dir_n mes 1 = 45 (base 43) y V.dir_f mes 1 = 34.999,77 (base 32.622,23, +2.377,55); EBITDA año 1 = 479.713,36. Costo fijo: V.fp_f mes 1 = 5.215,40 (base 4.393,48, +821,92); EBITDA año 1 = 499.613,84. TC: V.tc = 8.000 en los meses 1-24 y 7.300 en el mes 25; V.PERA mes 1 = 8.175,99; ventas sin cambio (4.850.000 / 6.181.200 / 11.031.200); EBITDA año 1 = 584.427,34. Balance 0 en los cinco casos. | F15: Paso 3c OK, 0 diferencias (16 de 16 comprobaciones). Detalle_24m restaurado tras cada caso; VAN del proyecto 6.989.921,76.
A16: 15 (Claude en Excel) | B16: 46322 | C16: Paso 3d — Escenario sobre el detalle, ventana de 12 meses y ventana móvil con reales. | D16: Caso 1: Q1 = 1.100 en los meses 1-24 con Inicio!C13 = Conservador. Caso 2: Q1 = 1.100 con Inicio!C14 = 12. Caso 3: reales del paso 3 cargados (Inicio!C11 = 6) y Q1 = 1.100 en los meses 1-36 (F14:AO14). | E16: Conservador: V.u1 = 0 en los meses 1-3 (atraso de 3 meses), 990 en los meses 4-24 y 1.125 en el mes 25. Ventana 12: V.u1 = 1.100 en los meses 1-12 y 1.250 en los meses 13-24. Ventana móvil: V.u1 = 600 en los meses 1-6 (reales), 1.100 en los meses 7-30 y 1.500 en los meses 31-36; Proyeccion_24m arranca en el mes 7 con primer mes 431.166,67; año 1 / año 2 / total = 5.432.170 / 5.953.414,70 / 11.385.584,70. Balance 0 en los tres casos. | F16: Paso 3d OK, 0 diferencias (15 de 15 comprobaciones). Restauración final verificada: Detalle_24m sin datos, Reales e Inversion G:H vacíos, Inicio!C11 vacía, C13 = Vigente y C14 = 24; ventas 81.222.447,72, VAN proyecto 6.989.921,76, VAN socios 3.695.678,09, balance 0 y controles en REVISAR = 2.
A17: 16 (Claude en Excel) | B17: 46322 | C17: Pasos 4 a 7 — Catálogo de escenarios: financiamiento y cobranza (F1-F8), costos (C1-C4), ventas (V1-V5) y plan desfavorable (P1-P3). | D17: F: Inversion!E32 (3.800.000 / 1.800.000) y Supuestos!E21 (180 / 0) y sus combinaciones. C: Productos!J6:J7, L6:L7, N6:N7 = I/K/M × 1,10 / 1,20 / 1,30; C4 suma Costos!F6:F31 = E × 1,30 y F75:F83 = E × 2. V: Productos!D63:M64 = D34:M35 × 0,90 / 0,80 / 0,70 / 1,10 y V5 con D63:F63 = 15.000/15.000/21.000 y D64:F64 = 90.000/90.000/120.000. P1: volumen × 0,70 + H6:H7 = G × 0,95 + Supuestos!E6 = 7 + Inversion!J6:J19 = D × 1,15. P2 y P3: Inicio!C13 = Conservador / Optimista. | E17: 20 escenarios corridos, uno por vez, con restauración de fórmulas entre casos. Los 9 indicadores comparados por escenario (ventas, VAN proyecto, VAN socios, aporte adicional, meses con brecha, intereses, años de cancelación, DSCR mínimo y balance) coinciden con los valores de LibreOffice dentro de tolerancia. Hitos: F3 VAN proyecto 6.230.649,83; C2 VAN proyecto 249.504,40; V3 ventas 56.855.713,41; P2 VAN proyecto -486.490,30. Balance 0 en los 20 casos. | F17: Pasos 4 a 7 OK, 0 diferencias (180 comprobaciones). Caso base restaurado tras cada grupo: VAN del proyecto 6.989.921,76 y balance 0.
A18: 17 (Claude en Excel) | B18: 46322 | C18: Pasos 8 a 10 — Plazo del préstamo (L1-L4), corto vs largo plazo (K1-K8) y tipo de cambio (T1-T3). | D18: L: Inversion!E36 = 30 / 78; E35 = 12 con E36 = 84; L4 con E32 = 0 y línea 4.000.000 al 9%. K: E32 = 3.250.000; préstamo 2 en G32:G36 (500.000, mes 25, 10%, gracia 0, 12 cuotas); líneas rotativas de 1.000.000, 3.000.000 y 4.000.000 al 10%, 7,99% y 11,24%, con y sin vencimiento en el mes 24. T: Supuestos!D51:M51 = 8.760 / 6.145 / 5.840. | E18: 15 escenarios corridos, uno por vez. Los 9 indicadores coinciden en los 15. Hitos: L1 cancela en 3,0 años con intereses 508.038,98; K5 aporte adicional 2.191.678,81 y cancela en 2,08 años; K7 VAN socios 3.806.552,07; T1 VAN proyecto 7.989.367,27; T3 VAN proyecto 5.490.753,49. El VAN del proyecto se mantiene en 6.989.921,76 en todos los casos de financiamiento (F1-F2, L1-L4, K1-K8), como corresponde a un FCFF. Balance 0 en los 15 casos. | F18: Pasos 8 a 10 OK, 0 diferencias (135 comprobaciones). Supuestos!D51:M51 restaurada a =D39..=M39; Inversion E32:E36, G32:G36 y E41:E44 con sus fórmulas =D../=F.. originales.
... A22: 21 (Claude Code) | B22: 46323 | C22: Mover los contadores de Detalle_24m al motor y presentar los resultados separados como el plan de negocio, para identificar cada cifra y compararla con el plan. | D22: Contadores «celdas con dato en el mes» movidos al final de Calculo (filas det.TC a det.FC); en Detalle_24m esas filas quedan libres. Nuevas hojas: «Cuadros» (índice, selector de versión en C5, resumen modelo vs plan y causas de las diferencias) y 15 cuadros como el plan: C01 Inversión, C07 Producción, C08 Ingresos, C09 Materiales, C10a Costos, C10b Costo unitario, C11 Rubros, C13 Deuda e IVA, C15 Resultados, C16 Capital trabajo, C17 Equilibrio, C18 Fondos, C19 VAN-TIR, C20 Depreciación y RRHH. | E22: Cada cuadro: bloque A = modelo (presupuesto o vigente), B = plan publicado (cargado desde el PDF con su página), C = diferencia con la explicación de la causa. Columnas por año de operación como el plan (año 0 = implantación). Filas de ajuste por datos reales y detalle mensual. Cuadro 19: el método del plan aplicado a los flujos publicados reproduce VAN 4.588.737 y TIR 22,61%; con las cifras del modelo da VAN 4.177.576 y TIR 23,99%. | F22: Validado en LibreOffice: 0 errores; motor, Resultados, Proyeccion_24m, guía y Control idénticos a la v6 (50.484 celdas); 39 escenarios 495/495 OK e idénticos a la v6 (1.625.364 valores); 7 pruebas de operación iguales a la v6; 60/60 de detalle; 147/147 de cuadros. Pendiente: validación en Excel con Prompt_Claude_Excel_ECOSTAR_v7.md (ruta corta: pasos 0, 1, 3e, 3f y 11).

Sheet Inicio
A1: ="Modelo financiero de maquila — "&IF(n_Negocio="","(completar nombre)",n_Negocio) -> Modelo financiero de maquila — ECOSTAR — Maquila CIE–PERG
A2: Plantilla común v2: un archivo por negocio, misma estructura. Presupuesto original, ejecución real y proyección vigente separados.
A4: 1. Configuración del negocio (completar)
B5: Dato | C5: Valor | D5: Instrucción
B6: Nombre del negocio | C6: ECOSTAR — Maquila CIE–PERG | D6: Texto libre.
B7: Socios / empresas | C7: CIE S.A. / PERG | D7: Texto libre.
B8: Actividad / productos | C8: Procesamiento de chapas: gabinetes metálicos (153 kg) y cajas metálicas (13 kg) | D8: Texto libre.
B9: Etapa del negocio | C9: Operación | D9: Implantación (aún sin operar) u Operación.
B10: Fecha del mes 1 del modelo | D10: Primer mes de implantación u operación. Se recomienda que sea enero para que los años coincidan con años calendario. Vacío = meses relativos.
B11: Último mes cerrado con datos reales (n° de mes) | D11: Los meses hasta este número usan solo la hoja Reales y no cambian con los escenarios. Vacío = sin datos reales.
B12: Mes real de inicio de operación (n° de mes) | D12: Cargar cuando la operación ya comenzó. Prevalece sobre el supuesto vigente y el atraso del escenario.
B13: Escenario para la proyección | C13: Vigente | D13: Vigente (sin ajustes), Conservador u Optimista. Solo afecta los meses posteriores al corte.
B14: Meses de proyección detallada (ventana móvil) | C14: 24 | D14: Meses siguientes al último cierre que usan el detalle mensual de Detalle_24m (recomendado 24). Después, supuestos anuales.
B15: Versión del plan aprobado (presupuesto original) | C15: Plan CIE–PERG Oct-2025 | D15: Ej.: Plan Oct-2025; Revisión 2027.
B16: Fecha de aprobación de la última revisión del plan | D16: Con la frecuencia, define la próxima revisión del plan a 10 años.
B17: Frecuencia de revisión del plan | C17: Anual | D17: Anual (año 1 firme + año 2 actualizado) o Bienal. El detalle de 24 meses se actualiza en cada cierre.
B18: Moneda de presentación | C18: USD (costos en Gs convertidos con el TC de cada año)
A20: 2. Estado del modelo (automático)
B21: Fecha del último mes cerrado | C21: =IF(Corte=0,"Sin datos reales",IF(n_Fecha1="","Mes "&Corte,"Mes "&Corte&" ("&TEXT(MONTH(EOMONTH(n_Fecha1,Corte-1)),"00")&"/"&YEAR(EOMONTH(n_Fecha1,Corte-1))&")")) -> Sin datos reales
B22: Inicio de operación (presupuesto / vigente) | C22: ="Mes "&P_Inicio&" / mes "&V_Inicio -> Mes 1 / mes 1
B23: Fin del horizonte evaluado (fijo) | C23: ="Mes "&Fin&" ("&P_Anios&" años de operación desde el inicio presupuestado)" -> Mes 120 (10 años de operación desde el inicio presupuestado)
B24: Supuestos vigentes modificados respecto del presupuesto | C24: =c_Modificados -> 0
B25: Controles con alerta (hoja Control) | C25: =c_Alertas -> 2
B26: Brecha de caja máxima vigente (USD) | C26: =r_BrechaV -> 373700.71
B27: Pasos de la Guía de carga con alerta (⚠) | C27: =g_Pendientes -> 11
B28: Ventana de proyección detallada | C28: =IF(N(n_Ventana)=0,"Sin detalle mensual","Meses "&(Corte+1)&" a "&MIN(144,Corte+n_Ventana)) -> Meses 1 a 24
B29: Próxima revisión del plan | C29: =IF(ISNUMBER(n_FechaRev),DAY(EDATE(n_FechaRev,IF(n_Frecuencia="Bienal",24,12)))&"/"&MONTH(EDATE(n_FechaRev,IF(n_Frecuencia="Bienal",24,12)))&"/"&YEAR(EDATE(n_FechaRev,IF(n_Frecuencia="Bienal",24,12))),"Sin fecha de revisión") -> Sin fecha de revisión
A31: 3. Cómo cargar y actualizar
B32: Paso a paso | C32: Seguir la hoja Guia_Carga: cada paso tiene vínculo a la celda, fuente, criterio y estado automático.
B33: Proyección 24 meses | C33: En Detalle_24m cargar mes a mes lo asegurado para los próximos meses (volúmenes, precios, costos, personal, fijos, TC). Celda vacía = supuesto anual. Con cada cierre la ventana avanza un mes: completar el nuevo último mes.
B34: Revisión del plan | C34: Anual o bienal: el plan aprobado (presupuesto original, 10 años) se actualiza con los supuestos vigentes aprobados; guardar la versión anterior.
B35: Alta de un negocio | C35: Copiar el archivo vacío, completar la sección 1 y luego las hojas en este orden: Supuestos → Productos → Costos → Inversion.
B36: Presupuesto original | C36: Cargar en las columnas «Presupuesto original» los datos del plan aprobado. No se modifican después: son la referencia de comparación.
B37: Proyección vigente | C37: Las columnas «Vigente» heredan el presupuesto (gris). Sobrescribir solo lo que cambió; la celda pasa a azul/amarillo y Control lo cuenta.
B38: Cierre mensual | C38: 1) Cargar en Reales el mes cerrado (unidades, ventas, costos, CAPEX, financiamiento). 2) Cargar los saldos al cierre en el mes de corte. 3) Actualizar «Último mes cerrado» arriba. 4) Revisar Control. 5) Ajustar la proyección vigente si cambió.
B39: Inversión | C39: En Inversion registrar por ítem lo ejecutado, pagado, comprometido y por contratar. El costo final estimado se calcula solo.
B40: Escenarios | C40: Elegir el escenario arriba. Los ajustes están en Supuestos sección C y solo afectan la proyección (nunca los meses reales).
B41: Lectura | C41: Resultados compara presupuesto original vs vigente (real + proyección). Control muestra los faltantes y las inconsistencias.
A43: 4. Convenciones
B44: Ejemplo 1.234 | C44: Celda para completar (dato de entrada).
...

Sheet Guia_Carga
A1: Guía de carga paso a paso
A2: Seguir en orden. El estado se calcula con los datos del libro: confirma que el dato está cargado y concilia, no que sea correcto.
B4: Mes en carga (próximo mes a cerrar) | C4: =MIN(144,Corte+1) -> 1 | D4: =IF(ISNUMBER(n_Fecha1),"Fecha: "&TEXT(MONTH(EOMONTH(n_Fecha1,g_Mes-1)),"00")&"/"&YEAR(EOMONTH(n_Fecha1,g_Mes-1)),"Sin fecha del mes 1") -> Sin fecha del mes 1
B5: Pasos con alerta (⚠) | C5: =COUNTIF(F9:F51,"⚠*") -> 11
B6: Leyenda: ✔ listo · ⚠ pendiente o a revisar · ○ informativo o manual · — no aplica
A8: N° | B8: Paso | C8: Dónde (clic para ir) | D8: Fuente del dato | E8: Criterio | F8: Estado (automático) | G8: Hecho | H8: Fecha | I8: Responsable | J8: Notas
A9: A. Alta del negocio (una vez)
A10: 1 | B10: Nombre, socios, actividad y etapa | C10: =HYPERLINK("#Inicio!C6","Inicio!C6:C9") -> Inicio!C6:C9 | D10: Plan de negocio / acta | E10: Etapa «Operación» si ya factura; «Implantación» si todavía no. | F10: =IF(AND(n_Negocio<>"",n_Etapa<>""),"✔ Listo","⚠ Pendiente") -> ✔ Listo
A11: 2 | B11: Fecha del mes 1 del modelo | C11: =HYPERLINK("#Inicio!C10","Inicio!C10") -> Inicio!C10 | D11: Plan aprobado | E11: Preferentemente enero. Solo cambia las etiquetas de fecha. | F11: =IF(ISNUMBER(n_Fecha1),"✔ Listo","⚠ Pendiente (recomendado)") -> ⚠ Pendiente (recomendado)
A12: 3 | B12: Mes real de inicio de operación | C12: =HYPERLINK("#Inicio!C12","Inicio!C12") -> Inicio!C12 | D12: Primera factura / acta de inicio | E12: No cambiar el inicio del presupuesto: el real se carga aquí. | F12: =IF(n_Etapa="Operación",IF(ISNUMBER(n_InicioReal),"✔ Listo","⚠ Pendiente"),IF(n_Etapa="","⚠ Definir primero la etapa (paso 1)","— No aplica (implantación)")) -> ⚠ Pendiente
A13: B. Presupuesto original (una vez, plan aprobado; no se modifica después)
A14: 4 | B14: Parámetros generales (columna «Presupuesto original») | C14: =HYPERLINK("#Supuestos!D6","Supuestos!D6:D34") -> Supuestos!D6:D34 | D14: Plan aprobado | E14: Porcentajes como fracción (0,05 = 5%). Anotar la fuente en la nota. | F14: =IF(COUNTBLANK(Supuestos!$D$6:$D$34)=0,"✔ Listo","⚠ Faltan "&COUNTBLANK(Supuestos!$D$6:$D$34)&" parámetros") -> ✔ Listo
A15: 5 | B15: Tipo de cambio por año | C15: =HYPERLINK("#Supuestos!D39","Supuestos!D39:M39") -> Supuestos!D39:M39 | D15: Plan / BCP | E15: Obligatorio: convierte la nómina y los costos en guaraníes. | F15: =IF(COUNTIF(TC_O,">0")=10,"✔ Listo","⚠ Faltan "&(10-COUNTIF(TC_O,">0"))&" años") -> ✔ Listo
A16: 6 | B16: Variaciones de precio, costos y salarios, y dividendos por año | C16: =HYPERLINK("#Supuestos!D40","Supuestos!D40:M44") -> Supuestos!D40:M44 | D16: Plan aprobado | E16: Vacío no es cero: cargar 0 si no hay variación. | F16: =IF(COUNTBLANK(Supuestos!$D$40:$M$44)=0,"✔ Listo","⚠ Faltan "&COUNTBLANK(Supuestos!$D$40:$M$44)&" celdas") -> ✔ Listo
A17: 7 | B17: Productos: nombre, unidad, precio, costos por unidad y capacidad | C17: =HYPERLINK("#Productos!B6","Productos!B6:N30") -> Productos!B6:N30 | D17: Plan / costeo de producto | E17: Hasta 25 productos individuales. Capacidad 0 = no se controla. | F17: =IF(SUMPRODUCT(--(Prod_Nombre<>""))=0,"⚠ Sin productos",IF(SUMPRODUCT((VolTot_O>0)*(Precio_O=0))>0,"⚠ "&SUMPRODUCT((VolTot_O>0)*(Precio_O=0))&" producto(s) con volumen y sin precio","✔ "&SUMPRODUCT(--(Prod_Nombre<>""))&" producto(s)")) -> ✔ 2 producto(s)
A18: 8 | B18: Volumen de ventas por año (presupuesto) | C18: =HYPERLINK("#Productos!D34","Productos!D34:M58") -> Productos!D34:M58 | D18: Plan comercial | E18: Unidades vendidas por año de operación. | F18: =IF(SUM(VolTot_O)=0,"⚠ Sin volumen",IF(SUMPRODUCT((Prod_Nombre<>"")*(VolTot_O=0)*(VolTot_V=0))>0,"⚠ Hay productos sin volumen","✔ Listo")) -> ✔ Listo
A19: 9 | B19: Personal: puesto, clase, moneda, salario mensual y dotación por año | C19: =HYPERLINK("#Costos!B6","Costos!B6:P35") -> Costos!B6:P35 | D19: Nómina / RR. HH. | E19: Clase: Directo, Indirecto o Administración. Salario sin cargas sociales. | F19: =IF(COUNT(Sal_O)=0,"⚠ Sin personal","✔ "&COUNT(Sal_O)&" puesto(s)") -> ✔ 26 puesto(s)
A20: 10 | B20: Costos fijos: concepto, clase, moneda, monto, crecimiento y año de inicio | C20: =HYPERLINK("#Costos!B75","Costos!B75:J99") -> Costos!B75:J99 | D20: Contratos / presupuesto de gastos | E20: IVA incluido solo si no se recupera. | F20: =IF(COUNT(FC_O)=0,"⚠ Sin costos fijos","✔ "&COUNT(FC_O)&" concepto(s)") -> ✔ 9 concepto(s)
A21: 11 | B21: Inversión (CAPEX): monto, mes de pago y vida útil por ítem | C21: =HYPERLINK("#Inversion!B6","Inversion!B6:F25") -> Inversion!B6:F25 | D21: Presupuesto de inversión / cotizaciones | E21: Aporte en especie: cargar el ítem y el aporte en el mismo mes. | F21: =IF(COUNT(Inv_D)=0,"⚠ Sin CAPEX",IF(SUMPRODUCT((Inv_D>0)*((Inv_E="")+(Inv_F="")))>0,"⚠ Ítems sin mes o sin vida útil","✔ "&COUNT(Inv_D)&" ítem(s)")) -> ✔ 14 ítem(s)
A22: 12 | B22: Financiamiento: préstamos, línea rotativa y aportes | C22: =HYPERLINK("#Inversion!B29","Inversion, secciones B, B2 y C") -> Inversion, secciones B, B2 y C | D22: Contratos bancarios / acta de socios | E22: Tasa nominal anual; gracia y cuotas según contrato. | F22: =IF(N(P_L1_Monto)+N(P_L2_Monto)+N(P_L3_Monto)+N(P_LC_Lim)+SUM(Ap_MontoO)=0,"○ Sin financiamiento cargado","✔ Listo") -> ✔ Listo
A23: 13 | B23: Revisión del presupuesto: balance y plan publicado | C23: =HYPERLINK("#Resultados!B4","Resultados") -> Resultados | D23: — | E23: Balance = 0. Explicar las diferencias con el plan publicado (sección E). | F23: =IF(c_C01="OK","✔ Balance OK","⚠ Revisar el balance") -> ✔ Balance OK
A24: C. Proyección vigente (cuando cambia un supuesto)
A25: 14 | B25: Sobrescribir en «Vigente» solo lo que cambió, con evidencia | C25: =HYPERLINK("#Supuestos!E6","Columnas «Vigente»") -> Columnas «Vigente» | D25: Contrato, cotización, nómina, oferta bancaria | E25: Anotar fuente y fecha. Para volver al presupuesto, reponer la fórmula que hereda. | F25: ="○ "&c_Modificados&" celda(s) vigente(s) modificada(s)" -> ○ 0 celda(s) vigente(s) modificada(s)
A26: 15 | B26: Escenario de trabajo | C26: =HYPERLINK("#Inicio!C13","Inicio!C13") -> Inicio!C13 | D26: — | E26: Vigente para el trabajo normal; Conservador y Optimista solo para análisis. | F26: =IF(n_Escenario="Vigente","✔ Vigente","⚠ Activo: "&n_Escenario&" (volver a Vigente)") -> ✔ Vigente
A27: D. Cierre mensual (cada mes): los vínculos llevan a la columna del mes en carga
A28: 16 | B28: TC real del mes | C28: =HYPERLINK("#Reales!"&ADDRESS(10,5+g_Mes,4),"Reales, fila 10, mes "&g_Mes) -> Reales, fila 10, mes 1 | D28: BCP / política de CIE | E28: Siempre el mismo criterio (promedio o cierre). | F28: =IF(ISNUMBER(INDEX(Reales!$F$10:$ES$10,1,g_Mes)),"✔ Cargado","⚠ Pendiente") -> ⚠ Pendiente
A29: 17 | B29: Unidades vendidas por producto | C29: =HYPERLINK("#Reales!"&ADDRESS(12,5+g_Mes,4),"Reales, filas 12-36, mes "&g_Mes) -> Reales, filas 12-36, mes 1 | D29: SAP SD (facturación) | E29: Una fila por producto con nombre. | F29: =IF(SUMPRODUCT(--(Prod_Nombre<>""))=0,"— Sin productos",IF(SUMPRODUCT((Prod_Nombre<>"")*ISNUMBER(INDEX(Reales!$F$12:$ES$36,0,g_Mes)))=SUMPRODUCT(--(Prod_Nombre<>"")),"✔ Cargado","⚠ Faltan "&(SUMPRODUCT(--(Prod_Nombre<>""))-SUMPRODUCT((Prod_Nombre<>"")*ISNUMBER(INDEX(Reales!$F$12:$ES$36,0,g_Mes))))&" producto(s)")) -> ⚠ Faltan 2 producto(s)
A30: 18 | B30: Ventas netas por producto (moneda en la columna C) | C30: =HYPERLINK("#Reales!"&ADDRESS(38,5+g_Mes,4),"Reales, filas 38-62, mes "&g_Mes) -> Reales, filas 38-62, mes 1 | D30: SAP SD / FI | E30: Facturación neta, sin IVA. | F30: =IF(SUMPRODUCT(--(Prod_Nombre<>""))=0,"— Sin productos",IF(SUMPRODUCT((Prod_Nombre<>"")*ISNUMBER(INDEX(Reales!$F$38:$ES$62,0,g_Mes)))=SUMPRODUCT(--(Prod_Nombre<>"")),"✔ Cargado","⚠ Faltan "&(SUMPRODUCT(--(Prod_Nombre<>""))-SUMPRODUCT((Prod_Nombre<>"")*ISNUMBER(INDEX(Reales!$F$38:$ES$62,0,g_Mes))))&" producto(s)")) -> ⚠ Faltan 2 producto(s)
A31: 19 | B31: Costos devengados: 7 rubros sin IVA recuperable | C31: =HYPERLINK("#Reales!"&ADDRESS(64,5+g_Mes,4),"Reales, filas 64-70, mes "&g_Mes) -> Reales, filas 64-70, mes 1 | D31: SAP MM / CO, nómina | E31: En un mes cerrado, vacío vale cero: cargar 0 si no hubo. | F31: =IF(COUNT(INDEX(Reales!$F$64:$ES$70,0,g_Mes))=7,"✔ 7 de 7","⚠ "&COUNT(INDEX(Reales!$F$64:$ES$70,0,g_Mes))&" de 7 cargados") -> ⚠ 0 de 7 cargados
A32: 20 | B32: Movimientos de caja: CAPEX, desembolsos, intereses, amortizaciones, aportes, dividendos | C32: =HYPERLINK("#Reales!"&ADDRESS(72,5+g_Mes,4),"Reales, filas 72-77, mes "&g_Mes) -> Reales, filas 72-77, mes 1 | D32: Tesorería / SAP PS | E32: Cargar 0 si no hubo movimiento. | F32: =IF(COUNT(INDEX(Reales!$F$72:$ES$77,0,g_Mes))=6,"✔ 6 de 6","⚠ "&COUNT(INDEX(Reales!$F$72:$ES$77,0,g_Mes))&" de 6 cargados") -> ⚠ 0 de 6 cargados
A33: 21 | B33: Saldos al cierre: caja, clientes, inventarios, IVA, proveedores, deuda | C33: =HYPERLINK("#Reales!"&ADDRESS(79,5+g_Mes,4),"Reales, filas 79-84, mes "&g_Mes) -> Reales, filas 79-84, mes 1 | D33: Balance de comprobación / bancos | E33: Obligatorios en el último mes cerrado. | F33: =IF(COUNT(INDEX(Reales!$F$79:$ES$84,0,g_Mes))=6,"✔ 6 de 6","⚠ "&COUNT(INDEX(Reales!$F$79:$ES$84,0,g_Mes))&" de 6 cargados") -> ⚠ 0 de 6 cargados
A34: 22 | B34: CAPEX por ítem: ejecutado, pagado, comprometido, por contratar | C34: =HYPERLINK("#Inversion!G6","Inversion!G6:L25") -> Inversion!G6:L25 | D34: SAP PS (elementos PEP) | E34: El pagado total debe igualar el CAPEX de Reales (control C08). | F34: =IF(AND(N(i_Pagado)=0,SUM(Reales!$F$72:$ES$72)=0),"○ Sin CAPEX ejecutado todavía",IF(c_C08="OK","✔ Concilia","⚠ No concilia con Reales")) -> ○ Sin CAPEX ejecutado todavía
A35: 23 | B35: Actualizar el último mes cerrado | C35: =HYPERLINK("#Inicio!C11","Inicio!C11") -> Inicio!C11 | D35: — | E35: Recién cuando los seis pasos anteriores de datos estén en ✔. | F35: =IF(AND(LEFT(F28,1)="✔",LEFT(F29,1)="✔",LEFT(F30,1)="✔",LEFT(F31,1)="✔",LEFT(F32,1)="✔",LEFT(F33,1)="✔"),"✔ Listo para cerrar: poner "&g_Mes,"⚠ Esperar: faltan datos del mes "&g_Mes) -> ⚠ Esperar: faltan datos del mes 1
A36: 24 | B36: Revisar Control después de cerrar | C36: =HYPERLINK("#Control!B4","Control") -> Control | D36: — | E36: C03 a C08 en OK; explicar el ajuste de conciliación de caja si es grande. | F36: =IF(Corte=0,"○ Sin meses cerrados",IF(AND(c_C03="OK",c_C04="OK",c_C05="OK",c_C06="OK",c_C07="OK",c_C08="OK"),"✔ Controles de carga OK","⚠ "&c_Alertas&" control(es) en REVISAR")) -> ○ Sin meses cerrados
A37: E. Revisión y reporte
A38: 25 | B38: Brecha de caja y financiamiento | C38: =HYPERLINK("#Resultados!B4","Resultados, indicadores") -> Resultados, indicadores | D38: — | E38: Si hay brecha: definir aporte, línea rotativa o mejora del capital de trabajo. | F38: =IF(c_C13="OK","✔ Sin brecha","⚠ Brecha máxima USD "&FIXED(r_BrechaV,0)) -> ⚠ Brecha máxima USD 373,701
A39: 26 | B39: Desvíos vigente vs presupuesto (ventas, EBITDA, caja) | C39: =HYPERLINK("#Resultados!B147","Resultados, sección D") -> Resultados, sección D | D39: — | E39: Explicar por volumen, precio, costo y atraso. | F39: ="○ Revisar" -> ○ Revisar
A40: 27 | B40: Guardar una versión fechada del cierre y registrar los cambios | C40: =HYPERLINK("#Inicio!B4","Inicio") -> Inicio | D40: — | E40: Por ejemplo: NEGOCIO_cierre_2026-10.xlsx. | F40: ="○ Manual" -> ○ Manual
A41: 28 | B41: Trimestral: revisar supuestos vigentes y escenarios | C41: =HYPERLINK("#Supuestos!E6","Supuestos") -> Supuestos | D41: — | E41: Actualizar tasas, TC, precios y costos con evidencia. | F41: ="○ Manual" -> ○ Manual
A42: F. Proyección rodante de 24 meses (Detalle_24m) y revisión del plan
...

Sheet Supuestos
A1: Supuestos — presupuesto original y vigente
A2: Presupuesto original = plan aprobado (no se modifica). Vigente = hereda el presupuesto; sobrescribir solo lo que cambió.
A4: A. Parámetros generales
A5: Cód. | B5: Parámetro | C5: Unidad | D5: Presupuesto original | E5: Vigente | F5: Nota / fuente
A6: G01 | B6: Mes de inicio de la operación (n° de mes del modelo) | C6: mes | D6: 1 | E6: =D6 -> 1 | F6: PDF: inversión en el año 0 y operación desde el año 1 (mes 1 del modelo).
A7: G02 | B7: Años de operación evaluados | C7: años | D7: 10 | E7: =D7 -> 10 | F7: PDF: 10 años de operación. Horizonte común a ambas versiones: se define solo en el presupuesto.
A8: G03 | B8: Merma entre producción y venta | C8: % | D8: 0 | E8: =D8 -> 0 | F8: PDF: producción = ventas.
A9: G04 | B9: Cargas sociales sobre salarios (aguinaldo, IPS, vacaciones) | C9: % | D9: 0.4309 | E9: =D9 -> 0.4309 | F9: PDF p. 19: coeficiente del plan (no validado como tasa legal).
A10: G05 | B10: Alimentación del personal | C10: Gs/persona/mes | D10: 576000 | E10: =D10 -> 576000 | F10: Inferido del PDF: USD 946,85/persona/año a Gs 7.300.
A11: G06 | B11: Personal directo activo antes del inicio de operación | C11: % dotación año 1 | D11: 0.5 | E11: =D11 -> 0.5 | F11: Supuesto provisional para meses de implantación (no aplica al plan original).
A12: G07 | B12: Personal indirecto y administrativo activo antes del inicio | C12: % dotación año 1 | D12: 1 | E12: =D12 -> 1 | F12: Supuesto provisional para meses de implantación.
A13: G08 | B13: Despacho y gastos de importación (s/ materia prima + insumos) | C13: % | D13: 0.03 | E13: =D13 -> 0.03 | F13: PDF p. 19: 3% sobre materia prima + insumos.
A14: G09 | B14: Packaging (s/ materiales, otros variables y personal directo) | C14: % | D14: 0.01 | E14: =D14 -> 0.01 | F14: PDF p. 19: 1% sobre materiales, otros variables y personal directo.
A15: G10 | B15: Imprevistos de producción (s/ costos de producción) | C15: % | D15: 0.05 | E15: =D15 -> 0.05 | F15: PDF p. 19: 5% sobre costos de producción (excluye tributo).
A16: G11 | B16: Imprevistos de administración (s/ gastos marcados como base) | C16: % | D16: 0.05 | E16: =D16 -> 0.05 | F16: PDF p. 19: 5% sobre administración (excluye alquiler y expensas).
A17: G12 | B17: Tributo de maquila (s/ ventas) | C17: % | D17: 0.01 | E17: =D17 -> 0.01 | F17: PDF p. 7: 1% sobre el valor exportado (verificar Ley 7547/2025).
... A34: G29 | B34: Mes de pago de dividendos del año siguiente (1-12) | C34: mes | D34: 4 | E34: =D34 -> 4 | F34: Supuesto provisional: dividendos pagados en abril del año siguiente.
A36: B. Supuestos por año (año 1 = primer año de operación; el TC se aplica por año del modelo)
A37: Cód. | B37: Concepto | C37: Unidad | D37: Año 1 | E37: Año 2 | F37: Año 3 | G37: Año 4 | H37: Año 5 | I37: Año 6 | J37: Año 7 | K37: Año 8 | L37: Año 9 | M37: Año 10 | N37: Nota
B38: PRESUPUESTO ORIGINAL
A39: TC | B39: Tipo de cambio (Gs/USD) — por año del modelo | C39: Gs/USD | D39: 7300 | E39: 7300 | F39: 7300 | G39: 7300 | H39: 7300 | I39: 7300 | J39: 7300 | K39: 7300 | L39: 7300 | M39: 7300
A40: dPrecio | B40: Variación de precios de venta (año de operación) | C40: % | D40: 0 | E40: 0.01 | F40: 0.01 | G40: 0.01 | H40: 0.01 | I40: 0.01 | J40: 0.01 | K40: 0.01 | L40: 0.01 | M40: 0.01
A41: dMP | B41: Variación del costo de materia prima | C41: % | D41: 0 | E41: 0.01 | F41: 0.01 | G41: 0.01 | H41: 0.01 | I41: 0.01 | J41: 0.01 | K41: 0.01 | L41: 0.01 | M41: 0.01
A42: dOV | B42: Variación de insumos y otros costos variables | C42: % | D42: 0 | E42: 0 | F42: 0 | G42: 0 | H42: 0 | I42: 0 | J42: 0 | K42: 0 | L42: 0 | M42: 0
A43: dSal | B43: Ajuste salarial | C43: % | D43: 0 | E43: 0 | F43: 0 | G43: 0 | H43: 0 | I43: 0 | J43: 0 | K43: 0 | L43: 0 | M43: 0
A44: Payout | B44: Dividendos (% del resultado del año) | C44: % | D44: 0 | E44: 0 | F44: 0.3 | G44: 0.5 | H44: 1 | I44: 1 | J44: 1 | K44: 1 | L44: 1 | M44: 1
B45: Índice acumulado de precios (cálculo) | D45: =1 -> 1 | E45: =D45*(1+N(E40)) -> 1.01 | F45: =E45*(1+N(F40)) -> 1.0201 | G45: =F45*(1+N(G40)) -> 1.030301 | H45: =G45*(1+N(H40)) -> 1.040604 | I45: =H45*(1+N(I40)) -> 1.0510101 | J45: =I45*(1+N(J40)) -> 1.0615202 | K45: =J45*(1+N(K40)) -> 1.0721354 | L45: =K45*(1+N(L40)) -> 1.0828567 | M45: =L45*(1+N(M40)) -> 1.0936853
B46: Índice acumulado de materia prima (cálculo) | D46: =1 -> 1 | E46: =D46*(1+N(E41)) -> 1.01 | F46: =E46*(1+N(F41)) -> 1.0201 | G46: =F46*(1+N(G41)) -> 1.030301 | H46: =G46*(1+N(H41)) -> 1.040604 | I46: =H46*(1+N(I41)) -> 1.0510101 | J46: =I46*(1+N(J41)) -> 1.0615202 | K46: =J46*(1+N(K41)) -> 1.0721354 | L46: =K46*(1+N(L41)) -> 1.0828567 | M46: =L46*(1+N(M41)) -> 1.0936853
B47: Índice acumulado de otros variables (cálculo) | D47: =1 -> 1 | E47: =D47*(1+N(E42)) -> 1 | F47: =E47*(1+N(F42)) -> 1 | G47: =F47*(1+N(G42)) -> 1 | H47: =G47*(1+N(H42)) -> 1 | I47: =H47*(1+N(I42)) -> 1 | J47: =I47*(1+N(J42)) -> 1 | K47: =J47*(1+N(K42)) -> 1 | L47: =K47*(1+N(L42)) -> 1 | M47: =L47*(1+N(M42)) -> 1
B48: Índice acumulado de salarios (cálculo) | D48: =1 -> 1 | E48: =D48*(1+N(E43)) -> 1 | F48: =E48*(1+N(F43)) -> 1 | G48: =F48*(1+N(G43)) -> 1 | H48: =G48*(1+N(H43)) -> 1 | I48: =H48*(1+N(I43)) -> 1 | J48: =I48*(1+N(J43)) -> 1 | K48: =J48*(1+N(K43)) -> 1 | L48: =K48*(1+N(L43)) -> 1 | M48: =L48*(1+N(M43)) -> 1
B50: VIGENTE (hereda el presupuesto)
A51: TC | B51: Tipo de cambio (Gs/USD) — por año del modelo | C51: Gs/USD | D51: =D39 -> 7300 | E51: =E39 -> 7300 | F51: =F39 -> 7300 | G51: =G39 -> 7300 | H51: =H39 -> 7300 | I51: =I39 -> 7300 | J51: =J39 -> 7300 | K51: =K39 -> 7300 | ... M51: =M39 -> 7300
A52: dPrecio | B52: Variación de precios de venta (año de operación) | C52: % | D52: =D40 -> 0 | E52: =E40 -> 0.01 | F52: =F40 -> 0.01 | G52: =G40 -> 0.01 | H52: =H40 -> 0.01 | I52: =I40 -> 0.01 | J52: =J40 -> 0.01 | K52: =K40 -> 0.01 | ... M52: =M40 -> 0.01
A53: dMP | B53: Variación del costo de materia prima | C53: % | D53: =D41 -> 0 | E53: =E41 -> 0.01 | F53: =F41 -> 0.01 | G53: =G41 -> 0.01 | H53: =H41 -> 0.01 | I53: =I41 -> 0.01 | J53: =J41 -> 0.01 | K53: =K41 -> 0.01 | ... M53: =M41 -> 0.01
A54: dOV | B54: Variación de insumos y otros costos variables | C54: % | D54: =D42 -> 0 | E54: =E42 -> 0 | F54: =F42 -> 0 | G54: =G42 -> 0 | H54: =H42 -> 0 | I54: =I42 -> 0 | J54: =J42 -> 0 | K54: =K42 -> 0 | ... M54: =M42 -> 0
A55: dSal | B55: Ajuste salarial | C55: % | D55: =D43 -> 0 | E55: =E43 -> 0 | F55: =F43 -> 0 | G55: =G43 -> 0 | H55: =H43 -> 0 | I55: =I43 -> 0 | J55: =J43 -> 0 | K55: =K43 -> 0 | ... M55: =M43 -> 0
A56: Payout | B56: Dividendos (% del resultado del año) | C56: % | D56: =D44 -> 0 | E56: =E44 -> 0 | F56: =F44 -> 0.3 | G56: =G44 -> 0.5 | H56: =H44 -> 1 | I56: =I44 -> 1 | J56: =J44 -> 1 | K56: =K44 -> 1 | ... M56: =M44 -> 1
B57: Índice acumulado de precios (cálculo) | D57: =1 -> 1 | E57: =D57*(1+N(E52)) -> 1.01 | F57: =E57*(1+N(F52)) -> 1.0201 | G57: =F57*(1+N(G52)) -> 1.030301 | H57: =G57*(1+N(H52)) -> 1.040604 | I57: =H57*(1+N(I52)) -> 1.0510101 | J57: =I57*(1+N(J52)) -> 1.0615202 | K57: =J57*(1+N(K52)) -> 1.0721354 | L57: =K57*(1+N(L52)) -> 1.0828567 | M57: =L57*(1+N(M52)) -> 1.0936853
B58: Índice acumulado de materia prima (cálculo) | D58: =1 -> 1 | E58: =D58*(1+N(E53)) -> 1.01 | F58: =E58*(1+N(F53)) -> 1.0201 | G58: =F58*(1+N(G53)) -> 1.030301 | H58: =G58*(1+N(H53)) -> 1.040604 | I58: =H58*(1+N(I53)) -> 1.0510101 | J58: =I58*(1+N(J53)) -> 1.0615202 | K58: =J58*(1+N(K53)) -> 1.0721354 | L58: =K58*(1+N(L53)) -> 1.0828567 | M58: =L58*(1+N(M53)) -> 1.0936853
B59: Índice acumulado de otros variables (cálculo) | D59: =1 -> 1 | E59: =D59*(1+N(E54)) -> 1 | F59: =E59*(1+N(F54)) -> 1 | G59: =F59*(1+N(G54)) -> 1 | H59: =G59*(1+N(H54)) -> 1 | I59: =H59*(1+N(I54)) -> 1 | J59: =I59*(1+N(J54)) -> 1 | K59: =J59*(1+N(K54)) -> 1 | L59: =K59*(1+N(L54)) -> 1 | M59: =L59*(1+N(M54)) -> 1
...

Sheet Productos
A1: Productos — precios, costos unitarios, capacidad y volúmenes (USD por unidad de venta)
A2: Hasta 25 productos. Las columnas «vigente» heredan el presupuesto; sobrescribir lo que cambió.
A4: A. Datos por producto
A5: # | B5: Producto | C5: Unidad | D5: Capacidad inicial (u/año) | E5: Capacidad ampliada (u/año) | F5: Desde año de operación | G5: Precio año 1 — presupuesto | H5: Precio año 1 — vigente | I5: Materia prima /u — presupuesto | J5: Materia prima /u — vigente | K5: Insumos /u — presupuesto | L5: Insumos /u — vigente | M5: Otros variables /u — presupuesto | N5: Otros variables /u — vigente | O5: Nota
A6: 1 | B6: Gabinetes metálicos 153 kg | C6: u | D6: 15000 | E6: 22000 | F6: 3 | G6: 270 | H6: =G6 -> 270 | I6: 82.65 | J6: =I6 -> 82.65 | K6: 45 | L6: =K6 -> 45 | M6: 27.909333 | N6: =M6 -> 27.909333 | O6: Otros variables = consumibles 4,709 (inferido) + flete 23,20 (inferido del cuadro 10a).
A7: 2 | B7: Cajas metálicas 13 kg | C7: u | D7: 90000 | E7: 121000 | F7: 3 | G7: 23 | H7: =G7 -> 23 | I7: 7.41 | J7: =I7 -> 7.41 | K7: 4.851 | L7: =K7 -> 4.851 | M7: 2.73 | N7: =M7 -> 2.73 | O7: Insumos = 339.570/70.000. Otros variables = consumibles 0,65 + flete 2,08 (inferido).
A8: 3 | H8: =G8 -> 0 | J8: =I8 -> 0 | L8: =K8 -> 0 | N8: =M8 -> 0
A9: 4 | H9: =G9 -> 0 | J9: =I9 -> 0 | L9: =K9 -> 0 | N9: =M9 -> 0
A10: 5 | H10: =G10 -> 0 | J10: =I10 -> 0 | L10: =K10 -> 0 | N10: =M10 -> 0
A11: 6 | H11: =G11 -> 0 | J11: =I11 -> 0 | L11: =K11 -> 0 | N11: =M11 -> 0
A12: 7 | H12: =G12 -> 0 | J12: =I12 -> 0 | L12: =K12 -> 0 | N12: =M12 -> 0
A13: 8 | H13: =G13 -> 0 | J13: =I13 -> 0 | L13: =K13 -> 0 | N13: =M13 -> 0
A14: 9 | H14: =G14 -> 0 | J14: =I14 -> 0 | L14: =K14 -> 0 | N14: =M14 -> 0
A15: 10 | H15: =G15 -> 0 | J15: =I15 -> 0 | L15: =K15 -> 0 | N15: =M15 -> 0
A16: 11 | H16: =G16 -> 0 | J16: =I16 -> 0 | L16: =K16 -> 0 | N16: =M16 -> 0
A17: 12 | H17: =G17 -> 0 | J17: =I17 -> 0 | L17: =K17 -> 0 | N17: =M17 -> 0
A18: 13 | H18: =G18 -> 0 | J18: =I18 -> 0 | L18: =K18 -> 0 | N18: =M18 -> 0
A19: 14 | H19: =G19 -> 0 | J19: =I19 -> 0 | L19: =K19 -> 0 | N19: =M19 -> 0
... A30: 25 | H30: =G30 -> 0 | J30: =I30 -> 0 | L30: =K30 -> 0 | N30: =M30 -> 0
A32: B. Ventas en unidades por año de operación — PRESUPUESTO ORIGINAL
A33: # | B33: Producto | C33: Unidad | D33: Año 1 | E33: Año 2 | F33: Año 3 | G33: Año 4 | H33: Año 5 | I33: Año 6 | J33: Año 7 | K33: Año 8 | L33: Año 9 | M33: Año 10 | N33: Total
A34: 1 | B34: =IF(B6="","",B6) -> Gabinetes metálicos 153 kg | C34: =IF(C6="","",C6) -> u | D34: 12000 | E34: 15000 | F34: 18000 | G34: 21000 | H34: 21000 | I34: 21000 | J34: 21000 | K34: 21000 | L34: 21000 | M34: 21000 | N34: =SUM(D34:M34) -> 192000
A35: 2 | B35: =IF(B7="","",B7) -> Cajas metálicas 13 kg | C35: =IF(C7="","",C7) -> u | D35: 70000 | E35: 90000 | F35: 110000 | G35: 120000 | H35: 120000 | I35: 120000 | J35: 120000 | K35: 120000 | L35: 120000 | M35: 120000 | N35: =SUM(D35:M35) -> 1110000
A36: 3 | B36: =IF(B8="","",B8) | C36: =IF(C8="","",C8) | N36: =SUM(D36:M36) -> 0
A37: 4 | B37: =IF(B9="","",B9) | C37: =IF(C9="","",C9) | N37: =SUM(D37:M37) -> 0
A38: 5 | B38: =IF(B10="","",B10) | C38: =IF(C10="","",C10) | N38: =SUM(D38:M38) -> 0
A39: 6 | B39: =IF(B11="","",B11) | C39: =IF(C11="","",C11) | N39: =SUM(D39:M39) -> 0
A40: 7 | B40: =IF(B12="","",B12) | C40: =IF(C12="","",C12) | N40: =SUM(D40:M40) -> 0
A41: 8 | B41: =IF(B13="","",B13) | C41: =IF(C13="","",C13) | N41: =SUM(D41:M41) -> 0
A42: 9 | B42: =IF(B14="","",B14) | C42: =IF(C14="","",C14) | N42: =SUM(D42:M42) -> 0
A43: 10 | B43: =IF(B15="","",B15) | C43: =IF(C15="","",C15) | N43: =SUM(D43:M43) -> 0
A44: 11 | B44: =IF(B16="","",B16) | C44: =IF(C16="","",C16) | N44: =SUM(D44:M44) -> 0
A45: 12 | B45: =IF(B17="","",B17) | C45: =IF(C17="","",C17) | N45: =SUM(D45:M45) -> 0
A46: 13 | B46: =IF(B18="","",B18) | C46: =IF(C18="","",C18) | N46: =SUM(D46:M46) -> 0
A47: 14 | B47: =IF(B19="","",B19) | C47: =IF(C19="","",C19) | N47: =SUM(D47:M47) -> 0
... A58: 25 | B58: =IF(B30="","",B30) | C58: =IF(C30="","",C30) | N58: =SUM(D58:M58) -> 0
B59: Total | D59: =SUM(D34:D58) -> 82000 | E59: =SUM(E34:E58) -> 105000 | F59: =SUM(F34:F58) -> 128000 | G59: =SUM(G34:G58) -> 141000 | H59: =SUM(H34:H58) -> 141000 | I59: =SUM(I34:I58) -> 141000 | J59: =SUM(J34:J58) -> 141000 | K59: =SUM(K34:K58) -> 141000 | ... N59: =SUM(N34:N58) -> 1302000
A61: C. Ventas en unidades por año de operación — VIGENTE (hereda; sobrescribir lo que cambió)
A62: # | B62: Producto | C62: Unidad | D62: Año 1 | E62: Año 2 | F62: Año 3 | G62: Año 4 | H62: Año 5 | I62: Año 6 | J62: Año 7 | K62: Año 8 | L62: Año 9 | M62: Año 10 | N62: Total
A63: 1 | B63: =IF(B6="","",B6) -> Gabinetes metálicos 153 kg | C63: =IF(C6="","",C6) -> u | D63: =D34 -> 12000 | E63: =E34 -> 15000 | F63: =F34 -> 18000 | G63: =G34 -> 21000 | H63: =H34 -> 21000 | I63: =I34 -> 21000 | J63: =J34 -> 21000 | K63: =K34 -> 21000 | ... M63: =M34 -> 21000 | N63: =SUM(D63:M63) -> 192000
...

Sheet Costos
A1: Costos — personal por puesto y costos fijos
A2: Salarios y costos fijos pueden cargarse en PYG o USD (columna Moneda). Se convierten con el TC de cada año.
A4: A. Personal por puesto — salario mensual y dotación por año de operación (PRESUPUESTO ORIGINAL; salario vigente al lado)
A5: # | B5: Puesto | C5: Clase | D5: Moneda | E5: Salario mensual — presupuesto | F5: Salario mensual — vigente | G5: Dot. año 1 | H5: Dot. año 2 | I5: Dot. año 3 | J5: Dot. año 4 | K5: Dot. año 5 | L5: Dot. año 6 | M5: Dot. año 7 | N5: Dot. año 8 | O5: Dot. año 9 | P5: Dot. año 10 | Q5: Nota
A6: 1 | B6: Operador láser | C6: Directo | D6: PYG | E6: 4668900 | F6: =E6 -> 4668900 | G6: 4 | H6: 4 | I6: 5 | J6: 5 | K6: 6 | L6: 6 | M6: 6 | N6: 6 | O6: 6 | P6: 6
A7: 2 | B7: Doblador | C7: Directo | D7: PYG | E7: 3650655 | F7: =E7 -> 3650655 | G7: 8 | H7: 8 | I7: 9 | J7: 9 | K7: 10 | L7: 10 | M7: 10 | N7: 10 | O7: 10 | P7: 10
A8: 3 | B8: Soldador | C8: Directo | D8: PYG | E8: 3968900 | F8: =E8 -> 3968900 | G8: 5 | H8: 5 | I8: 6 | J8: 6 | K8: 6 | L8: 6 | M8: 6 | N8: 6 | O8: 6 | P8: 6
A9: 4 | B9: Baño | C9: Directo | D9: PYG | E9: 3650655 | F9: =E9 -> 3650655 | G9: 2 | H9: 2 | I9: 2 | J9: 2 | K9: 3 | L9: 3 | M9: 3 | N9: 3 | O9: 3 | P9: 3
A10: 5 | B10: Pintor | C10: Directo | D10: PYG | E10: 3650655 | F10: =E10 -> 3650655 | G10: 4 | H10: 4 | I10: 4 | J10: 5 | K10: 5 | L10: 5 | M10: 5 | N10: 5 | O10: 5 | P10: 5
A11: 6 | B11: Montador | C11: Directo | D11: PYG | E11: 3150655 | F11: =E11 -> 3150655 | G11: 10 | H11: 10 | I11: 10 | J11: 11 | K11: 11 | L11: 11 | M11: 11 | N11: 11 | O11: 11 | P11: 11
A12: 7 | B12: Ayudante | C12: Directo | D12: PYG | E12: 2798309 | F12: =E12 -> 2798309 | G12: 10 | H12: 10 | I12: 10 | J12: 11 | K12: 11 | L12: 11 | M12: 11 | N12: 11 | O12: 11 | P12: 11
A13: 8 | B13: Gerente General | C13: Administración | D13: PYG | E13: 18000000 | F13: =E13 -> 18000000 | G13: 1 | H13: 1 | I13: 1 | J13: 1 | K13: 1 | L13: 1 | M13: 1 | N13: 1 | O13: 1 | P13: 1
A14: 9 | B14: Gerente Industrial | C14: Indirecto | D14: PYG | E14: 9800000 | F14: =E14 -> 9800000 | G14: 1 | H14: 1 | I14: 1 | J14: 1 | K14: 1 | L14: 1 | M14: 1 | N14: 1 | O14: 1 | P14: 1
A15: 10 | B15: Coord. Prod. Corte y Deformación | C15: Indirecto | D15: PYG | E15: 6550000 | F15: =E15 -> 6550000 | G15: 1 | H15: 1 | I15: 1 | J15: 1 | K15: 1 | L15: 1 | M15: 1 | N15: 1 | O15: 1 | P15: 1
A16: 11 | B16: Coord. Prod. Soldadura | C16: Indirecto | D16: PYG | E16: 6550000 | F16: =E16 -> 6550000 | G16: 1 | H16: 1 | I16: 1 | J16: 1 | K16: 1 | L16: 1 | M16: 1 | N16: 1 | O16: 1 | P16: 1
A17: 12 | B17: Coord. Prod. Trat. Sup. y Pintura | C17: Indirecto | D17: PYG | E17: 6550000 | F17: =E17 -> 6550000 | G17: 1 | H17: 1 | I17: 1 | J17: 1 | K17: 1 | L17: 1 | M17: 1 | N17: 1 | O17: 1 | P17: 1
... A31: 26 | B31: Asistente Administrativo | C31: Administración | D31: PYG | E31: 2798309 | F31: =E31 -> 2798309 | G31: 1 | H31: 1 | I31: 1 | J31: 1 | K31: 1 | L31: 1 | M31: 1 | N31: 1 | O31: 1 | P31: 1
A32: 27 | F32: =E32 -> 0
A33: 28 | F33: =E33 -> 0
A34: 29 | F34: =E34 -> 0
A35: 30 | F35: =E35 -> 0
B36: Totales de dotación | G36: =SUM(G6:G35) -> 65 | H36: =SUM(H6:H35) -> 65 | I36: =SUM(I6:I35) -> 68 | J36: =SUM(J6:J35) -> 71 | K36: =SUM(K6:K35) -> 74 | L36: =SUM(L6:L35) -> 74 | M36: =SUM(M6:M35) -> 74 | N36: =SUM(N6:N35) -> 74 | ... P36: =SUM(P6:P35) -> 74
B37: Clase: Directo = mano de obra de producción; Indirecto = supervisión, calidad, mantenimiento, depósito (costo de producción); Administración = gerencia general y administración.
A39: B. Dotación VIGENTE por año de operación (hereda; sobrescribir lo que cambió)
A40: # | B40: Puesto | C40: Clase | G40: Dot. año 1 | H40: Dot. año 2 | I40: Dot. año 3 | J40: Dot. año 4 | K40: Dot. año 5 | L40: Dot. año 6 | M40: Dot. año 7 | N40: Dot. año 8 | O40: Dot. año 9 | P40: Dot. año 10
A41: 1 | B41: =IF(B6="","",B6) -> Operador láser | C41: =IF(C6="","",C6) -> Directo | G41: =G6 -> 4 | H41: =H6 -> 4 | I41: =I6 -> 5 | J41: =J6 -> 5 | K41: =K6 -> 6 | L41: =L6 -> 6 | M41: =M6 -> 6 | N41: =N6 -> 6 | ... P41: =P6 -> 6
A42: 2 | B42: =IF(B7="","",B7) -> Doblador | C42: =IF(C7="","",C7) -> Directo | G42: =G7 -> 8 | H42: =H7 -> 8 | I42: =I7 -> 9 | J42: =J7 -> 9 | K42: =K7 -> 10 | L42: =L7 -> 10 | M42: =M7 -> 10 | N42: =N7 -> 10 | ... P42: =P7 -> 10
A43: 3 | B43: =IF(B8="","",B8) -> Soldador | C43: =IF(C8="","",C8) -> Directo | G43: =G8 -> 5 | H43: =H8 -> 5 | I43: =I8 -> 6 | J43: =J8 -> 6 | K43: =K8 -> 6 | L43: =L8 -> 6 | M43: =M8 -> 6 | N43: =N8 -> 6 | ... P43: =P8 -> 6
A44: 4 | B44: =IF(B9="","",B9) -> Baño | C44: =IF(C9="","",C9) -> Directo | G44: =G9 -> 2 | H44: =H9 -> 2 | I44: =I9 -> 2 | J44: =J9 -> 2 | K44: =K9 -> 3 | L44: =L9 -> 3 | M44: =M9 -> 3 | N44: =N9 -> 3 | ... P44: =P9 -> 3
A45: 5 | B45: =IF(B10="","",B10) -> Pintor | C45: =IF(C10="","",C10) -> Directo | G45: =G10 -> 4 | H45: =H10 -> 4 | I45: =I10 -> 4 | J45: =J10 -> 5 | K45: =K10 -> 5 | L45: =L10 -> 5 | M45: =M10 -> 5 | N45: =N10 -> 5 | ... P45: =P10 -> 5
A46: 6 | B46: =IF(B11="","",B11) -> Montador | C46: =IF(C11="","",C11) -> Directo | G46: =G11 -> 10 | H46: =H11 -> 10 | I46: =I11 -> 10 | J46: =J11 -> 11 | K46: =K11 -> 11 | L46: =L11 -> 11 | M46: =M11 -> 11 | N46: =N11 -> 11 | ... P46: =P11 -> 11
A47: 7 | B47: =IF(B12="","",B12) -> Ayudante | C47: =IF(C12="","",C12) -> Directo | G47: =G12 -> 10 | H47: =H12 -> 10 | I47: =I12 -> 10 | J47: =J12 -> 11 | K47: =K12 -> 11 | L47: =L12 -> 11 | M47: =M12 -> 11 | N47: =N12 -> 11 | ... P47: =P12 -> 11
A48: 8 | B48: =IF(B13="","",B13) -> Gerente General | C48: =IF(C13="","",C13) -> Administración | G48: =G13 -> 1 | H48: =H13 -> 1 | I48: =I13 -> 1 | J48: =J13 -> 1 | K48: =K13 -> 1 | L48: =L13 -> 1 | M48: =M13 -> 1 | N48: =N13 -> 1 | ... P48: =P13 -> 1
A49: 9 | B49: =IF(B14="","",B14) -> Gerente Industrial | C49: =IF(C14="","",C14) -> Indirecto | G49: =G14 -> 1 | H49: =H14 -> 1 | I49: =I14 -> 1 | J49: =J14 -> 1 | K49: =K14 -> 1 | L49: =L14 -> 1 | M49: =M14 -> 1 | N49: =N14 -> 1 | ... P49: =P14 -> 1
A50: 10 | B50: =IF(B15="","",B15) -> Coord. Prod. Corte y Deformación | C50: =IF(C15="","",C15) -> Indirecto | G50: =G15 -> 1 | H50: =H15 -> 1 | I50: =I15 -> 1 | J50: =J15 -> 1 | K50: =K15 -> 1 | L50: =L15 -> 1 | M50: =M15 -> 1 | N50: =N15 -> 1 | ... P50: =P15 -> 1
A51: 11 | B51: =IF(B16="","",B16) -> Coord. Prod. Soldadura | C51: =IF(C16="","",C16) -> Indirecto | G51: =G16 -> 1 | H51: =H16 -> 1 | I51: =I16 -> 1 | J51: =J16 -> 1 | K51: =K16 -> 1 | L51: =L16 -> 1 | M51: =M16 -> 1 | N51: =N16 -> 1 | ... P51: =P16 -> 1
A52: 12 | B52: =IF(B17="","",B17) -> Coord. Prod. Trat. Sup. y Pintura | C52: =IF(C17="","",C17) -> Indirecto | G52: =G17 -> 1 | H52: =H17 -> 1 | I52: =I17 -> 1 | J52: =J17 -> 1 | K52: =K17 -> 1 | L52: =L17 -> 1 | M52: =M17 -> 1 | N52: =N17 -> 1 | ... P52: =P17 -> 1
... A70: 30 | B70: =IF(B35="","",B35) | C70: =IF(C35="","",C35) | G70: =G35 -> 0 | H70: =H35 -> 0 | I70: =I35 -> 0 | J70: =J35 -> 0 | K70: =K35 -> 0 | L70: =L35 -> 0 | M70: =M35 -> 0 | N70: =N35 -> 0 | ... P70: =P35 -> 0
B71: Totales de dotación vigente | G71: =SUM(G41:G70) -> 65 | H71: =SUM(H41:H70) -> 65 | I71: =SUM(I41:I70) -> 68 | J71: =SUM(J41:J70) -> 71 | K71: =SUM(K41:K70) -> 74 | L71: =SUM(L41:L70) -> 74 | M71: =SUM(M41:M70) -> 74 | N71: =SUM(N41:N70) -> 74 | ... P71: =SUM(P41:P70) -> 74
A73: C. Costos fijos y gastos (monto mensual del año 1)
...

Sheet Inversion
A1: Inversión y financiamiento — CAPEX por ítem, préstamos y aportes (USD)
A2: Costo final estimado = ejecutado + comprometido pendiente + por contratar. Los pendientes se pagan en el «mes de pago pendiente».
A4: A. Inversiones (CAPEX)
A5: # | B5: Ítem | C5: Clase | D5: Presupuesto original | E5: Mes de pago (presup.) | F5: Vida útil (años) | G5: Ejecutado (devengado real) | H5: Pagado (real) | I5: Comprometido pendiente | J5: Por contratar (si difiere) | K5: Mes de pago pendiente (si difiere) | L5: Mes de puesta en servicio real | M5: Por contratar usado | N5: Costo final estimado | O5: Desvío vs presupuesto | P5: Avance financiero | Q5: Mes de pago pendiente usado | R5: Pendiente devengado + comprometido | S5: Servicio (presup.) | T5: Servicio (vigente) | U5: Base depreciable vigente
A6: 1 | B6: Adecuación de infraestructura | C6: Infraestructura | D6: 87000 | E6: 1 | F6: 10 | M6: =IF(J6<>"",N(J6),MAX(0,N(D6)-N(G6)-N(I6))) -> 87000 | N6: =N(G6)+N(I6)+M6 -> 87000 | O6: =N6-N(D6) -> 0 | P6: =IF(N6>0,N(H6)/N6,"") -> 0 | Q6: =IF(K6<>"",K6,MAX(N(E6),Corte+1)) -> 1 | R6: =N(G6)-N(H6)+N(I6) -> 0 | S6: =MAX(N(E6),P_Inicio) -> 1 | T6: =IF(L6<>"",L6,MAX(N(E6),V_Inicio)) -> 1 | U6: =N(G6)+N(I6)+M6*(1+V_dCapex) -> 87000
A7: 2 | B7: Conjunto línea de pintura | C7: Maquinaria | D7: 183073.6 | E7: 1 | F7: 10 | M7: =IF(J7<>"",N(J7),MAX(0,N(D7)-N(G7)-N(I7))) -> 183073.6 | N7: =N(G7)+N(I7)+M7 -> 183073.6 | O7: =N7-N(D7) -> 0 | P7: =IF(N7>0,N(H7)/N7,"") -> 0 | Q7: =IF(K7<>"",K7,MAX(N(E7),Corte+1)) -> 1 | R7: =N(G7)-N(H7)+N(I7) -> 0 | S7: =MAX(N(E7),P_Inicio) -> 1 | T7: =IF(L7<>"",L7,MAX(N(E7),V_Inicio)) -> 1 | U7: =N(G7)+N(I7)+M7*(1+V_dCapex) -> 183073.6
A8: 3 | B8: Cortadoras láser (2) | C8: Maquinaria | D8: 84295.23 | E8: 1 | F8: 10 | M8: =IF(J8<>"",N(J8),MAX(0,N(D8)-N(G8)-N(I8))) -> 84295.23 | N8: =N(G8)+N(I8)+M8 -> 84295.23 | O8: =N8-N(D8) -> 0 | P8: =IF(N8>0,N(H8)/N8,"") -> 0 | Q8: =IF(K8<>"",K8,MAX(N(E8),Corte+1)) -> 1 | R8: =N(G8)-N(H8)+N(I8) -> 0 | S8: =MAX(N(E8),P_Inicio) -> 1 | T8: =IF(L8<>"",L8,MAX(N(E8),V_Inicio)) -> 1 | U8: =N(G8)+N(I8)+M8*(1+V_dCapex) -> 84295.23
A9: 4 | B9: Manipulador | C9: Maquinaria | D9: 10197 | E9: 1 | F9: 10 | M9: =IF(J9<>"",N(J9),MAX(0,N(D9)-N(G9)-N(I9))) -> 10197 | N9: =N(G9)+N(I9)+M9 -> 10197 | O9: =N9-N(D9) -> 0 | P9: =IF(N9>0,N(H9)/N9,"") -> 0 | Q9: =IF(K9<>"",K9,MAX(N(E9),Corte+1)) -> 1 | R9: =N(G9)-N(H9)+N(I9) -> 0 | S9: =MAX(N(E9),P_Inicio) -> 1 | T9: =IF(L9<>"",L9,MAX(N(E9),V_Inicio)) -> 1 | U9: =N(G9)+N(I9)+M9*(1+V_dCapex) -> 10197
A10: 5 | B10: Dobladoras (4) | C10: Maquinaria | D10: 151967.08 | E10: 1 | F10: 10 | M10: =IF(J10<>"",N(J10),MAX(0,N(D10)-N(G10)-N(I10))) -> 151967.08 | N10: =N(G10)+N(I10)+M10 -> 151967.08 | O10: =N10-N(D10) -> 0 | P10: =IF(N10>0,N(H10)/N10,"") -> 0 | Q10: =IF(K10<>"",K10,MAX(N(E10),Corte+1)) -> 1 | R10: =N(G10)-N(H10)+N(I10) -> 0 | S10: =MAX(N(E10),P_Inicio) -> 1 | T10: =IF(L10<>"",L10,MAX(N(E10),V_Inicio)) -> 1 | U10: =N(G10)+N(I10)+M10*(1+V_dCapex) -> 151967.08
A11: 6 | B11: Soldadoras (6) | C11: Maquinaria | D11: 3399 | E11: 1 | F11: 10 | M11: =IF(J11<>"",N(J11),MAX(0,N(D11)-N(G11)-N(I11))) -> 3399 | N11: =N(G11)+N(I11)+M11 -> 3399 | O11: =N11-N(D11) -> 0 | P11: =IF(N11>0,N(H11)/N11,"") -> 0 | Q11: =IF(K11<>"",K11,MAX(N(E11),Corte+1)) -> 1 | R11: =N(G11)-N(H11)+N(I11) -> 0 | S11: =MAX(N(E11),P_Inicio) -> 1 | T11: =IF(L11<>"",L11,MAX(N(E11),V_Inicio)) -> 1 | U11: =N(G11)+N(I11)+M11*(1+V_dCapex) -> 3399
A12: 7 | B12: Lijadoras (4) | C12: Maquinaria | D12: 589.16 | E12: 1 | F12: 10 | M12: =IF(J12<>"",N(J12),MAX(0,N(D12)-N(G12)-N(I12))) -> 589.16 | N12: =N(G12)+N(I12)+M12 -> 589.16 | O12: =N12-N(D12) -> 0 | P12: =IF(N12>0,N(H12)/N12,"") -> 0 | Q12: =IF(K12<>"",K12,MAX(N(E12),Corte+1)) -> 1 | R12: =N(G12)-N(H12)+N(I12) -> 0 | S12: =MAX(N(E12),P_Inicio) -> 1 | T12: =IF(L12<>"",L12,MAX(N(E12),V_Inicio)) -> 1 | U12: =N(G12)+N(I12)+M12*(1+V_dCapex) -> 589.16
