Workbook
Name AmortizaciónInterés: -IPMT('[1]Calculadora de préstamos'!TasaInterés/12,'[1]Calculadora de préstamos'!NúmeroDePago,'[1]Calculadora de préstamos'!NúmeroDePagos,'[1]Calculadora de préstamos'!CantidadPréstamo)
Name PagoMensual: -PMT('[2]Calculadora de préstamos'!TasaInterés/12,'[2]Calculadora de préstamos'!NúmeroDePagos,'[2]Calculadora de préstamos'!CantidadPréstamo)
Name PréstamoNoPagado: IF([1]!NúmeroDePago<=[1]!NúmeroDePagos,1,0)
Name PréstamoPagado: IF([1]!CantidadPréstamo*[1]!TasaInterés*'[1]Calculadora de préstamos'!AñosPréstamo*'[1]Calculadora de préstamos'!FechaInicioPréstamo>0,1,0)
Name Principal: -PPMT([1]!TasaInterés/12,[1]!NúmeroDePago,[1]!NúmeroDePagos,[1]!CantidadPréstamo)
Name SCS: IF('[2]Calculadora de préstamos'!CantidadPréstamo*'[2]Calculadora de préstamos'!TasaInterés*'[2]Calculadora de préstamos'!AñosPréstamo*'[2]Calculadora de préstamos'!FechaInicioPréstamo>0,1,0)
Name ÚltimaFila: MATCH(9.99E+307,'[1]Calculadora de préstamos'!$B:$B)
Name USD: Ej_Costos!$O$1

Sheet PASO A PASO
B2: PASO A PASO — ACTUALIZAR EL PLAN DE NEGOCIOS CON NUEVAS PROYECCIONES DE VENTAS
B3: Alianza del Acero · Modelo a 10 años (Año 1 = 2026 … Año 10 = 2035) · Libro base: INFORME2 ajustado a 10 años (09/06/2026) · Guía preparada el 13/10/2026 y actualizada el 16/10/2026 · Controles y datos para el PowerPoint en la hoja «CONTROLES Y PPT».
B5: CÓMO USAR ESTA GUÍA
B6: • | C6: Seguir las fases en orden: A Preparar → B Correcciones únicas → C Ventas → D Costos → E Caja y préstamos CP → F Resultados y controles → G PowerPoint. Al terminar cada fase presionar F9 y revisar en «CONTROLES Y PPT» los controles que indica cada paso (columna «Control / resultado esperado»). Los controles 13, 14 y 23 (caja, préstamos CP y dividendos) recién deben quedar en OK al terminar la fase E; en el paso F1, todos (salvo el 13 si depende de la decisión de dividendos: paso E5).
B7: • | C7: Columna «Dónde»: hacer clic para ir a la celda. Los vínculos a hojas ocultas funcionan después del paso A3.
B8: • | C8: Colores del modelo: relleno azul claro = dato real; relleno amarillo = proyección cargada a mano; fuente verde = plan original (no se toca). En estas dos hojas, fuente azul sobre amarillo = dato de entrada o referencia fija.
B9: • | C9: Las fórmulas de esta guía están escritas para Excel en español (separador «;»). Si su Excel usa «,» como separador, reemplazarlo.
B10: • | C10: Escribir solo en las celdas indicadas. No escribir en columnas de total o promedio (O y AD de Ej_Producción, Ej_Ingresos, Ej_Costos, Ej_Resultados y Ej_Deuda; O, AB, AO, BB, BO, CB, CO, DB, DO, EB y EF de Ej_Flujo), salvo las celdas que un paso indica expresamente: Ej_Producción!O31:O32 y O46:O47 (B4), Ej_Costos!O9:O19 y AD9:AD19 (B5), Ej_Costos!O1 (D2) y Ej_Flujo!O37 y O40 (E2). Tampoco en el plan original (columnas P y AE de esas cinco hojas, salvo el rótulo Ej_Costos!P1, que se actualiza en el paso D2; columna E de Supuestos). En Ej_Flujo no hay columnas de plan: P, AD y AE son meses (ene-2027, feb-2028 y mar-2028) y se editan cuando un paso lo indica. El auxiliar Ej_Costos!O88:P114 (paso D5) no es plan ni total.
B11: • | C11: Trabajar sobre este libro (INFORME2). El libro «ORIGINAL» es casi idéntico, pero tiene #¡REF! en Payback y depende de este archivo por un vínculo externo: no copiar celdas desde él.
B13: CRITERIOS DEL MODELO (mantenerlos; si alguno cambia, anotarlo en el registro del final)
B14: # | C14: Tema | D14: Criterio
B15: 1 | C15: Horizonte | D15: Año 1 = 2026 (real hasta el corte + proyección); Año 2 = 2027 (proyección mensual); Años 3-10 = 2028-2035 (proyección anual).
B16: 2 | C16: Volumen años 1 y 2 | D16: Tn producidas y vendidas por producto y mes en Ej_Producción (filas 22-32 producción; 37-47 ventas). El modelo a 10 años toma los totales (columnas O y AD).
B17: 3 | C17: Volumen años 3-10 | D17: Producción = año anterior × (1 + Supuestos!B11, hoy 5%). Venta = producción × (1 − Supuestos!B8, merma 1,5%). Igual para los 11 productos.
B18: 4 | C18: Precio | D18: Años 1 y 2: promedio ponderado por Tn de Ej_Ingresos (filas 8-18, USD/Tn sin IVA, régimen maquila). Año 3 = año 2 × (1 + B14, 5%); años 4-10 = año anterior × (1 + B15, 2%).
B19: 5 | C19: Costo de materia prima | D19: USD/Tn por producto y mes en Ej_Costos (filas 9-19) × Tn PRODUCIDAS. Años 3-10: costo/Tn promedio de 2027 × (1 + B18, 3%) por año.
B20: 6 | C20: Otros costos | D20: Insumos, packaging, mantenimiento y movimiento de carga: en 2026, tarifa del plan por Tn × Tn del mes (el mantenimiento 2026 está tipeado); en 2027, plan × (2 − MP plan / MP proyectada), repartido por las Tn de cada mes. Años 3-10: insumos (Supuestos!B61 × Tn producidas), packaging (B62 × MP) y seguro caución (20% × 1,8% × MP) siguen al volumen; mantenimiento, movimiento de carga y energía crecen 10% anual fijo (Costos filas 11, 15 y 16) y no cambian con la prospección. Mano de obra y gastos fijos no siguen al volumen: la MO crece 3% anual desde el año 3 (cargas 43,09%; en los años 1-2 el factor 1,42 está incluido).
B21: 7 | C21: Capital de trabajo | D21: Días de Supuestos!B77:B83: caja 2, sueldos 15, stock MP 45, ventas a crédito 90, producto terminado 0, crédito de proveedores de MP 0 (sin crédito del proveedor de chapa) y proveedores menores 15. En el flujo mensual, las ventas se cobran a los 3 meses.
B22: 8 | C22: Impuesto | D22: Tributo maquila: 1% de las ventas (Supuestos!B68).
B23: 9 | C23: Préstamos CP para chapas | D23: Desembolsos tipeados en Ej_Flujo fila 8; devolución en la fila 16; interés 8% sobre la devolución (fila 17). El interés baja la utilidad, pero no entra al VAN.
B24: 10 | C24: Valuación | D24: VAN a 10 años al WACC (9,87%), sin valor terminal, con recupero del capital de trabajo en el año 10; TIR del mismo flujo (VAN-TIR fila 15). Es el método con que se calculó el VAN del plan: no cambiarlo.
B25: 11 | C25: Payback | D25: Inversión propia: dividendos descontados a Ke (16,32%) contra el aporte propio (USD 606.000). Los dividendos siguen un calendario fijo que empieza en el año 6 (Resultados filas 18 y 26-31).
B26: 12 | C26: Plan original | D26: En el libro solo están el plan de los años 1 y 2 (columnas P y AE de Ej_Producción, Ej_Ingresos, Ej_Costos, Ej_Resultados y Ej_Deuda) y los supuestos originales (Supuestos, columna E). En «CONTROLES Y PPT», el VAN, la TIR, el payback y los rótulos acumulados del plan están en la sección 4, y las series plan de los gráficos (los 10 años, copiadas del PPT de junio) en la sección 3, filas 82, 85, 87 y 89.
B28: FASE A — PREPARAR LA ACTUALIZACIÓN
B29: Paso | C29: Qué hacer | D29: Dónde | E29: Cómo / criterio | F29: Control / resultado esperado
B30: A1 | C30: Guardar una copia con versión | D30: (libro) | E30: Archivo > Guardar como: «…_RV01_PROSPECCION_AAAAMMDD.xlsx». Trabajar siempre sobre la copia y conservar la versión anterior para comparar. Antes de la fase G, hacer lo mismo con el PowerPoint (Informe_Ejecutivo_Plan_vs_Actualizado_ALIANZA_DEL_ACERO_10_AÑOS.pptx): guardarlo con un nombre nuevo («…_RV01_AAAAMMDD.pptx») y editar solo la copia. | F30: El nombre del libro indica versión y fecha (y, antes de empezar la fase G, también el del PPT).
B31: A2 | C31: Abrir sin actualizar vínculos y con cálculo automático | D31: Servicio Deuda!D18 | E31: Al abrir el libro, ante el aviso de vínculos externos, elegir «No actualizar»: la deuda LP de 'Servicio Deuda'!D18:I20 viene del archivo CALCULADORA PRESTAMO, que no está en este equipo. En Datos > Editar vínculos se puede confirmar que el vínculo quedó sin actualizar. Fórmulas > Opciones para el cálculo > Automático. | F31: Después del paso A3 (la hoja Servicio Deuda está oculta): 'Servicio Deuda'!D18 sigue en 29.277,76, sin error.
B32: A3 | C32: Mostrar las hojas ocultas y expandir los grupos | D32: Ej_Producción!B6 | E32: Hojas ocultas: Ej_Producción, Ej_Ingresos, Ej_Costos, Ej_Resultados, Ej_Deuda, Dashboard Ejec., Productos, Maquinaria, Mano de Obra, Servicio Deuda, Depreciación, IVA y Estr. Costos. Clic derecho en una pestaña > Mostrar (una vez por hoja). En Ej_Producción y Ej_Ingresos expandir filas y columnas con los botones de nivel «2». En Ej_Costos mostrar las filas 22-34. En Ej_Ingresos: Vista > Inmovilizar > Movilizar paneles y volver a inmovilizar en C8. | F32: Se ven los meses ene…dic de 2026 y 2027.
B33: A4 | C33: Guardar la foto «antes» | D33: CONTROLES Y PPT, sección 2 | E33: La columna «PPT jun-2026» de la sección 2 ya guarda las cifras de la versión anterior. Antes de cargar, copiar la columna «Libro (vivo)» y pegarla como valores en una hoja «Foto_antes». Sirve para explicar las variaciones. | F33: Hoy: VAN 2.844.948; TIR 14,92%; EBITDA acumulado 25,4M.
B34: A5 | C34: Definir el corte y reunir la prospección | D34: — | E34: Definir el último mes real (hoy el libro tiene volúmenes reales hasta mayo-2026 y precios hasta abril-2026). Reunir por producto y mes: Tn producidas, Tn vendidas y precio USD/Tn sin IVA del resto de 2026 y de 2027; costo de chapa USD/Tn; dotación de personal. Para 2028-2035: tasas de crecimiento, o Tn y precio por producto y año. | F34: Información con fuente y fecha (Comercial, Compras, RR. HH.).
B36: FASE B — CORRECCIONES ÚNICAS (una sola vez, antes de cargar; sin ellas la nueva prospección no llega a la caja ni al payback)
B37: Paso | C37: Qué hacer | D37: Dónde | E37: Cómo / criterio | F37: Control / resultado esperado
B38: B1 | C38: Vincular los cobros 2028-2036 (hoy son valores pegados) | D38: Ej_Flujo!AC6 | E38: Mismo criterio del modelo (venta anual / 12, cobrada a 90 días). AC6 =Ej_Ingresos!AA34; AD6 =Ej_Ingresos!AB34; AE6 =Ej_Ingresos!AC34. AF6:AN6 y AP6:AR6 =$AF$40; AS6:BA6 y BC6:BE6 =$AS$40; BF6:BN6 y BP6:BR6 =$BF$40; BS6:CA6 y CC6:CE6 =$BS$40; CF6:CN6 y CP6:CR6 =$CE$40; CS6:DA6 y DC6:DE6 =$CS$40; DF6:DN6 y DP6:DR6 =$DF$40; DS6:EA6 y EC6:EE6 =$DS$40. No escribir en las columnas de total. Con los datos actuales los valores no cambian (se verificó celda por celda). | F38: Controles 10 y 11 en OK.
B39: B2 | C39: Vincular el impuesto maquila 2028-2035 (hoy repite el de 2027) | D39: Ej_Flujo!AC24 | E39: Se paga al mes siguiente. AC24 =Ej_Resultados!AC18; AD24:AN24 y AP24 =Resultados!$E$13/12; AQ24:BA24 y BC24 =Resultados!$F$13/12; BD24:BN24 y BP24 =Resultados!$G$13/12; BQ24:CA24 y CC24 =Resultados!$H$13/12; CD24:CN24 y CP24 =Resultados!$I$13/12; CQ24:DA24 y DC24 =Resultados!$J$13/12; DD24:DN24 y DP24 =Resultados!$K$13/12; DQ24:EA24 =Resultados!$L$13/12. | F39: Control 12 en OK.
B40: B3 | C40: Completar las cuotas LP de jul-oct 2031 (faltan) | D40: Ej_Flujo!AC23 | E40: AC23:AN23 =('Servicio Deuda'!$F$23+'Servicio Deuda'!$F$24+'Servicio Deuda'!$F$25)/12; AP23:BA23 igual con la columna G; BC23:BN23 con la H; BP23:BY23 =('Servicio Deuda'!$I$23+'Servicio Deuda'!$I$24+'Servicio Deuda'!$I$25)/10. Agrega unos USD 464.000 de egresos en jul-oct 2031 (4 × 116.058) y, neto de la baja de las cuotas de ene-2028 a jun-2031 (≈ USD 77.000), unos USD 387.000 (≈ valor actual del control 17). Después hay que revisar los préstamos CP (paso E3). | F40: Control 17 en OK.
B41: B4 | C41: Crear los totales 2026 de Steel Frame y Accesorios y vincular Producción!D26 | D41: Ej_Producción!O31 | E41: En Ej_Producción escribir O31 =SUMA(C31:N31) y copiarla a O32; escribir O46 =SUMA(C46:N46) y copiarla a O47 (hoy las cuatro están vacías, a diferencia de O30 y O45). Luego Producción!D26 =+Ej_Producción!O32 (hoy es un 0 tipeado; D24, D25 y D27 ya apuntan a O31, O46 y O47). Sin esto, si Steel Frame o Accesorios producen o venden en 2026, su volumen no llega al modelo anual: Tn, precio promedio (Ej_Ingresos!O17:O18) y costo/Tn (Ej_Costos!O18:O19) quedan en 0. | F41: Control 9 en OK.
B42: B5 | C42: Proteger el costo/Tn y reparar los productos 4, 10 y 11 | D42: Ej_Costos!O9 | E42: O9 =SI(Ej_Producción!O22=0;0;O23/Ej_Producción!O22) y copiar a O10:O19 (reemplaza los 0 tipeados de O18:O19). AD9 =SI(Ej_Producción!AD22=0;0;AD23/Ej_Producción!AD22) y copiar a AD10:AD19. Copiar E26 en C26:D26 (falta la fórmula de ene-feb del producto 4). | F42: Control 25 en OK (sin #¡DIV/0! si un producto queda en 0 Tn).
B43: B6 | C43: Corregir los exponentes del payback de la inversión total | D43: Payback!D11 | E43: Hoy todas las columnas descuentan con ^1. D11 ='VAN-TIR'!D28/(1+Supuestos!$B$73)^(COLUMNA()-COLUMNA($C$11)) y copiar hasta M11 (equivale a ^1, ^2 … ^10). | F43: Control 22 en OK (Payback!M12 ≈ 986.333 con los datos actuales).
B44: B7 | C44: Calcular el payback con fórmula (hoy es texto tipeado) | D44: Payback!C8 | E44: En Payback!B8 escribir el rótulo «Payback inversión propia (años)» y en Payback!C8: =SI.ERROR(CONTAR.SI(D7:M7;"<0")+(-INDICE(C7:M7;CONTAR.SI(C7:M7;"<0")))/INDICE(C6:M6;CONTAR.SI(C7:M7;"<0")+1);"No recupera en 10 años"). En Payback!B13 escribir «Payback inversión total (años)» y en Payback!C13: =SI.ERROR(CONTAR.SI(D12:M12;"<0")+(-INDICE(C12:M12;CONTAR.SI(C12:M12;"<0")))/INDICE(C11:M11;CONTAR.SI(C12:M12;"<0")+1);"No recupera en 10 años"). Luego Dashboard!C12 =Payback!C8 y Dashboard!C13 =Payback!C13 (hoy dicen «4 Años» y «7 Años» tipeados), con formato 0,0 "años". | F44: Control 21 en OK. Hoy: propia 6,4 años (recupera en el año 7); total ≈ 8,1 años después de B6.
B45: B8 | C45: Vincular los demás egresos operativos 2028-2035 (hoy son valores pegados) | D45: Ej_Flujo!AC13 | E45: Mismo mapeo que 2027, con el costo anual de la hoja Costos / 12. Para 2028: AC13:AN13 =(Costos!$F$10+Costos!$F$13+Costos!$F$27)/12 (insumos, packaging y honorarios); AC19:AN19 =(Costos!$F$7+Costos!$F$8+Costos!$F$14+Costos!$F$20+Costos!$F$21)/12 (nómina y alimentación); AC21:AN21 =(Costos!$F$16+Costos!$F$22+Costos!$F$23)/12 (energía, servicios y alquileres); AC22:AN22 =(Costos!$F$9+Costos!$F$11+Costos!$F$12+Costos!$F$15+Costos!$F$24+Costos!$F$25+Costos!$F$26)/12 (otros). Repetir con la columna G de Costos en AP:BA, H en BC:BN, I en BP:CA, J en CC:CN, K en CP:DA, L en DC:DN y M en DP:EA, sin escribir en las columnas de total. Hoy esas filas son valores pegados, iguales en los ocho años 2028-2035 (parecidos a 2027, pero no iguales en las filas 13 y 22), y no siguen al volumen: el cambio agrega ≈ USD 1,62M de egresos en 2028-2035. Atención: la fila 25 («Inversiones / CAPEX») repite desde feb-2027 los servicios de terceros de Steel Frame que ya están en la fila 22 (USD 3.750/mes; 371.250 en 2027-2035). Confirmarlo con quien armó el modelo; si es una duplicación, dejar en 0 las columnas de mes de la fila 25 desde feb-2027 y anotarlo en el registro. | F45: Control 26 en OK. Con B2, B3 y B8 la caja empeora: es esperable y se resuelve en E3 y E5.
...

Sheet CONTROLES Y PPT
B2: CONTROLES DEL MODELO Y DATOS PARA EL POWERPOINT
B3: Las celdas de las columnas «Valor», «Libro» y de los años son fórmulas vivas: se recalculan al cargar la nueva prospección. Los valores en fuente azul son referencias fijas (plan original y PPT de junio 2026). Ver la hoja «PASO A PASO».
B5: 1. CONTROLES (todos en OK antes de pasar al PowerPoint, salvo el 13 si depende de la decisión de dividendos: ver paso E5)
B6: # | C6: Control | D6: Qué compara | E6: Valor | F6: Esperado | G6: Estado | H6: Si da REVISAR: qué hacer (paso de la hoja PASO A PASO)
B7: 1 | C7: Producción año 1 = detalle mensual (Tn) | D7: Producción!D28 − SUMA(Ej_Producción!C22:N32) | E7: =ROUND('Producción'!D28-SUM('Ej_Producción'!C22:N32),2) -> 0 | F7: 0 | G7: =IF(ABS(E7)<0.5,"OK","REVISAR") -> OK | H7: B4 (totales Ej_Producción!O31:O32 y Producción!D26) y C1-C2: revisar que Producción!D6:D26 (filas pares) tomen Ej_Producción!O22:O32.
B8: 2 | C8: Producción año 2 = detalle mensual (Tn) | D8: Producción!E28 − SUMA(Ej_Producción!R22:AC32) | E8: =ROUND('Producción'!E28-SUM('Ej_Producción'!R22:AC32),2) -> 0 | F8: 0 | G8: =IF(ABS(E8)<0.5,"OK","REVISAR") -> OK | H8: C3: revisar Ej_Producción!R22:AC32 y que Producción!E6:E26 tomen la columna AD.
B9: 3 | C9: Ventas años 1 y 2 = detalle mensual (Tn) | D9: |Producción!D29 − SUMA(Ej_Producción!C37:N47)| + |E29 − SUMA(R37:AC47)| | E9: =ROUND(ABS('Producción'!D29-SUM('Ej_Producción'!C37:N47))+ABS('Producción'!E29-SUM('Ej_Producción'!R37:AC47)),2) -> 0 | F9: 0 | G9: =IF(ABS(E9)<0.5,"OK","REVISAR") -> OK | H9: B4 (totales Ej_Producción!O46:O47) y C1-C3: revisar Ej_Producción filas 37-47 (ventas).
B10: 4 | C10: Ingresos años 1 y 2 = detalle mensual (USD) | D10: |Ingresos!D28 − Ej_Ingresos!O34| + |E28 − AD34| | E10: =ROUND(ABS('Ingresos'!D28-'Ej_Ingresos'!O34)+ABS('Ingresos'!E28-'Ej_Ingresos'!AD34),2) -> 0 | F10: 0 | G10: =IF(ABS(E10)<1,"OK","REVISAR") -> OK | H10: C1-C3: revisar precios Ej_Ingresos!C8:AC18 y que Ingresos!D/E tomen las columnas O/AD. Si Steel Frame o Accesorios venden en 2026, verificar los totales Ej_Producción!O46:O47 (paso B4).
B11: 5 | C11: Meses con venta y sin precio (cantidad) | D11: Tn vendidas > 0 con precio = 0 (2026 y 2027) | E11: =SUMPRODUCT(('Ej_Producción'!C37:N47>0)*('Ej_Ingresos'!C8:N18=0))+SUMPRODUCT(('Ej_Producción'!R37:AC47>0)*('Ej_Ingresos'!R8:AC18=0)) -> 0 | F11: 0 | G11: =IF(E11=0,"OK","REVISAR") -> OK | H11: C1-C3: cargar el precio USD/Tn de cada mes con venta.
B12: 6 | C12: Meses con producción y sin costo de chapa (cantidad) | D12: Tn producidas > 0 con USD/Tn = 0 (2026 y 2027) | E12: =SUMPRODUCT(('Ej_Producción'!C22:N32>0)*('Ej_Costos'!C9:N19=0))+SUMPRODUCT(('Ej_Producción'!R22:AC32>0)*('Ej_Costos'!R9:AC19=0)) -> 0 | F12: 0 | G12: =IF(E12=0,"OK","REVISAR") -> OK | H12: D3: cargar el costo USD/Tn de chapa en Ej_Costos para cada mes con producción.
B13: 7 | C13: Venta ≤ producción, años 1 y 2 (Tn) | D13: Mínimo de (producción − venta) año 1 y año 2 | E13: =ROUND(MIN('Producción'!D28-'Producción'!D29,'Producción'!E28-'Producción'!E29),2) -> 0 | F13: ≥ 0 | G13: =IF(E13>=0,"OK","REVISAR") -> OK | H13: C2-C3: la venta no puede superar la producción (salvo stock inicial documentado).
B14: 8 | C14: Materia prima igual en Ej_Costos, Costos y Materia Prima (USD) | D14: Años 1 y 2: Materia Prima!D28/E28 vs Costos!D6/E6 vs Ej_Costos!O22/AD22 | E14: =ROUND(ABS('Materia Prima'!D28-'Costos'!D6)+ABS('Costos'!D6-'Ej_Costos'!O22)+ABS('Materia Prima'!E28-'Costos'!E6)+ABS('Costos'!E6-'Ej_Costos'!AD22),2) -> 0 | F14: 0 | G14: =IF(ABS(E14)<1,"OK","REVISAR") -> OK | H14: B4 (totales Ej_Producción!O31:O32 y Producción!D26) y B5 (Ej_Costos!O18:O19 con fórmula).
B15: 9 | C15: Steel Frame y Accesorios del año 1 vinculados | D15: ¿Producción!D26 y Ej_Producción!O31, O32, O46 y O47 son fórmulas? | E15: =AND(_xlfn.ISFORMULA('Producción'!D26),_xlfn.ISFORMULA('Ej_Producción'!O31),_xlfn.ISFORMULA('Ej_Producción'!O32),_xlfn.ISFORMULA('Ej_Producción'!O46),_xlfn.ISFORMULA('Ej_Producción'!O47)) -> FALSE | F15: VERDADERO | G15: =IF(E15=TRUE,"OK","REVISAR") -> REVISAR | H15: B4: crear los totales Ej_Producción!O31, O32, O46 y O47 (hoy vacíos) y escribir =+Ej_Producción!O32 en Producción!D26.
B16: 10 | C16: Cobros 2026-2036 = ventas de los 10 años (USD) | D16: Suma de cobros de Ej_Flujo (totales) − SUMA(Ingresos!D28:M28) | E16: =ROUND(('Ej_Flujo'!O6+'Ej_Flujo'!AB6+'Ej_Flujo'!AO6+'Ej_Flujo'!BB6+'Ej_Flujo'!BO6+'Ej_Flujo'!CB6+'Ej_Flujo'!CO6+'Ej_Flujo'!DB6+'Ej_Flujo'!DO6+'Ej_Flujo'!EB6+'Ej_Flujo'!EF6)-SUM('Ingresos'!D28:M28),2) -> 0 | F16: 0 | G16: =IF(ABS(E16)<1,"OK","REVISAR") -> OK | H16: B1: vincular los cobros 2028-2036 (Ej_Flujo!AC6:EE6).
B17: 11 | C17: Cobros 2028-2036 vinculados a las ventas | D17: ¿Ej_Flujo!AF6 es fórmula? | E17: =_xlfn.ISFORMULA('Ej_Flujo'!AF6) -> FALSE | F17: VERDADERO | G17: =IF(E17=TRUE,"OK","REVISAR") -> REVISAR | H17: B1: hoy son valores pegados; no cambian con la nueva prospección.
B18: 12 | C18: Impuesto maquila pagado 2028-2035 = Resultados (USD) | D18: Ej_Flujo fila 24 (totales 2028-2035) − (impuesto dic-2027 + SUMA(Resultados!E13:L13) − 1/12 de L13) | E18: =ROUND(('Ej_Flujo'!AO24+'Ej_Flujo'!BB24+'Ej_Flujo'!BO24+'Ej_Flujo'!CB24+'Ej_Flujo'!CO24+'Ej_Flujo'!DB24+'Ej_Flujo'!DO24+'Ej_Flujo'!EB24)-('Ej_Resultados'!AC18+SUM('Resultados'!E13:L13)-'Resultados'!L13/12),2) -> -612871.03 | F18: 0 | G18: =IF(ABS(E18)<1,"OK","REVISAR") -> REVISAR | H18: B2: vincular Ej_Flujo!AC24:EA24 al 1% de las ventas de cada año (se paga al mes siguiente).
B19: 13 | C19: Saldo de caja mensual mínimo, ago-2026 a dic-2035 (USD) | D19: MIN(Ej_Flujo!J29:EA29) | E19: =ROUND(MIN('Ej_Flujo'!J29:EA29),2) -> -245725.67 | F19: ≥ 0 | G19: =IF(E19>=0,"OK","REVISAR") -> REVISAR | H19: E3: redimensionar los préstamos CP (Ej_Flujo fila 8) hasta que el saldo no sea negativo. Es normal que siga en REVISAR hasta terminar la fase E: la fase B lo empeora.
B20: 14 | C20: Préstamos CP: desembolsado − devuelto (USD) | D20: Ej_Flujo fila 8 − fila 16, 2026-2035 (sin L16, que es la devolución a CIE S.A.) | E20: =ROUND(('Ej_Flujo'!O8+'Ej_Flujo'!AB8+'Ej_Flujo'!AO8+'Ej_Flujo'!BB8+'Ej_Flujo'!BO8+'Ej_Flujo'!CB8+'Ej_Flujo'!CO8+'Ej_Flujo'!DB8+'Ej_Flujo'!DO8+'Ej_Flujo'!EB8)-(SUM('Ej_Flujo'!C16:K16)+SUM('Ej_Flujo'!M16:N16)+'Ej_Flujo'!AB16+'Ej_Flujo'!AO16+'Ej_Flujo'!BB16+'Ej_Flujo'!BO16+'Ej_Flujo'!CB16+'Ej_Flujo'!CO16+'Ej_Flujo'!DB16+'Ej_Flujo'!DO16+'Ej_Flujo'!EB16),2) -> 0 | F20: 0 | G20: =IF(ABS(E20)<1,"OK","REVISAR") -> OK | H20: E3: cada desembolso de la fila 8 necesita su devolución en la fila 16, a más tardar en dic-2035 (EA16).
B21: 15 | C21: Intereses 2027 completos en Ej_Costos (USD) | D21: Ej_Costos!AD63 − (Ej_Deuda!AD7 + AD13 + Ej_Flujo!AB17) | E21: =ROUND('Ej_Costos'!AD63-('Ej_Deuda'!AD7+'Ej_Deuda'!AD13+'Ej_Flujo'!AB17),2) -> 0 | F21: 0 | G21: =IF(ABS(E21)<1,"OK","REVISAR") -> OK | H21: E4: vincular Ej_Costos!R62:AC62 a Ej_Flujo fila 17 del mismo mes.
B22: 16 | C22: Intereses 2028 (LP + CP) en Resultados (USD) | D22: Resultados!E11 − ('Servicio Deuda'!F24 + Ej_Flujo!AO17) | E22: =ROUND('Resultados'!E11-('Servicio Deuda'!F24+'Ej_Flujo'!AO17),2) -> 0 | F22: 0 | G22: =IF(ABS(E22)<1,"OK","REVISAR") -> OK | H22: E3-E4: revisar Costos!F34 y los intereses CP de Ej_Flujo fila 17.
B23: 17 | C23: Cuotas LP del flujo = Servicio Deuda (USD) | D23: Ej_Flujo fila 23 (2026-2031) − SUMA('Servicio Deuda'!D23:I25) | E23: =ROUND(('Ej_Flujo'!O23+'Ej_Flujo'!AB23+'Ej_Flujo'!AO23+'Ej_Flujo'!BB23+'Ej_Flujo'!BO23+'Ej_Flujo'!CB23)-SUM('Servicio Deuda'!D23:I25),2) -> -387346.81 | F23: ≈ 0 (± 1.000) | G23: =IF(ABS(E23)<1000,"OK","REVISAR") -> REVISAR | H23: B3: faltan las cuotas de jul-oct 2031 (Ej_Flujo!BV23:BY23).
B24: 18 | C24: Capital de trabajo sigue a las ventas (USD) | D24: Capital Trabajo!D9 − Ingresos!E28 × Supuestos!B80 / 365 | E24: =ROUND('Capital Trabajo'!D9-'Ingresos'!E28*'Supuestos'!B80/365,2) -> 0 | F24: 0 | G24: =IF(ABS(E24)<1,"OK","REVISAR") -> OK | H24: E1: no escribir valores en Capital Trabajo; revisar Supuestos!B77:B83.
B25: 19 | C25: Recupero de CT del VAN = CT neto año 10 (USD) | D25: VAN-TIR!M6 − Capital Trabajo!L18 | E25: =ROUND('VAN-TIR'!M6-'Capital Trabajo'!L18,2) -> 0 | F25: 0 | G25: =IF(ABS(E25)<1,"OK","REVISAR") -> OK | H25: F2: no modificar VAN-TIR; revisar la hoja Capital Trabajo.
B26: 20 | C26: VAN reproducible (USD) | D26: VNA(WACC; flujos años 1-10) + flujo año 0 − VAN-TIR!C24 | E26: =ROUND(NPV('VAN-TIR'!C22,'VAN-TIR'!D15:M15)+'VAN-TIR'!C15-'VAN-TIR'!C24,2) -> 0 | F26: 0 | G26: =IF(ABS(E26)<1,"OK","REVISAR") -> OK | H26: F2: la fórmula de VAN-TIR!C24 fue alterada; restituir =VNA(C22;D15:M15)+C15.
B27: 21 | C27: Payback del Dashboard calculado con fórmula | D27: ¿Dashboard!C12 es fórmula y da un número? | E27: =AND(_xlfn.ISFORMULA('Dashboard'!C12),ISNUMBER('Dashboard'!C12)) -> FALSE | F27: VERDADERO | G27: =IF(E27=TRUE,"OK","REVISAR") -> REVISAR | H27: B7: hoy dice «4 Años» tipeado; vincular a Payback!C8.
B28: 22 | C28: Payback total descontado correctamente (USD) | D28: Payback!M12 − (VNA(Ke; VAN-TIR!D28:M28) + C28) | E28: =ROUND('Payback'!M12-(NPV('Supuestos'!B73,'VAN-TIR'!D28:M28)+'VAN-TIR'!C28),2) -> 7774618.4 | F28: 0 | G28: =IF(ABS(E28)<1,"OK","REVISAR") -> REVISAR | H28: B6: corregir los exponentes de Payback!D11:M11 (^1 … ^10).
B29: 23 | C29: Dividendos no negativos (USD) | D29: Mínimo de Resultados!C18:L18, H30 e I31 | E29: =ROUND(MIN(MIN('Resultados'!C18:L18),'Resultados'!H30,'Resultados'!I31),2) -> 0 | F29: ≥ 0 | G29: =IF(E29>=0,"OK","REVISAR") -> OK | H29: E5: con utilidades menores a 500.000 (año 6) u 800.000 (año 7) el calendario fijo da negativo; la Gerencia lo presenta a la Dirección.
B30: 24 | C30: Plan original intacto | D30: Ej_Producción!P18, AE18; Ej_Ingresos!P34, AE34; Ej_Resultados!P13; Supuestos!E11 | E30: =AND('Ej_Producción'!P18=11087,'Ej_Producción'!AE18=12587,'Ej_Ingresos'!P34=10820400,'Ej_Ingresos'!AE34=13591134,ROUND('Ej_Resultados'!P13,0)=841163,'Supuestos'!E11=0.05) -> TRUE | F30: VERDADERO | G30: =IF(E30=TRUE,"OK","REVISAR") -> OK | H30: No escribir en columnas P/AE de las hojas Ej_ ni en la columna E de Supuestos; restaurar desde la copia.
B31: 25 | C31: Errores de fórmula en hojas de resultados (cantidad) | D31: Celdas con error (REF, DIV/0, VALOR, N/A) en Resultados, VAN-TIR, Payback, Dashboard, Capital Trabajo, Materia Prima y Costos | E31: =SUMPRODUCT(--ISERROR('Resultados'!C5:L22))+SUMPRODUCT(--ISERROR('VAN-TIR'!C5:M28))+SUMPRODUCT(--ISERROR('Payback'!C6:M12))+SUMPRODUCT(--ISERROR('Dashboard'!C6:L26))+SUMPRODUCT(--ISERROR('Capital Trabajo'!C6:L20))+SUMPRODUCT(--ISERROR('Materia Prima'!D6:M28))+SUMPRODUCT(--ISERROR('Costos'!D6:M38)) -> 0 | F31: 0 | G31: =IF(E31=0,"OK","REVISAR") -> OK | H31: B5 (división por cero en Ej_Costos) o referencias borradas; usar Ctrl+B «#» en valores.
B32: 26 | C32: Egresos operativos 2028-2035 del flujo = Costos (USD) | D32: Ej_Flujo filas 13, 19, 21 y 22 (totales 2028-2035) − Costos!F:M filas 7-16 y 20-27 | E32: =ROUND(('Ej_Flujo'!AO13+'Ej_Flujo'!AO19+'Ej_Flujo'!AO21+'Ej_Flujo'!AO22+'Ej_Flujo'!BB13+'Ej_Flujo'!BB19+'Ej_Flujo'!BB21+'Ej_Flujo'!BB22+'Ej_Flujo'!BO13+'Ej_Flujo'!BO19+'Ej_Flujo'!BO21+'Ej_Flujo'!BO22+'Ej_Flujo'!CB13+'Ej_Flujo'!CB19+'Ej_Flujo'!CB21+'Ej_Flujo'!CB22+'Ej_Flujo'!CO13+'Ej_Flujo'!CO19+'Ej_Flujo'!CO21+'Ej_Flujo'!CO22+'Ej_Flujo'!DB13+'Ej_Flujo'!DB19+'Ej_Flujo'!DB21+'Ej_Flujo'!DB22+'Ej_Flujo'!DO13+'Ej_Flujo'!DO19+'Ej_Flujo'!DO21+'Ej_Flujo'!DO22+'Ej_Flujo'!EB13+'Ej_Flujo'!EB19+'Ej_Flujo'!EB21+'Ej_Flujo'!EB22)-(SUM('Costos'!F7:M16)+SUM('Costos'!F20:M27)),2) -> -1617237.6 | F32: 0 | G32: =IF(ABS(E32)<1,"OK","REVISAR") -> REVISAR | H32: B8: vincular Ej_Flujo filas 13, 19, 21 y 22 de 2028-2035 a la hoja Costos (hoy son valores pegados).
C34: Resumen de controles | D34: =COUNTIF(G7:G32,"OK")&" de "&ROWS(G7:G32)&" en OK" -> 18 de 26 en OK | E34: Con el libro tal como llegó (09/06/2026) hay 8 controles en REVISAR: el 9, 11, 12, 17, 21, 22 y 26 se corrigen en la fase B (verificado: después de B1-B8 quedan 25 de 26 en OK); el 13 (caja) se corrige en E3 y E5, y empeora con la fase B.
B36: 2. INDICADORES PARA EL POWERPOINT (tablas y textos)
B37: # | C37: Dato | D37: Celda o cálculo de origen | E37: Libro (vivo) | F37: PPT jun-2026 | G37: Diferencia | H37: Diapositivas y observaciones
B38: 1 | C38: Inversión total (USD) | D38: Inversión!C7 | E38: ='Inversión'!C7 -> 5074594 | F38: 5074594 | G38: =IF(ISNUMBER(E38),E38-F38,"") -> 0 | H38: Diap. 3. Igual en plan y actualizado.
B39: 2 | C39: VAN con financiamiento (USD) | D39: VAN-TIR!C24 | E39: ='VAN-TIR'!C24 -> 2844947.8 | F39: 2844948 | G39: =IF(ISNUMBER(E39),E39-F39,"") -> -0.24030234 | H39: Diap. 2, 3, 9 y 13.
B40: 3 | C40: TIR con financiamiento | D40: VAN-TIR!C23 | E40: ='VAN-TIR'!C23 -> 0.14915446 | F40: 0.149 | G40: =IF(ISNUMBER(E40),E40-F40,"") -> 0.00015445575 | H40: Diap. 2, 3, 9 y 13. Mostrar con 1 decimal (14,9%).
B41: 4 | C41: WACC | D41: VAN-TIR!C22 | E41: ='VAN-TIR'!C22 -> 0.098741428 | F41: 0.0987 | G41: =IF(ISNUMBER(E41),E41-F41,"") -> 4.1428378e-05 | H41: Diap. 3, 9 y 13. No cambia si no cambia el financiamiento.
B42: 5 | C42: Spread TIR − WACC (puntos porcentuales) | D42: VAN-TIR!C23 − C22 | E42: ='VAN-TIR'!C23-'VAN-TIR'!C22 -> 0.050413027 | F42: 0.05 | G42: =IF(ISNUMBER(E42),E42-F42,"") -> 0.00041302737 | H42: Diap. 9 y 13 («5,0 pp»). Plan: 5,3 pp.
B43: 6 | C43: VAN actualizado − VAN plan (USD) | D43: VAN-TIR!C24 − VAN plan (sección 4) | E43: ='VAN-TIR'!C24-E103 -> 1419.7597 | F43: 1400 | G43: =IF(ISNUMBER(E43),E43-F43,"") -> 19.759698 | H43: Diap. 9 («Mejora VAN +USD 1,4K»).
B44: 7 | C44: VAN actualizado vs plan (%) | D44: VAN-TIR!C24 / VAN plan − 1 | E44: ='VAN-TIR'!C24/E103-1 -> 0.00049929514 | F44: 0.0005 | G44: =IF(ISNUMBER(E44),E44-F44,"") -> -7.0486464e-07 | H44: Diap. 2, 3, 9 y 13 («+0,05%»).
...

Sheet Ej_Producción
B2: SEGUIMIENTO PRODUCCIÓN AÑO 1 Y 2 — EJECUTADO A ABRIL & PROYECTADO vs PLAN
B3: Producción y Ventas en Toneladas (Tn)
C5: 2026 | R5: 2027
B6: PRODUCCIÓN PROYECTADA MENSUAL
B7: Producto | C7: Ene | D7: Feb | E7: Mar | F7: Abr | G7: May | H7: Jun | I7: Jul | J7: Ago | K7: Sep | L7: Oct | M7: Nov | N7: Dic | O7: TOTAL PROY. | P7: PROY. AÑO 1 | Q7: % vs Anual | R7: Ene | S7: Feb | T7: Mar | U7: Abr | V7: May | W7: Jun | X7: Jul | Y7: Ago | Z7: Sep | AA7: Oct | AB7: Nov | AC7: Dic | AD7: TOTAL PROY. | AE7: PROY. AÑO 2 | AF7: % vs Anual
B8: 1. Slitter Portas Autom. | C8: =+$P$8/12 -> 233.5 | D8: =+$P$8/12 -> 233.5 | E8: =+$P$8/12 -> 233.5 | F8: =+$P$8/12 -> 233.5 | G8: =+$P$8/12 -> 233.5 | H8: =+$P$8/12 -> 233.5 | I8: =+$P$8/12 -> 233.5 | J8: =+$P$8/12 -> 233.5 | ... N8: =+$P$8/12 -> 233.5 | O8: =SUM(C8:N8) -> 2802 | P8: 2802 | Q8: =IF(P8=0,0,O8/P8) -> 1 | R8: =+$AE$8/12 -> 245.16667 | S8: =+$AE$8/12 -> 245.16667 | T8: =+$AE$8/12 -> 245.16667 | U8: =+$AE$8/12 -> 245.16667 | V8: =+$AE$8/12 -> 245.16667 | W8: =+$AE$8/12 -> 245.16667 | X8: =+$AE$8/12 -> 245.16667 | Y8: =+$AE$8/12 -> 245.16667 | ... AC8: =+$AE$8/12 -> 245.16667 | AD8: =SUM(R8:AC8) -> 2942 | AE8: 2942 | AF8: =IF(AE8=0,0,AD8/AE8) -> 1
B9: 2. Slitter Drywall 0,43/0,48 | C9: =+$P$9/12 -> 264 | D9: =+$P$9/12 -> 264 | E9: =+$P$9/12 -> 264 | F9: =+$P$9/12 -> 264 | G9: =+$P$9/12 -> 264 | H9: =+$P$9/12 -> 264 | I9: =+$P$9/12 -> 264 | J9: =+$P$9/12 -> 264 | ... N9: =+$P$9/12 -> 264 | O9: =SUM(C9:N9) -> 3168 | P9: 3168 | Q9: =IF(P9=0,0,O9/P9) -> 1 | R9: =+$AE$9/12 -> 277.16667 | S9: =+$AE$9/12 -> 277.16667 | T9: =+$AE$9/12 -> 277.16667 | U9: =+$AE$9/12 -> 277.16667 | V9: =+$AE$9/12 -> 277.16667 | W9: =+$AE$9/12 -> 277.16667 | X9: =+$AE$9/12 -> 277.16667 | Y9: =+$AE$9/12 -> 277.16667 | ... AC9: =+$AE$9/12 -> 277.16667 | AD9: =SUM(R9:AC9) -> 3326 | AE9: 3326 | AF9: =IF(AE9=0,0,AD9/AE9) -> 1
B10: 3. Slitter Drywall 0,50 | C10: =+$P$10/12 -> 30.416667 | D10: =+$P$10/12 -> 30.416667 | E10: =+$P$10/12 -> 30.416667 | F10: =+$P$10/12 -> 30.416667 | G10: =+$P$10/12 -> 30.416667 | H10: =+$P$10/12 -> 30.416667 | I10: =+$P$10/12 -> 30.416667 | J10: =+$P$10/12 -> 30.416667 | ... N10: =+$P$10/12 -> 30.416667 | O10: =SUM(C10:N10) -> 365 | P10: 365 | Q10: =IF(P10=0,0,O10/P10) -> 1 | R10: =+$AE$10/12 -> 31.916667 | S10: =+$AE$10/12 -> 31.916667 | T10: =+$AE$10/12 -> 31.916667 | U10: =+$AE$10/12 -> 31.916667 | V10: =+$AE$10/12 -> 31.916667 | W10: =+$AE$10/12 -> 31.916667 | X10: =+$AE$10/12 -> 31.916667 | Y10: =+$AE$10/12 -> 31.916667 | ... AC10: =+$AE$10/12 -> 31.916667 | AD10: =SUM(R10:AC10) -> 383 | AE10: 383 | AF10: =IF(AE10=0,0,AD10/AE10) -> 1
B11: 5. Telhas Met. Naturales | C11: =+$P$11/12 -> 142.16667 | D11: =+$P$11/12 -> 142.16667 | E11: =+$P$11/12 -> 142.16667 | F11: =+$P$11/12 -> 142.16667 | G11: =+$P$11/12 -> 142.16667 | H11: =+$P$11/12 -> 142.16667 | I11: =+$P$11/12 -> 142.16667 | J11: =+$P$11/12 -> 142.16667 | ... N11: =+$P$11/12 -> 142.16667 | O11: =SUM(C11:N11) -> 1706 | P11: 1706 | Q11: =IF(P11=0,0,O11/P11) -> 1 | R11: =+$AE$11/12 -> 149.25 | S11: =+$AE$11/12 -> 149.25 | T11: =+$AE$11/12 -> 149.25 | U11: =+$AE$11/12 -> 149.25 | V11: =+$AE$11/12 -> 149.25 | W11: =+$AE$11/12 -> 149.25 | X11: =+$AE$11/12 -> 149.25 | Y11: =+$AE$11/12 -> 149.25 | ... AC11: =+$AE$11/12 -> 149.25 | AD11: =SUM(R11:AC11) -> 1791 | AE11: 1791 | AF11: =IF(AE11=0,0,AD11/AE11) -> 1
B12: 6. Telhas Met. Pre Pintadas | C12: =+$P$12/12 -> 15.25 | D12: =+$P$12/12 -> 15.25 | E12: =+$P$12/12 -> 15.25 | F12: =+$P$12/12 -> 15.25 | G12: =+$P$12/12 -> 15.25 | H12: =+$P$12/12 -> 15.25 | I12: =+$P$12/12 -> 15.25 | J12: =+$P$12/12 -> 15.25 | ... N12: =+$P$12/12 -> 15.25 | O12: =SUM(C12:N12) -> 183 | P12: 183 | Q12: =IF(P12=0,0,O12/P12) -> 1 | R12: =+$AE$12/12 -> 16 | S12: =+$AE$12/12 -> 16 | T12: =+$AE$12/12 -> 16 | U12: =+$AE$12/12 -> 16 | V12: =+$AE$12/12 -> 16 | W12: =+$AE$12/12 -> 16 | X12: =+$AE$12/12 -> 16 | Y12: =+$AE$12/12 -> 16 | ... AC12: =+$AE$12/12 -> 16 | AD12: =SUM(R12:AC12) -> 192 | AE12: 192 | AF12: =IF(AE12=0,0,AD12/AE12) -> 1
B13: 7. Perfil DW 0,43 Prepint. | C13: =+$P$13/12 -> 35.5 | D13: =+$P$13/12 -> 35.5 | E13: =+$P$13/12 -> 35.5 | F13: =+$P$13/12 -> 35.5 | G13: =+$P$13/12 -> 35.5 | H13: =+$P$13/12 -> 35.5 | I13: =+$P$13/12 -> 35.5 | J13: =+$P$13/12 -> 35.5 | ... N13: =+$P$13/12 -> 35.5 | O13: =SUM(C13:N13) -> 426 | P13: 426 | Q13: =IF(P13=0,0,O13/P13) -> 1 | R13: =+$AE$13/12 -> 37.25 | S13: =+$AE$13/12 -> 37.25 | T13: =+$AE$13/12 -> 37.25 | U13: =+$AE$13/12 -> 37.25 | V13: =+$AE$13/12 -> 37.25 | W13: =+$AE$13/12 -> 37.25 | X13: =+$AE$13/12 -> 37.25 | Y13: =+$AE$13/12 -> 37.25 | ... AC13: =+$AE$13/12 -> 37.25 | AD13: =SUM(R13:AC13) -> 447 | AE13: 447 | AF13: =IF(AE13=0,0,AD13/AE13) -> 1
B14: 8. Perfil Drywall 0,50 | C14: =+$P$14/12 -> 60.916667 | D14: =+$P$14/12 -> 60.916667 | E14: =+$P$14/12 -> 60.916667 | F14: =+$P$14/12 -> 60.916667 | G14: =+$P$14/12 -> 60.916667 | H14: =+$P$14/12 -> 60.916667 | I14: =+$P$14/12 -> 60.916667 | J14: =+$P$14/12 -> 60.916667 | ... N14: =+$P$14/12 -> 60.916667 | O14: =SUM(C14:N14) -> 731 | P14: 731 | Q14: =IF(P14=0,0,O14/P14) -> 1 | R14: =+$AE$14/12 -> 64 | S14: =+$AE$14/12 -> 64 | T14: =+$AE$14/12 -> 64 | U14: =+$AE$14/12 -> 64 | V14: =+$AE$14/12 -> 64 | W14: =+$AE$14/12 -> 64 | X14: =+$AE$14/12 -> 64 | Y14: =+$AE$14/12 -> 64 | ... AC14: =+$AE$14/12 -> 64 | AD14: =SUM(R14:AC14) -> 768 | AE14: 768 | AF14: =IF(AE14=0,0,AD14/AE14) -> 1
B15: 9. Perfil Drywall 0,48 | C15: =+$P$15/12 -> 142.16667 | D15: =+$P$15/12 -> 142.16667 | E15: =+$P$15/12 -> 142.16667 | F15: =+$P$15/12 -> 142.16667 | G15: =+$P$15/12 -> 142.16667 | H15: =+$P$15/12 -> 142.16667 | I15: =+$P$15/12 -> 142.16667 | J15: =+$P$15/12 -> 142.16667 | ... N15: =+$P$15/12 -> 142.16667 | O15: =SUM(C15:N15) -> 1706 | P15: 1706 | Q15: =IF(P15=0,0,O15/P15) -> 1 | R15: =+$AE$15/12 -> 149.25 | S15: =+$AE$15/12 -> 149.25 | T15: =+$AE$15/12 -> 149.25 | U15: =+$AE$15/12 -> 149.25 | V15: =+$AE$15/12 -> 149.25 | W15: =+$AE$15/12 -> 149.25 | X15: =+$AE$15/12 -> 149.25 | Y15: =+$AE$15/12 -> 149.25 | ... AC15: =+$AE$15/12 -> 149.25 | AD15: =SUM(R15:AC15) -> 1791 | AE15: 1791 | AF15: =IF(AE15=0,0,AD15/AE15) -> 1
B16: 10. Steel Frame | P16: 0 | R16: =+$AE$16/12 -> 73.833333 | S16: =+$AE$16/12 -> 73.833333 | T16: =+$AE$16/12 -> 73.833333 | U16: =+$AE$16/12 -> 73.833333 | V16: =+$AE$16/12 -> 73.833333 | W16: =+$AE$16/12 -> 73.833333 | X16: =+$AE$16/12 -> 73.833333 | Y16: =+$AE$16/12 -> 73.833333 | ... AC16: =+$AE$16/12 -> 73.833333 | AD16: =SUM(R16:AC16) -> 886 | AE16: 886 | AF16: =IF(AE16=0,0,AD16/AE16) -> 1
B17: 11. Accesorios Metálicos | P17: 0 | R17: =+$AE$17/12 -> 5.0833333 | S17: =+$AE$17/12 -> 5.0833333 | T17: =+$AE$17/12 -> 5.0833333 | U17: =+$AE$17/12 -> 5.0833333 | V17: =+$AE$17/12 -> 5.0833333 | W17: =+$AE$17/12 -> 5.0833333 | X17: =+$AE$17/12 -> 5.0833333 | Y17: =+$AE$17/12 -> 5.0833333 | ... AC17: =+$AE$17/12 -> 5.0833333 | AD17: =SUM(R17:AC17) -> 61 | AE17: 61 | AF17: =IF(AE17=0,0,AD17/AE17) -> 1
B18: TOTAL PRODUCCIÓN PROY. | C18: =SUM(C8:C15) -> 923.91667 | D18: =SUM(D8:D15) -> 923.91667 | E18: =SUM(E8:E15) -> 923.91667 | F18: =SUM(F8:F15) -> 923.91667 | G18: =SUM(G8:G15) -> 923.91667 | H18: =SUM(H8:H15) -> 923.91667 | I18: =SUM(I8:I15) -> 923.91667 | J18: =SUM(J8:J15) -> 923.91667 | ... N18: =SUM(N8:N15) -> 923.91667 | O18: =SUM(O8:O17) -> 11087 | P18: =SUM(P8:P17) -> 11087 | R18: =SUM(R8:R17) -> 1048.9167 | S18: =SUM(S8:S17) -> 1048.9167 | T18: =SUM(T8:T17) -> 1048.9167 | U18: =SUM(U8:U17) -> 1048.9167 | V18: =SUM(V8:V17) -> 1048.9167 | W18: =SUM(W8:W17) -> 1048.9167 | X18: =SUM(X8:X17) -> 1048.9167 | Y18: =SUM(Y8:Y17) -> 1048.9167 | ... AE18: =SUM(AE8:AE17) -> 12587
B20: PRODUCCIÓN EJECUTADA Y PROYEC. MENSUAL
B21: Producto | C21: Ene | D21: Feb | E21: Mar | F21: Abr | G21: May | H21: Jun | I21: Jul | J21: Ago | K21: Sep | L21: Oct | M21: Nov | N21: Dic | O21: TOTAL EJEC. | P21: % Avance vs Proy. | Q21: Desvío (Tn) | R21: Ene | S21: Feb | T21: Mar | U21: Abr | V21: May | W21: Jun | X21: Jul | Y21: Ago | Z21: Sep | AA21: Oct | AB21: Nov | AC21: Dic | AD21: TOTAL EJEC. | AE21: % Avance vs Proy. | AF21: Desvío (Tn)
B22: 1. Slitter Portas Autom. | C22: 29.7 | D22: 0 | E22: 22.335 | F22: 59.945 | G22: 14 | H22: 46 | I22: 90 | J22: 90 | K22: 90 | L22: 90 | M22: 90 | N22: 90 | O22: =SUM(C22:N22) -> 711.98 | P22: =IF(O8=0,0,O22/O8) -> 0.25409707 | Q22: =O22-O8 -> -2090.02 | R22: 30 | S22: 60 | T22: 90 | U22: 90 | V22: 90 | W22: 90 | X22: 90 | Y22: 90 | Z22: 90 | AA22: 90 | AB22: 90 | AC22: 90 | AD22: =SUM(R22:AC22) -> 990 | AE22: =IF(AD8=0,0,AD22/AD8) -> 0.33650578 | AF22: =AD22-AD8 -> -1952
B23: 2. Slitter Drywall 0,43/0,48 | C23: 0 | D23: 0 | E23: 121.97 | F23: 134.773 | G23: 350.47 | H23: 348.832 | I23: 110 | J23: 50 | K23: 0 | L23: 150 | M23: 300 | N23: 240 | O23: =SUM(C23:N23) -> 1806.045 | P23: =IF(O9=0,0,O23/O9) -> 0.57008996 | Q23: =O23-O9 -> -1361.955 | R23: 300 | S23: 300 | T23: 390 | U23: 420 | V23: 420 | W23: 420 | X23: 420 | Y23: 420 | Z23: 420 | AA23: 420 | AB23: 420 | AC23: 420 | AD23: =SUM(R23:AC23) -> 4770 | AE23: =IF(AD9=0,0,AD23/AD9) -> 1.4341551 | AF23: =AD23-AD9 -> 1444
B24: 3. Slitter Drywall 0,50 | C24: 0 | D24: 0 | E24: 5.16 | F24: 14.688 | G24: 59.125 | H24: 10.168 | I24: 70 | J24: 50 | K24: 50 | L24: 30 | M24: 60 | N24: 60 | O24: =SUM(C24:N24) -> 409.141 | P24: =IF(O10=0,0,O24/O10) -> 1.1209342 | Q24: =O24-O10 -> 44.141 | R24: 90 | S24: 90 | T24: 120 | U24: 150 | V24: 150 | W24: 150 | X24: 150 | Y24: 150 | Z24: 150 | AA24: 150 | AB24: 150 | AC24: 150 | AD24: =SUM(R24:AC24) -> 1650 | AE24: =IF(AD10=0,0,AD24/AD10) -> 4.308094 | AF24: =AD24-AD10 -> 1267
B25: 4. Slitter Steel Frame 0,80/0,95 | C25: 0 | D25: 0 | E25: 0 | F25: 0 | G25: 0 | H25: 0 | I25: 0 | J25: 0 | K25: 30 | L25: 180 | M25: 150 | N25: 120 | O25: =SUM(C25:N25) -> 480 | P25: =IF(O19=0,0,O25/O19) -> 0 | Q25: =O25-O19 -> 480 | R25: 90 | S25: 90 | T25: 120 | U25: 150 | V25: 150 | W25: 150 | X25: 150 | Y25: 150 | Z25: 150 | AA25: 150 | AB25: 150 | AC25: 150 | AD25: =SUM(R25:AC25) -> 1650 | AE25: =IF(AD19=0,0,AD25/AD19) -> 0 | AF25: =AD25-AD19 -> 1650
B26: 5. Telhas Met. Naturales | C26: 0 | D26: 0 | E26: 0 | F26: 0 | G26: 0 | H26: 0 | I26: 0 | J26: 60 | K26: 60 | L26: 60 | M26: 30 | N26: 30 | O26: =SUM(C26:N26) -> 240 | P26: =IF(O11=0,0,O26/O11) -> 0.14067995 | Q26: =O26-O11 -> -1466 | R26: 30 | S26: 30 | T26: 60 | U26: 60 | V26: 60 | W26: 60 | X26: 60 | Y26: 60 | Z26: 60 | AA26: 60 | AB26: 60 | AC26: 60 | AD26: =SUM(R26:AC26) -> 660 | AE26: =IF(AD11=0,0,AD26/AD11) -> 0.36850921 | AF26: =AD26-AD11 -> -1131
B27: 6. Telhas Met. Pre Pintadas | C27: 0 | D27: 0 | E27: 0 | F27: 0 | G27: 8 | H27: 0 | I27: 0 | J27: 30 | K27: 30 | L27: 30 | M27: 30 | N27: 30 | O27: =SUM(C27:N27) -> 158 | P27: =IF(O12=0,0,O27/O12) -> 0.86338798 | Q27: =O27-O12 -> -25 | R27: 0 | S27: 30 | T27: 30 | U27: 30 | V27: 30 | W27: 30 | X27: 30 | Y27: 30 | Z27: 30 | AA27: 30 | AB27: 30 | AC27: 30 | AD27: =SUM(R27:AC27) -> 330 | AE27: =IF(AD12=0,0,AD27/AD12) -> 1.71875 | AF27: =AD27-AD12 -> 138
B28: 7. Perfil DW 0,43 Prepint. | C28: 0 | D28: 0 | E28: 0 | F28: 0 | G28: 0 | H28: 0 | I28: 0 | J28: 0 | K28: 30 | L28: 30 | M28: 30 | N28: 30 | O28: =SUM(C28:N28) -> 120 | P28: =IF(O13=0,0,O28/O13) -> 0.28169014 | Q28: =O28-O13 -> -306 | R28: 30 | S28: 30 | T28: 45 | U28: 60 | V28: 60 | W28: 60 | X28: 60 | Y28: 60 | Z28: 60 | AA28: 60 | AB28: 60 | AC28: 60 | AD28: =SUM(R28:AC28) -> 645 | AE28: =IF(AD13=0,0,AD28/AD13) -> 1.442953 | AF28: =AD28-AD13 -> 198
B29: 8. Perfil Drywall 0,50 | C29: 0 | D29: 0 | E29: 0 | F29: 0 | G29: 6 | H29: 0 | I29: 0 | J29: 0 | K29: 0 | L29: 54 | M29: 30 | N29: 30 | O29: =SUM(C29:N29) -> 120 | P29: =IF(O14=0,0,O29/O14) -> 0.16415869 | Q29: =O29-O14 -> -611 | R29: 30 | S29: 30 | T29: 60 | U29: 60 | V29: 60 | W29: 60 | X29: 60 | Y29: 60 | Z29: 60 | AA29: 60 | AB29: 60 | AC29: 60 | AD29: =SUM(R29:AC29) -> 660 | AE29: =IF(AD14=0,0,AD29/AD14) -> 0.859375 | AF29: =AD29-AD14 -> -108
B30: 9. Perfil Drywall 0,48 | C30: 0 | D30: 0 | E30: 0 | F30: 0 | G30: 74 | H30: 0 | I30: 0 | J30: 0 | K30: 0 | L30: 16 | M30: 120 | N30: 60 | O30: =SUM(C30:N30) -> 270 | P30: =IF(O15=0,0,O30/O15) -> 0.15826495 | Q30: =O30-O15 -> -1436 | R30: 90 | S30: 90 | T30: 120 | U30: 120 | V30: 150 | W30: 150 | X30: 150 | Y30: 150 | Z30: 150 | AA30: 150 | AB30: 150 | AC30: 150 | AD30: =SUM(R30:AC30) -> 1620 | AE30: =IF(AD15=0,0,AD30/AD15) -> 0.90452261 | AF30: =AD30-AD15 -> -171
B31: 10. Steel Frame | R31: 30 | S31: 60 | T31: 60 | U31: 60 | V31: 90 | W31: 90 | X31: 90 | Y31: 90 | Z31: 90 | AA31: 90 | AB31: 90 | AC31: 90 | AD31: =SUM(R31:AC31) -> 930 | AE31: =IF(AD16=0,0,AD31/AD16) -> 1.0496614 | AF31: =AD31-AD16 -> 44
B32: 11. Accesorios Metálicos | R32: 15 | S32: 15 | T32: 30 | U32: 30 | V32: 30 | W32: 30 | X32: 30 | Y32: 30 | Z32: 30 | AA32: 30 | AB32: 30 | AC32: 30 | AD32: =SUM(R32:AC32) -> 330 | AE32: =IF(AD17=0,0,AD32/AD17) -> 5.4098361 | AF32: =AD32-AD17 -> 269
B33: TOTAL PRODUCCIÓN EJEC. | C33: =SUM(C22:C32) -> 29.7 | D33: =SUM(D22:D32) -> 0 | E33: =SUM(E22:E32) -> 149.465 | F33: =SUM(F22:F32) -> 209.406 | G33: =SUM(G22:G32) -> 511.595 | H33: =SUM(H22:H32) -> 405 | I33: =SUM(I22:I32) -> 270 | J33: =SUM(J22:J32) -> 280 | ... O33: =SUM(O22:O32) -> 4315.166 | P33: =+O33/O18 -> 0.38920952 | Q33: =SUM(Q22:Q32) -> -6771.834 | R33: =SUM(R22:R32) -> 735 | S33: =SUM(S22:S32) -> 825 | T33: =SUM(T22:T32) -> 1125 | U33: =SUM(U22:U32) -> 1230 | V33: =SUM(V22:V32) -> 1290 | W33: =SUM(W22:W32) -> 1290 | X33: =SUM(X22:X32) -> 1290 | ... AD33: =SUM(AD22:AD32) -> 14235 | AE33: =+AD33/AD18 -> 1.1309287 | AF33: =SUM(AF22:AF32) -> 1648
C34: =+C33/$O$33 -> 0.0068827016 | D34: =+D33/$O$33 -> 0 | E34: =+E33/$O$33 -> 0.034637138 | F34: =+F33/$O$33 -> 0.048527913 | G34: =+G33/$O$33 -> 0.11855743 | H34: =+H33/$O$33 -> 0.093855022 | I34: =+I33/$O$33 -> 0.062570015 | J34: =+J33/$O$33 -> 0.064887423 | ... N34: =+N33/$O$33 -> 0.15990115 | Q34: =+Q33/O18 -> -0.61079048 | R34: =+R33/$AD$33 -> 0.051633298 | S34: =+S33/$AD$33 -> 0.057955743 | T34: =+T33/$AD$33 -> 0.079030558 | U34: =+U33/$AD$33 -> 0.086406744 | V34: =+V33/$AD$33 -> 0.090621707 | W34: =+W33/$AD$33 -> 0.090621707 | X34: =+X33/$AD$33 -> 0.090621707 | Y34: =+Y33/$AD$33 -> 0.090621707 | ... AC34: =+AC33/$AD$33 -> 0.090621707 | AF34: =+AF33/AD18 -> 0.13092874
B35: VENTAS EJECUTADAS Y PROYEC. MENSUAL (Tn)
B36: Producto | C36: Ene | D36: Feb | E36: Mar | F36: Abr | G36: May | H36: Jun | I36: Jul | J36: Ago | K36: Sep | L36: Oct | M36: Nov | N36: Dic | O36: TOTAL VTA EJEC | P36: PROY. VTA AÑO1 | Q36: Desvío (Tn) | R36: Ene | S36: Feb | T36: Mar | U36: Abr | V36: May | W36: Jun | X36: Jul | Y36: Ago | Z36: Sep | AA36: Oct | AB36: Nov | AC36: Dic | AD36: TOTAL VTA EJEC | AE36: PROY. VTA AÑO2 | AF36: Desvío (Tn)
B37: 1. Slitter Portas Autom. | C37: 29.7 | D37: 0 | E37: 22.335 | F37: 59.945 | G37: 0 | H37: 60 | I37: 90 | J37: 90 | K37: 90 | L37: 90 | M37: 90 | N37: 90 | O37: =SUM(C37:N37) -> 711.98 | P37: 2760 | Q37: =O37-P37 -> -2048.02 | R37: 30 | S37: 60 | T37: 90 | U37: 90 | V37: 90 | W37: 90 | X37: 90 | Y37: 90 | Z37: 90 | AA37: 90 | AB37: 90 | AC37: 90 | AD37: =SUM(R37:AC37) -> 990 | AE37: 2898 | AF37: =AD37-AE37 -> -1908
B38: 2. Slitter Drywall 0,43/0,48 | C38: 0 | D38: 0 | E38: 121.97 | F38: 134.773 | G38: 224.47 | H38: 474.832 | I38: 110 | J38: 50 | K38: 0 | L38: 120 | M38: 300 | N38: 210 | O38: =SUM(C38:N38) -> 1746.045 | P38: 3120 | Q38: =O38-P38 -> -1373.955 | R38: 300 | S38: 300 | T38: 390 | U38: 420 | V38: 420 | W38: 420 | X38: 420 | Y38: 420 | Z38: 420 | AA38: 420 | AB38: 420 | AC38: 420 | AD38: =SUM(R38:AC38) -> 4770 | AE38: 3276 | AF38: =AD38-AE38 -> 1494
B39: 3. Slitter Drywall 0,50 | C39: 0 | D39: 0 | E39: 5.16 | F39: 14.688 | G39: 34.125 | H39: 35.168 | I39: 70 | J39: 50 | K39: 50 | L39: 30 | M39: 60 | N39: 30 | O39: =SUM(C39:N39) -> 379.141 | P39: 360 | Q39: =O39-P39 -> 19.141 | R39: 90 | S39: 90 | T39: 120 | U39: 150 | V39: 150 | W39: 150 | X39: 150 | Y39: 150 | Z39: 150 | AA39: 150 | AB39: 150 | AC39: 150 | AD39: =SUM(R39:AC39) -> 1650 | AE39: 377 | AF39: =AD39-AE39 -> 1273
B40: 4. Slitter Steel Frame 0,80/0,95 | C40: 0 | D40: 0 | E40: 0 | F40: 0 | G40: 0 | H40: 0 | I40: 0 | J40: 0 | K40: 30 | L40: 150 | M40: 120 | N40: 150 | O40: =SUM(C40:N40) -> 450 | P40: 0 | Q40: =O40-P40 -> 450 | R40: 90 | S40: 90 | T40: 120 | U40: 150 | V40: 150 | W40: 150 | X40: 150 | Y40: 150 | Z40: 150 | AA40: 150 | AB40: 150 | AC40: 150 | AD40: =SUM(R40:AC40) -> 1650 | AE40: 0 | AF40: =AD40-AE40 -> 1650
B41: 5. Telhas Met. Naturales | C41: 0 | D41: 0 | E41: 0 | F41: 0 | G41: 0 | H41: 0 | I41: 0 | J41: 60 | K41: 60 | L41: 60 | M41: 30 | N41: 30 | O41: =SUM(C41:N41) -> 240 | P41: 1680 | Q41: =O41-P41 -> -1440 | R41: 30 | S41: 30 | T41: 60 | U41: 60 | V41: 60 | W41: 60 | X41: 60 | Y41: 60 | Z41: 60 | AA41: 60 | AB41: 60 | AC41: 60 | AD41: =SUM(R41:AC41) -> 660 | AE41: 1764 | AF41: =AD41-AE41 -> -1104
B42: 6. Telhas Met. Pre Pintadas | C42: 0 | D42: 0 | E42: 0 | F42: 0 | G42: 8 | H42: 0 | I42: 0 | J42: 30 | K42: 30 | L42: 30 | M42: 30 | N42: 30 | O42: =SUM(C42:N42) -> 158 | P42: 180 | Q42: =O42-P42 -> -22 | R42: 0 | S42: 30 | T42: 30 | U42: 30 | V42: 30 | W42: 30 | X42: 30 | Y42: 30 | Z42: 30 | AA42: 30 | AB42: 30 | AC42: 30 | AD42: =SUM(R42:AC42) -> 330 | AE42: 189 | AF42: =AD42-AE42 -> 141
B43: 7. Perfil DW 0,43 Prepint. | C43: 0 | D43: 0 | E43: 0 | F43: 0 | G43: 0 | H43: 0 | I43: 0 | J43: 0 | K43: 30 | L43: 30 | M43: 30 | N43: 30 | O43: =SUM(C43:N43) -> 120 | P43: 420 | Q43: =O43-P43 -> -300 | R43: 30 | S43: 30 | T43: 45 | U43: 60 | V43: 60 | W43: 60 | X43: 60 | Y43: 60 | Z43: 60 | AA43: 60 | AB43: 60 | AC43: 60 | AD43: =SUM(R43:AC43) -> 645 | AE43: 440 | AF43: =AD43-AE43 -> 205
...

Sheet Ej_Ingresos
B2: SEGUIMIENTO INGRESOS AÑO 1 Y 2 — EJECUTADO A ABRIL & PROYECTADO vs PLAN
B3: Valores en USD
C5: 2026 | R5: 2027
B6: PRECIOS REALES DE VENTA (USD/Tn) — EJECUTADO Y PROYECTADO
B7: Producto | C7: Ene | D7: Feb | E7: Mar | F7: Abr | G7: May | H7: Jun | I7: Jul | J7: Ago | K7: Sep | L7: Oct | M7: Nov | N7: Dic | O7: PRECIO PROM EJEC | P7: PRECIO PROY. | Q7: DESVÍO % | R7: Ene | S7: Feb | T7: Mar | U7: Abr | V7: May | W7: Jun | X7: Jul | Y7: Ago | Z7: Sep | AA7: Oct | AB7: Nov | AC7: Dic | AD7: PRECIO PROM P. EJEC | AE7: PRECIO PROY. | AF7: DESVÍO %
B8: 1. Slitter Portas Autom. | C8: 680 | D8: 0 | E8: 660 | F8: 760 | G8: 680 | H8: 858 | I8: 858 | J8: 858 | K8: 858 | L8: 858 | M8: 858 | N8: 858 | O8: =IF(Ej_Producción!O37=0,0,O23/Ej_Producción!O37) -> 836.11239 | P8: 800 | Q8: =IF(P8=0,0,(O8-P8)/P8) -> 0.045140488 | R8: 858 | S8: 858 | T8: 858 | U8: 858 | V8: 858 | W8: 858 | X8: 858 | Y8: 858 | Z8: 858 | AA8: 858 | AB8: 858 | AC8: 858 | AD8: =IF(Ej_Producción!AD37=0,0,AD23/Ej_Producción!AD37) -> 858 | AE8: 840 | AF8: =IF(AE8=0,0,(AD8-AE8)/AE8) -> 0.021428571
B9: 2. Slitter Drywall 0,43/0,48 | C9: 0 | D9: 0 | E9: 741.04 | F9: 720.05 | G9: 776.65 | H9: 964 | I9: 964 | J9: 964 | K9: 964 | L9: 964 | M9: 964 | N9: 964 | O9: =IF(Ej_Producción!O38=0,0,O24/Ej_Producción!O38) -> 905.50966 | P9: 900 | Q9: =IF(P9=0,0,(O9-P9)/P9) -> 0.0061218487 | R9: 964 | S9: 964 | T9: 964 | U9: 964 | V9: 964 | W9: 964 | X9: 964 | Y9: 964 | Z9: 964 | AA9: 964 | AB9: 964 | AC9: 964 | AD9: =IF(Ej_Producción!AD38=0,0,AD24/Ej_Producción!AD38) -> 964 | AE9: 945 | AF9: =IF(AE9=0,0,(AD9-AE9)/AE9) -> 0.02010582
B10: 3. Slitter Drywall 0,50 | C10: 0 | D10: 0 | E10: 770 | F10: 840 | G10: 870 | H10: 1080 | I10: 1080 | J10: 1080 | K10: 1080 | L10: 1080 | M10: 1080 | N10: 1080 | O10: =IF(Ej_Producción!O39=0,0,O25/Ej_Producción!O39) -> 1047.5821 | P10: 1010 | Q10: =IF(P10=0,0,(O10-P10)/P10) -> 0.037209961 | R10: 1080 | S10: 1080 | T10: 1080 | U10: 1080 | V10: 1080 | W10: 1080 | X10: 1080 | Y10: 1080 | Z10: 1080 | AA10: 1080 | AB10: 1080 | AC10: 1080 | AD10: =IF(Ej_Producción!AD39=0,0,AD25/Ej_Producción!AD39) -> 1080 | AE10: 1060.5 | AF10: =IF(AE10=0,0,(AD10-AE10)/AE10) -> 0.018387553
B11: 4. Slitter Steel Frame 0,80/0,95 | C11: 0 | D11: 0 | E11: 0 | F11: 0 | G11: 0 | H11: 1080 | I11: 1080 | J11: 1080 | K11: 1080 | L11: 1080 | M11: 1080 | N11: 1080 | O11: =IF(Ej_Producción!O40=0,0,O26/Ej_Producción!O40) -> 1080 | P11: 0 | Q11: =IF(P11=0,0,(O11-P11)/P11) -> 0 | R11: 1080 | S11: 1080 | T11: 1080 | U11: 1080 | V11: 1080 | W11: 1080 | X11: 1080 | Y11: 1080 | Z11: 1080 | AA11: 1080 | AB11: 1080 | AC11: 1080 | AD11: =IF(Ej_Producción!AD40=0,0,AD26/Ej_Producción!AD40) -> 1080 | AE11: 0 | AF11: =IF(AE11=0,0,(AD11-AE11)/AE11) -> 0
B12: 5. Telhas Met. Naturales | C12: 0 | D12: 0 | E12: 0 | F12: 0 | G12: 0 | H12: 1218 | I12: 1218 | J12: 1218 | K12: 1218 | L12: 1218 | M12: 1218 | N12: 1218 | O12: =IF(Ej_Producción!O41=0,0,O27/Ej_Producción!O41) -> 1218 | P12: 1150 | Q12: =IF(P12=0,0,(O12-P12)/P12) -> 0.059130435 | R12: 1218 | S12: 1218 | T12: 1218 | U12: 1218 | V12: 1218 | W12: 1218 | X12: 1218 | Y12: 1218 | Z12: 1218 | AA12: 1218 | AB12: 1218 | AC12: 1218 | AD12: =IF(Ej_Producción!AD41=0,0,AD27/Ej_Producción!AD41) -> 1218 | AE12: 1207.5 | AF12: =IF(AE12=0,0,(AD12-AE12)/AE12) -> 0.0086956522
B13: 6. Telhas Met. Pre Pintadas | C13: 0 | D13: 0 | E13: 0 | F13: 0 | G13: 1040 | H13: 1399 | I13: 1399 | J13: 1399 | K13: 1399 | L13: 1399 | M13: 1399 | N13: 1399 | O13: =IF(Ej_Producción!O42=0,0,O28/Ej_Producción!O42) -> 1380.8228 | P13: 1310 | Q13: =IF(P13=0,0,(O13-P13)/P13) -> 0.054063195 | R13: 1399 | S13: 1399 | T13: 1399 | U13: 1399 | V13: 1399 | W13: 1399 | X13: 1399 | Y13: 1399 | Z13: 1399 | AA13: 1399 | AB13: 1399 | AC13: 1399 | AD13: =IF(Ej_Producción!AD42=0,0,AD28/Ej_Producción!AD42) -> 1399 | AE13: 1375.5 | AF13: =IF(AE13=0,0,(AD13-AE13)/AE13) -> 0.017084696
B14: 7. Perfil DW 0,43 Prepint. | C14: 0 | D14: 0 | E14: 0 | F14: 0 | G14: 0 | H14: 1399 | I14: 1399 | J14: 1399 | K14: 1399 | L14: 1399 | M14: 1399 | N14: 1399 | O14: =IF(Ej_Producción!O43=0,0,O29/Ej_Producción!O43) -> 1399 | P14: 1330 | Q14: =IF(P14=0,0,(O14-P14)/P14) -> 0.051879699 | R14: 1399 | S14: 1399 | T14: 1399 | U14: 1399 | V14: 1399 | W14: 1399 | X14: 1399 | Y14: 1399 | Z14: 1399 | AA14: 1399 | AB14: 1399 | AC14: 1399 | AD14: =IF(Ej_Producción!AD43=0,0,AD29/Ej_Producción!AD43) -> 1399 | AE14: 1396.5 | AF14: =IF(AE14=0,0,(AD14-AE14)/AE14) -> 0.0017901898
B15: 8. Perfil Drywall 0,50 | C15: 0 | D15: 0 | E15: 0 | F15: 0 | G15: 0 | H15: 1272 | I15: 1272 | J15: 1272 | K15: 1272 | L15: 1272 | M15: 1272 | N15: 1272 | O15: =IF(Ej_Producción!O44=0,0,O30/Ej_Producción!O44) -> 1272 | P15: 1180 | Q15: =IF(P15=0,0,(O15-P15)/P15) -> 0.077966102 | R15: 1272 | S15: 1272 | T15: 1272 | U15: 1272 | V15: 1272 | W15: 1272 | X15: 1272 | Y15: 1272 | Z15: 1272 | AA15: 1272 | AB15: 1272 | AC15: 1272 | AD15: =IF(Ej_Producción!AD44=0,0,AD30/Ej_Producción!AD44) -> 1272 | AE15: 1239 | AF15: =IF(AE15=0,0,(AD15-AE15)/AE15) -> 0.026634383
B16: 9. Perfil Drywall 0,48 | C16: 0 | D16: 0 | E16: 0 | F16: 0 | G16: 0 | H16: 1178 | I16: 1178 | J16: 1178 | K16: 1178 | L16: 1178 | M16: 1178 | N16: 1178 | O16: =IF(Ej_Producción!O45=0,0,O31/Ej_Producción!O45) -> 1178 | P16: 1110 | Q16: =IF(P16=0,0,(O16-P16)/P16) -> 0.061261261 | R16: 1178 | S16: 1178 | T16: 1178 | U16: 1178 | V16: 1178 | W16: 1178 | X16: 1178 | Y16: 1178 | Z16: 1178 | AA16: 1178 | AB16: 1178 | AC16: 1178 | AD16: =IF(Ej_Producción!AD45=0,0,AD31/Ej_Producción!AD45) -> 1178 | AE16: 1165.5 | AF16: =IF(AE16=0,0,(AD16-AE16)/AE16) -> 0.010725011
B17: 10. Steel Frame | O17: =IF(Ej_Producción!O46=0,0,O32/Ej_Producción!O46) -> 0 | P17: 0 | Q17: =IF(P17=0,0,(O17-P17)/P17) -> 0 | R17: 1840 | S17: 1840 | T17: 1840 | U17: 1840 | V17: 1840 | W17: 1840 | X17: 1840 | Y17: 1840 | Z17: 1840 | AA17: 1840 | AB17: 1840 | AC17: 1840 | AD17: =IF(Ej_Producción!AD46=0,0,AD32/Ej_Producción!AD46) -> 1840 | AE17: 1700 | AF17: =IF(AE17=0,0,(AD17-AE17)/AE17) -> 0.082352941
B18: 11. Accesorios Metálicos | O18: =IF(Ej_Producción!O47=0,0,O33/Ej_Producción!O47) -> 0 | P18: 0 | Q18: =IF(P18=0,0,(O18-P18)/P18) -> 0 | R18: 5202 | S18: 5202 | T18: 5202 | U18: 5202 | V18: 5202 | W18: 5202 | X18: 5202 | Y18: 5202 | Z18: 5202 | AA18: 5202 | AB18: 5202 | AC18: 5202 | AD18: =IF(Ej_Producción!AD47=0,0,AD33/Ej_Producción!AD47) -> 5202 | AE18: 3000 | AF18: =IF(AE18=0,0,(AD18-AE18)/AE18) -> 0.734
B21: INGRESOS EJECUTADO Y PROYECTADO MENSUALES (USD)
B22: Producto | C22: Ene | D22: Feb | E22: Mar | F22: Abr | G22: May | H22: Jun | I22: Jul | J22: Ago | K22: Sep | L22: Oct | M22: Nov | N22: Dic | O22: TOTAL EJEC. PROY. | P22: PROY. AÑO 1 | Q22: DESVÍO USD | R22: Ene | S22: Feb | T22: Mar | U22: Abr | V22: May | W22: Jun | X22: Jul | Y22: Ago | Z22: Sep | AA22: Oct | AB22: Nov | AC22: Dic | AD22: TOTAL PROY. | AE22: PROY. AÑO 2 | AF22: DESVÍO USD
B23: 1. Slitter Portas Autom. | C23: =C8*Ej_Producción!C37 -> 20196 | D23: =D8*Ej_Producción!D37 -> 0 | E23: =E8*Ej_Producción!E37 -> 14741.1 | F23: =F8*Ej_Producción!F37 -> 45558.2 | G23: =G8*Ej_Producción!G37 -> 0 | H23: =H8*Ej_Producción!H37 -> 51480 | I23: =I8*Ej_Producción!I37 -> 77220 | J23: =J8*Ej_Producción!J37 -> 77220 | ... N23: =N8*Ej_Producción!N37 -> 77220 | O23: =SUM(C23:N23) -> 595295.3 | P23: 2208000 | Q23: =O23-P23 -> -1612704.7 | R23: =R8*Ej_Producción!R37 -> 25740 | S23: =S8*Ej_Producción!S37 -> 51480 | T23: =T8*Ej_Producción!T37 -> 77220 | U23: =U8*Ej_Producción!U37 -> 77220 | V23: =V8*Ej_Producción!V37 -> 77220 | W23: =W8*Ej_Producción!W37 -> 77220 | X23: =X8*Ej_Producción!X37 -> 77220 | Y23: =Y8*Ej_Producción!Y37 -> 77220 | ... AC23: =AC8*Ej_Producción!AC37 -> 77220 | AD23: =SUM(R23:AC23) -> 849420 | AE23: 2434320 | AF23: =AD23-AE23 -> -1584900
B24: 2. Slitter Drywall 0,43/0,48 | C24: =C9*Ej_Producción!C38 -> 0 | D24: =D9*Ej_Producción!D38 -> 0 | E24: =E9*Ej_Producción!E38 -> 90384.649 | F24: =F9*Ej_Producción!F38 -> 97043.299 | G24: =G9*Ej_Producción!G38 -> 174334.63 | H24: =H9*Ej_Producción!H38 -> 457738.05 | I24: =I9*Ej_Producción!I38 -> 106040 | J24: =J9*Ej_Producción!J38 -> 48200 | ... N24: =N9*Ej_Producción!N38 -> 202440 | O24: =SUM(C24:N24) -> 1581060.6 | P24: 2808000 | Q24: =O24-P24 -> -1226939.4 | R24: =R9*Ej_Producción!R38 -> 289200 | S24: =S9*Ej_Producción!S38 -> 289200 | T24: =T9*Ej_Producción!T38 -> 375960 | U24: =U9*Ej_Producción!U38 -> 404880 | V24: =V9*Ej_Producción!V38 -> 404880 | W24: =W9*Ej_Producción!W38 -> 404880 | X24: =X9*Ej_Producción!X38 -> 404880 | Y24: =Y9*Ej_Producción!Y38 -> 404880 | ... AC24: =AC9*Ej_Producción!AC38 -> 404880 | AD24: =SUM(R24:AC24) -> 4598280 | AE24: 3095820 | AF24: =AD24-AE24 -> 1502460
B25: 3. Slitter Drywall 0,50 | C25: =C10*Ej_Producción!C39 -> 0 | D25: =D10*Ej_Producción!D39 -> 0 | E25: =E10*Ej_Producción!E39 -> 3973.2 | F25: =F10*Ej_Producción!F39 -> 12337.92 | G25: =G10*Ej_Producción!G39 -> 29688.75 | H25: =H10*Ej_Producción!H39 -> 37981.44 | I25: =I10*Ej_Producción!I39 -> 75600 | J25: =J10*Ej_Producción!J39 -> 54000 | ... N25: =N10*Ej_Producción!N39 -> 32400 | O25: =SUM(C25:N25) -> 397181.31 | P25: 363600 | Q25: =O25-P25 -> 33581.31 | R25: =R10*Ej_Producción!R39 -> 97200 | S25: =S10*Ej_Producción!S39 -> 97200 | T25: =T10*Ej_Producción!T39 -> 129600 | U25: =U10*Ej_Producción!U39 -> 162000 | V25: =V10*Ej_Producción!V39 -> 162000 | W25: =W10*Ej_Producción!W39 -> 162000 | X25: =X10*Ej_Producción!X39 -> 162000 | Y25: =Y10*Ej_Producción!Y39 -> 162000 | ... AC25: =AC10*Ej_Producción!AC39 -> 162000 | AD25: =SUM(R25:AC25) -> 1782000 | AE25: 399808.5 | AF25: =AD25-AE25 -> 1382191.5
B26: 4. Slitter Steel Frame 0,80/0,95 | C26: =C11*Ej_Producción!C40 -> 0 | D26: =D11*Ej_Producción!D40 -> 0 | E26: =E11*Ej_Producción!E40 -> 0 | F26: =F11*Ej_Producción!F40 -> 0 | G26: =G11*Ej_Producción!G40 -> 0 | H26: =H11*Ej_Producción!H40 -> 0 | I26: =I11*Ej_Producción!I40 -> 0 | J26: =J11*Ej_Producción!J40 -> 0 | ... N26: =N11*Ej_Producción!N40 -> 162000 | O26: =SUM(C26:N26) -> 486000 | P26: 0 | Q26: =O26-P26 -> 486000 | R26: =R11*Ej_Producción!R40 -> 97200 | S26: =S11*Ej_Producción!S40 -> 97200 | T26: =T11*Ej_Producción!T40 -> 129600 | U26: =U11*Ej_Producción!U40 -> 162000 | V26: =V11*Ej_Producción!V40 -> 162000 | W26: =W11*Ej_Producción!W40 -> 162000 | X26: =X11*Ej_Producción!X40 -> 162000 | Y26: =Y11*Ej_Producción!Y40 -> 162000 | ... AC26: =AC11*Ej_Producción!AC40 -> 162000 | AD26: =SUM(R26:AC26) -> 1782000 | AE26: 0 | AF26: =AD26-AE26 -> 1782000
B27: 5. Telhas Met. Naturales | C27: =C12*Ej_Producción!C41 -> 0 | D27: =D12*Ej_Producción!D41 -> 0 | E27: =E12*Ej_Producción!E41 -> 0 | F27: =F12*Ej_Producción!F41 -> 0 | G27: =G12*Ej_Producción!G41 -> 0 | H27: =H12*Ej_Producción!H41 -> 0 | I27: =I12*Ej_Producción!I41 -> 0 | J27: =J12*Ej_Producción!J41 -> 73080 | ... N27: =N12*Ej_Producción!N41 -> 36540 | O27: =SUM(C27:N27) -> 292320 | P27: 1932000 | Q27: =O27-P27 -> -1639680 | R27: =R12*Ej_Producción!R41 -> 36540 | S27: =S12*Ej_Producción!S41 -> 36540 | T27: =T12*Ej_Producción!T41 -> 73080 | U27: =U12*Ej_Producción!U41 -> 73080 | V27: =V12*Ej_Producción!V41 -> 73080 | W27: =W12*Ej_Producción!W41 -> 73080 | X27: =X12*Ej_Producción!X41 -> 73080 | Y27: =Y12*Ej_Producción!Y41 -> 73080 | ... AC27: =AC12*Ej_Producción!AC41 -> 73080 | AD27: =SUM(R27:AC27) -> 803880 | AE27: 2130030 | AF27: =AD27-AE27 -> -1326150
B28: 6. Telhas Met. Pre Pintadas | C28: =C13*Ej_Producción!C42 -> 0 | D28: =D13*Ej_Producción!D42 -> 0 | E28: =E13*Ej_Producción!E42 -> 0 | F28: =F13*Ej_Producción!F42 -> 0 | G28: =G13*Ej_Producción!G42 -> 8320 | H28: =H13*Ej_Producción!H42 -> 0 | I28: =I13*Ej_Producción!I42 -> 0 | J28: =J13*Ej_Producción!J42 -> 41970 | ... N28: =N13*Ej_Producción!N42 -> 41970 | O28: =SUM(C28:N28) -> 218170 | P28: 235800 | Q28: =O28-P28 -> -17630 | R28: =R13*Ej_Producción!R42 -> 0 | S28: =S13*Ej_Producción!S42 -> 41970 | T28: =T13*Ej_Producción!T42 -> 41970 | U28: =U13*Ej_Producción!U42 -> 41970 | V28: =V13*Ej_Producción!V42 -> 41970 | W28: =W13*Ej_Producción!W42 -> 41970 | X28: =X13*Ej_Producción!X42 -> 41970 | Y28: =Y13*Ej_Producción!Y42 -> 41970 | ... AC28: =AC13*Ej_Producción!AC42 -> 41970 | AD28: =SUM(R28:AC28) -> 461670 | AE28: 259969.5 | AF28: =AD28-AE28 -> 201700.5
B29: 7. Perfil DW 0,43 Prepint. | C29: =C14*Ej_Producción!C43 -> 0 | D29: =D14*Ej_Producción!D43 -> 0 | E29: =E14*Ej_Producción!E43 -> 0 | F29: =F14*Ej_Producción!F43 -> 0 | G29: =G14*Ej_Producción!G43 -> 0 | H29: =H14*Ej_Producción!H43 -> 0 | I29: =I14*Ej_Producción!I43 -> 0 | J29: =J14*Ej_Producción!J43 -> 0 | ... N29: =N14*Ej_Producción!N43 -> 41970 | O29: =SUM(C29:N29) -> 167880 | P29: 558600 | Q29: =O29-P29 -> -390720 | R29: =R14*Ej_Producción!R43 -> 41970 | S29: =S14*Ej_Producción!S43 -> 41970 | T29: =T14*Ej_Producción!T43 -> 62955 | U29: =U14*Ej_Producción!U43 -> 83940 | V29: =V14*Ej_Producción!V43 -> 83940 | W29: =W14*Ej_Producción!W43 -> 83940 | X29: =X14*Ej_Producción!X43 -> 83940 | Y29: =Y14*Ej_Producción!Y43 -> 83940 | ... AC29: =AC14*Ej_Producción!AC43 -> 83940 | AD29: =SUM(R29:AC29) -> 902355 | AE29: 614460 | AF29: =AD29-AE29 -> 287895
B30: 8. Perfil Drywall 0,50 | C30: =C15*Ej_Producción!C44 -> 0 | D30: =D15*Ej_Producción!D44 -> 0 | E30: =E15*Ej_Producción!E44 -> 0 | F30: =F15*Ej_Producción!F44 -> 0 | G30: =G15*Ej_Producción!G44 -> 0 | H30: =H15*Ej_Producción!H44 -> 0 | I30: =I15*Ej_Producción!I44 -> 0 | J30: =J15*Ej_Producción!J44 -> 0 | ... N30: =N15*Ej_Producción!N44 -> 38160 | O30: =SUM(C30:N30) -> 152640 | P30: 849600 | Q30: =O30-P30 -> -696960 | R30: =R15*Ej_Producción!R44 -> 38160 | S30: =S15*Ej_Producción!S44 -> 38160 | T30: =T15*Ej_Producción!T44 -> 76320 | U30: =U15*Ej_Producción!U44 -> 76320 | V30: =V15*Ej_Producción!V44 -> 76320 | W30: =W15*Ej_Producción!W44 -> 76320 | X30: =X15*Ej_Producción!X44 -> 76320 | Y30: =Y15*Ej_Producción!Y44 -> 76320 | ... AC30: =AC15*Ej_Producción!AC44 -> 76320 | AD30: =SUM(R30:AC30) -> 839520 | AE30: 936684 | AF30: =AD30-AE30 -> -97164
