Workbook

Sheet Guia
A1: Modelo financiero de maquila CIE-PERG — guía de uso
A2: Base documental: plan «Procesamiento de chapas para gabinetes metálicos» (Mujica & Saldivar, Oct-2025) e informe de validación (29/09/2026).
A4: Propósito
C5: Reconstruir el plan publicado, documentar sus inconsistencias y convertirlo en un modelo de actualización continua: reales + forecast, escenarios y evaluación de rentabilidad, liquidez, financiamiento y creación de valor por separado.
C6: Tres capas: (1) PDF publicado Oct-2025 (Base_PDF, inalterado); (2) Base depurada (supuestos históricos + correcciones C1-C6 + motor mensual); (3) Reales + forecast (Datos_Reales hasta el último mes cerrado; escenario activo para el futuro).
A8: Hojas
B9: Resumen | C9: Tablero ejecutivo: PDF vs escenario activo, alertas y gráficos.
B10: Supuestos | C10: Selector único de escenario, prueba de sensibilidad, parámetros generales, préstamo, correcciones metodológicas, drivers por escenario, dividendos y aportes.
B11: Calendario | C11: Meses del modelo (0 = inicio de implantación), años de proyecto y operativos, banderas de operación/horizonte/reales, TC y factores de descuento.
B12: Produccion_Ventas | C12: Capacidad, demanda, rampa, recuperación de volumen, producción buena, rechazos, inventario de PT en unidades, precios y ventas.
B13: Costos_Personal | C13: Nómina por puesto (PYG), maestro de costos fijos con moneda de origen, materiales, costos variables, fijos y resúmenes.
B14: Inversion_Activos | C14: Presupuesto original, ejecutado, comprometido, por contratar, costo final estimado, pagos, altas y depreciación por ítem.
B15: Capital_Trabajo | C15: Clientes por cohortes (DSO interpolado), inventarios, proveedores, anticipos y CT operativo neto (sin caja mínima).
B16: Deuda_Tributos | C16: IVA recuperable, préstamo original (reproduce el PDF), tramo 2 opcional y aportes.
B17: Resultados_Caja | C17: Estado de resultados, caja por método directo con control indirecto, tesorería (caja mínima, brecha, dividendos, línea hipotética), balance de control y flujos de valuación.
B18: Resultados_Anuales | C18: Agregación anual, comparación con el PDF, indicadores (VAN/TIR proyecto y socios, payback, DSCR, equilibrio, rentabilidad por producto).
B19: Escenarios_Sensib | C19: Capturas identificadas de escenarios, pruebas de sensibilidad y puente de correcciones, con verificación en vivo.
B20: Datos_Reales | C20: Tablas vacías para fechas, saldos al corte, CAPEX por ítem, movimientos mensuales, documentación y campos mínimos.
... B22: Validaciones | C22: Controles con tolerancia, registro de inconsistencias del PDF y pruebas realizadas.
A24: Convenciones
B25: Colores | C25: Azul sobre amarillo claro = entrada editable. Amarillo intenso = pendiente de cargar. Verde = vínculo a otra hoja. Negro = fórmula. Gris itálica = valor heredado de la base (sobrescribir para cambiar). Salmón = dato histórico del PDF.
B26: Moneda | C26: Presentación en USD. Nómina y varios costos fijos tienen origen en PYG y se convierten con el TC de cada año; compras en USD no cambian con el TC. Nunca se suman PYG con USD.
B27: Tiempo | C27: Mes 0 = inicio de implantación/desembolso. Sin fecha del mes 0 el modelo trabaja en meses relativos (no se asume año 1 = 2025 o 2026).
B28: Signos | C28: Costos y pagos positivos en sus filas; los flujos (FCFF, socios) llevan signo: negativo = salida.
A30: Cómo usar
B31: Cambiar escenario | C31: Supuestos!D5. Los escenarios Conservador y Recuperación son ILUSTRATIVOS. Actualizado y Personalizado heredan la base hasta que se sobrescriban (columna E/H).
B32: Prueba de sensibilidad | C32: Supuestos!D8 aplica un choque sobre el escenario activo y recalcula todo (tributos, CT, financiamiento e intereses). Volver a «Ninguna».
B33: Correcciones | C33: Supuestos sección C: poner 0 reproduce el criterio del PDF de esa corrección (para el puente de conciliación).
B34: Cierre mensual | C34: 1) Cargar movimientos del mes en Datos_Reales T7 (código, mes, moneda, importe, TC, fuente, estado). 2) Cargar saldos al corte en T2 y CAPEX por ítem en T3. 3) Actualizar T1 «Último mes cerrado». 4) Revisar Validaciones (meses reales sin registros, ajustes de conciliación a patrimonio). 5) Ajustar supuestos futuros en la columna Actualizado. 6) Revisar Resumen y alertas.
B35: Congelamiento | C35: Los meses ≤ último mes cerrado usan solo reales; los escenarios afectan únicamente el futuro. Una diferencia entre saldos reales y calculados se registra como «ajuste de conciliación» en patrimonio y debe investigarse.
A37: Métricas
B38: VAN/TIR del proyecto | C38: FCFF: flujo operativo después de tributos - CAPEX - ΔCT operativo, sin préstamos, intereses, aportes ni dividendos. Tasa del proyecto (G17), mensual equivalente.
B39: VAN/TIR de socios | C39: Aportes (negativos), dividendos efectivamente pagados y valor final atribuible (caja + activos netos - deuda), descontados a Ke. No suma FCFE no distribuido.
B40: Payback | C40: Simple y descontado sobre la misma serie; «No recupera en el horizonte» si no cruza.
B41: Necesidad de financiamiento | C41: Pico antes de aportes adicionales (caja acumulada con préstamo original y aporte inicial vs caja mínima) y brecha no cubierta después del financiamiento planificado.
B42: CFADS y DSCR | C42: CFADS = flujo operativo - CAPEX de mantenimiento. DSCR = CFADS / (capital + intereses + IVA + comisiones). EBITDA/servicio es solo una aproximación.
B43: Equilibrio | C43: En ventas con el mix del año y unidades por producto; no se mezclan gabinetes y cajas como unidades equivalentes.
B44: Valor terminal | C44: Liquidación realizable (por defecto) o negocio en marcha; nunca ambos.
A46: Registro de avance
B47: Versión | C47: v1.0 — 29/09/2026. Libro construido con generar_modelo.py (reproducible).
...

Sheet Resumen
A1: Resumen ejecutivo — Maquila CIE-PERG: procesamiento de chapas para gabinetes y cajas metálicas (USD)
A2: ="Escenario: "&p_Escenario&" | Prueba: "&p_Shock&" | "&INDEX(Supuestos!$D$98:$H$98,1,p_EscIdx) -> Escenario: Base depurada (supuestos Oct-2025) | Prueba: Ninguna | Supuestos históricos Oct-2025 con correcciones metodológicas. NO es ejecución real.
A4: A. Estado del modelo
B5: Escenario activo | C5: =p_Escenario -> Base depurada (supuestos Oct-2025)
B6: Prueba de sensibilidad activa | C6: =p_Shock -> Ninguna
B7: Correcciones metodológicas activas (de 6) | C7: =p_NCorr -> 6
B8: Último mes cerrado con datos reales | C8: =IF(p_MesCorte<0,"Ninguno: proyección con supuestos históricos",p_MesCorte) -> Ninguno: proyección con supuestos históricos
B9: Campos mínimos para forecast actualizado | C9: =r_MinCompletos -> 0 de 10
B10: Calendario | C10: =IF(p_FechaInicio="","PENDIENTE: meses relativos (sin fecha del mes 0)","Mes 0 = "&MONTH(p_FechaInicio)&"/"&YEAR(p_FechaInicio)) -> PENDIENTE: meses relativos (sin fecha del mes 0)
B11: Tasa del proyecto aplicada | C11: =FIXED(p_TasaProy*100,2)&"% — "&p_TasaEstado -> 9.49% — Ponderada inicial PDF (histórica)
B12: Ke aplicado (histórico) | C12: =FIXED(p_Ke*100,2)&"%" -> 16.32%
B13: Controles de Validaciones en estado REVISAR | C13: =v_Revisar -> 0
A15: B. PDF publicado (histórico) vs escenario activo recalculado
B16: Indicador | C16: PDF publicado Oct-2025 (histórico) | D16: Escenario activo (motor) | E16: Diferencia | F16: Nota
B17: Inversión fija inicial / CAPEX estimado total | C17: =Base_PDF!$E$50 -> 655044 | D17: =k_capex_e -> 755044.1 | E17: =IF(AND(ISNUMBER(C17),ISNUMBER(D17)),D17-C17,"") -> 100000.1 | F17: El motor incluye el CAPEX adicional del año 2 (USD 100.000).
B18: Capital operativo inicial (PDF) / CT operativo neto máximo (motor) | C18: =Base_PDF!$E$51 -> 2336543 | D18: =k_ctn_max -> 4942519.1 | E18: =IF(AND(ISNUMBER(C18),ISNUMBER(D18)),D18-C18,"") -> 2605976.1 | F18: Conceptos distintos: el PDF suma CT de un año al inicio; el motor lo construye mes a mes.
B19: Ventas año 1 | C19: =Base_PDF!$F$102 -> 4850000 | D19: =k_v1 -> 4850000 | E19: =IF(AND(ISNUMBER(C19),ISNUMBER(D19)),D19-C19,"") -> 0 | F19: Año de proyecto 1.
B20: Ventas totales 10 años | C20: =Base_PDF!$P$102 -> 81222448 | D20: =k_vt -> 81222448 | E20: =IF(AND(ISNUMBER(C20),ISNUMBER(D20)),D20-C20,"") -> -0.27835459
B21: EBITDA año 1 | C21: =Base_PDF!$F$358 -> 573024 | D21: =k_e1 -> 526818.42 | E21: =IF(AND(ISNUMBER(C21),ISNUMBER(D21)),D21-C21,"") -> -46205.577 | F21: Tributo de maquila incluido una sola vez dentro del EBITDA.
B22: EBITDA total 10 años | C22: =Base_PDF!$P$358 -> 17354010 | D22: =k_et -> 16318100 | E22: =IF(AND(ISNUMBER(C22),ISNUMBER(D22)),D22-C22,"") -> -1035910.1
B23: Resultado neto total | C23: =Base_PDF!$P$359 -> 15945168 | D23: =k_nit -> 14759842 | E23: =IF(AND(ISNUMBER(C23),ISNUMBER(D23)),D23-C23,"") -> -1185326.4
B24: VAN (PDF: cuadro 19 mezcla perspectivas / motor: FCFF del proyecto) | C24: =Base_PDF!$E$58 -> 4588736 | D24: =k_van_p -> 6732540.9 | E24: =IF(AND(ISNUMBER(C24),ISNUMBER(D24)),D24-C24,"") -> 2143804.9 | F24: PUBLICADO, METODOLOGÍA POR DEPURAR vs VAN del proyecto. No son comparables en sentido estricto.
B25: TIR (PDF «con financiamiento» / motor: TIR del proyecto) | C25: =Base_PDF!$E$59 -> 0.2261 | D25: =k_tir_p -> 0.32312817 | E25: =IF(AND(ISNUMBER(C25),ISNUMBER(D25)),D25-C25,"") -> 0.09702817 | F25: Una TIR alta no implica decisión conveniente sin VAN, caja y riesgo.
B26: VAN de los socios a Ke (PDF reexpresado / motor) | C26: =Base_PDF!$E$427 -> 3912957.6 | D26: =k_van_e -> 3748260 | E26: =IF(AND(ISNUMBER(C26),ISNUMBER(D26)),D26-C26,"") -> -164697.58 | F26: Aportes, dividendos pagados y valor final.
B27: TIR de los socios (PDF reexpresado / motor) | C27: =Base_PDF!$E$428 -> 0.49362358 | D27: =k_tir_e -> 0.44982914 | E27: =IF(AND(ISNUMBER(C27),ISNUMBER(D27)),D27-C27,"") -> -0.043794439
B28: Payback descontado (PDF: serie desde -2.791.587 / motor: FCFF) | C28: =Base_PDF!$E$60 -> 7 | D28: =k_pb_d -> 5.1359395 | E28: =IF(AND(ISNUMBER(C28),ISNUMBER(D28)),D28-C28,"") -> -1.8640605 | F28: Años. PDF «durante el 7mo año»; sobre la serie del VAN ≈ 6,89. Motor simple en Resultados_Anuales.
B29: Aportes de socios en efectivo (total) | C29: =Base_PDF!$E$14+Base_PDF!$E$386 -> 1139710 | D29: =k_ap -> 1139710 | E29: =IF(AND(ISNUMBER(C29),ISNUMBER(D29)),D29-C29,"") -> 0
B30: Pico de necesidad de fondos adicionales (antes de aportes adicionales) | C30: =Base_PDF!$E$386 -> 939710 | D30: =k_nec -> 1529018.5 | E30: =IF(AND(ISNUMBER(C30),ISNUMBER(D30)),D30-C30,"") -> 589308.48 | F30: PDF: aportes adicionales planificados. Motor: necesidad mensual acumulada incluida la caja mínima.
B31: Brecha no cubierta máxima (con financiamiento planificado) | C31: 0 | D31: =k_brecha_nc -> 589308.48 | E31: =IF(AND(ISNUMBER(C31),ISNUMBER(D31)),D31-C31,"") -> 589308.48 | F31: El motor no inserta fondos ficticios: la brecha queda visible.
B32: Deuda financiera máxima | C32: =Base_PDF!$E$15 -> 2791587 | D32: =k_deuda_max -> 2791587 | E32: =IF(AND(ISNUMBER(C32),ISNUMBER(D32)),D32-C32,"") -> 0
B33: DSCR mínimo (CFADS / servicio de deuda) | C33: n/d en el PDF | D33: =k_dscr_min -> -2.5448787 | E33: =IF(AND(ISNUMBER(C33),ISNUMBER(D33)),D33-C33,"") | F33: EBITDA/servicio año 1 PDF ≈ 1,08x (aproximación, no DSCR).
B34: Equilibrio año 1 (PDF: unidades mezcladas / motor: ventas USD) | C34: =Base_PDF!$F$392 -> 66042 | D34: =k_pe1 -> 3538366.4 | E34: =IF(AND(ISNUMBER(C34),ISNUMBER(D34)),D34-C34,"") -> 3472324.4 | F34: Motor: ver gabinetes y cajas en equilibrio con el mix del año.
A36: C. Alertas específicas
B37: =IF(p_EscIdx=1,"Base depurada: supuestos de Oct-2025 con correcciones metodológicas; NO es situación real de 2026.",IF(p_EscIdx=2,INDEX(Supuestos!$D$98:$H$98,1,2),"Escenario "&p_Escenario&": "&INDEX(Supuestos!$D$98:$H$98,1,p_EscIdx))) -> Base depurada: supuestos de Oct-2025 con correcciones metodológicas; NO es situación real de 2026.
B38: =IF(p_ShockIdx>1,"PRUEBA DE SENSIBILIDAD ACTIVA («"&p_Shock&"»): los resultados son un choque ilustrativo. Volver a «Ninguna».","")
B39: =IF(k_brecha_nc>0.5,"Brecha de caja no cubierta: máx. USD "&FIXED(k_brecha_nc,0)&" en "&k_brecha_nc_n&" meses. El financiamiento planificado no alcanza; definir aportes, deuda o mejoras de CT.","Sin brecha de caja no cubierta con el financiamiento planificado.") -> Brecha de caja no cubierta: máx. USD 589,308 en 32 meses. El financiamiento planificado no alcanza; definir aportes, deuda o mejoras de CT.
B40: ="Pico de necesidad antes de aportes adicionales: USD "&FIXED(k_nec,0)&" en el mes "&k_nec_m&" (PDF planificó USD 939.710 de aportes adicionales)." -> Pico de necesidad antes de aportes adicionales: USD 1,529,018 en el mes 28 (PDF planificó USD 939.710 de aportes adicionales).
B41: =IF(k_chk_cap>0,k_chk_cap&" meses con producción sobre la capacidad del plan: requiere horas extra, turno o inversión explícitos.","") -> 2 meses con producción sobre la capacidad del plan: requiere horas extra, turno o inversión explícitos.
B42: =IF(ISNUMBER(k_dscr_min),IF(k_dscr_min<1,"DSCR mínimo "&FIXED(k_dscr_min,2)&"x: el flujo operativo (incluida la formación de CT del arranque) no cubre el servicio de deuda en algún año; se financia con aportes o caja.",""),"") -> DSCR mínimo -2.54x: el flujo operativo (incluida la formación de CT del arranque) no cubre el servicio de deuda en algún año; se financia con aportes o caja.
B43: =IF(ISNUMBER(k_tir_p),IF(LEFT(k_tir_p_u,5)<>"Única","TIR del proyecto con posibles valores múltiples: priorizar VAN.",""),"TIR del proyecto no disponible: "&k_tir_p)
...

Sheet Supuestos
A1: Supuestos — selector de escenario, parámetros y drivers
A2: Celdas amarillas con texto azul = entradas editables. Gris itálica = hereda de la base (sobrescribir para cambiar). Los parámetros tributarios y económicos no están embebidos en fórmulas.
A4: A. Selector de escenario y prueba de sensibilidad
B5: Escenario activo (único selector de supuestos futuros) | D5: Base depurada (supuestos Oct-2025) | H5: Cambia solo el futuro: los meses reales (hasta el último mes cerrado) no se modifican.
B6: Índice del escenario activo | D6: =MATCH(p_Escenario,$D$97:$H$97,0) -> 1
B7: Estado del escenario activo | D7: =INDEX($D$98:$H$98,1,p_EscIdx) -> Supuestos históricos Oct-2025 con correcciones metodológicas. NO es ejecución real.
B8: Prueba de sensibilidad activa (choque ilustrativo sobre el escenario) | D8: Ninguna | H8: Choques de prueba del modelo, no premisas de negocio. Volver a «Ninguna» al terminar.
B9: Índice de la prueba activa | D9: =MATCH(p_Shock,$B$192:$B$207,0) -> 1
A11: B. Parámetros generales (no dependen del escenario)
A12: Cód. | B12: Parámetro | C12: Unidad / moneda | D12: Valor | E12: Vigencia | F12: Fuente / pág. | G12: Estado | H12: Nota
A13: G01 | B13: Tipo de cambio de referencia del plan | C13: Gs/USD | D13: =Base_PDF!$E$7 -> 7300 | E13: Histórico Oct-2025 | F13: PDF p. 4-5 | G13: Publicado (PDF)
A14: G02 | B14: TC implícito en la nómina del PDF (solo para reproducir) | C14: Gs/USD | D14: =Base_PDF!$E$10 -> 8000 | E14: Histórico | F14: PDF p. 30-34 | G14: Inferido | H14: Se usa únicamente si la corrección C1 está desactivada.
A15: G03 | B15: Meses de implantación previstos antes del primer mes operativo | C15: meses | D15: 0 | E15: Plan | F15: PDF: año 0 puntual | G15: Supuesto provisional | H15: El PDF concentra la inversión en el año 0 y opera desde el año 1. Cargar el cronograma real si difiere.
A16: G04 | B16: Fecha calendario del mes 0 (inicio de implantación / desembolso) | C16: fecha | E16: — | F16: No informada en el PDF | G16: Pendiente de confirmar | H16: Sin fecha el modelo usa meses relativos. No se infiere que año 1 = 2025 o 2026.
A17: G05 | B17: Modo de horizonte (1 = fecha final fija; 2 = 10 años desde el arranque efectivo) | C17: 1/2 | D17: 1 | E17: Todo | F17: Prompt 5.6 | G17: Supuesto provisional | H17: Con 1 un atraso acorta la operación (no prolonga la vida). Con 2 se compara 10 años desde la puesta en marcha efectiva.
A18: G06 | B18: Años operativos del plan | C18: años | D18: 10 | E18: Todo | F18: PDF | G18: Publicado (PDF)
A19: G07 | B19: Meses operativos del plan | C19: meses | D19: =p_AniosOp*12 -> 120 | E19: Todo | F19: Cálculo | G19: Cálculo
A20: G08 | B20: Días por año (convención de días de CT) | C20: días | D20: 365 | E20: Todo | F20: PDF cuadro 16 | G20: Publicado (PDF)
A21: G09 | B21: Días promedio por mes | C21: días | D21: =p_DiasAnio/12 -> 30.416667 | E21: Todo | F21: Cálculo | G21: Cálculo
A22: G10 | B22: Costo del capital propio Ke (anual efectiva, USD nominal) | C22: % | D22: =Base_PDF!$E$11 -> 0.1632 | E22: Histórico | F22: PDF p. 9 | G22: Publicado (PDF) - histórico no vigente confirmado | H22: Hipótesis histórica. Actualizar con fecha y fundamento (tasa libre de riesgo, prima, riesgo país, tamaño).
A23: G11 | B23: Tasa bancaria de referencia (nominal anual) | C23: % | D23: =Base_PDF!$E$12 -> 0.09 | E23: Histórico | F23: PDF p. 4 | G23: Publicado (PDF) - histórico
A24: G12 | B24: Tasa de descuento del proyecto: 1 = ponderada inicial PDF; 2 = WACC con estructura objetivo; 3 = manual | C24: 1/2/3 | D24: 1 | E24: Todo | F24: Prompt 8.5 | G24: Supuesto provisional | H24: La ponderada inicial usa pesos del momento 0 (6,7%/93,3%), que no representan la estructura durante 10 años.
A25: G13 | B25: Peso objetivo de la deuda D/(D+E) para el método 2 | C25: % | E25: Todo | F25: — | G25: Pendiente de definir | H25: Definir estructura objetivo justificada o usar APV si el apalancamiento cambia materialmente.
A26: G14 | B26: Costo efectivo de la deuda = tasa x (1 + IVA intereses no recuperable) | C26: % | D26: =p_Kd*(1+p_IVAint) -> 0.099 | E26: Todo | F26: Cálculo | G26: Cálculo | H26: Sin escudo de IRE: el plan asume IRE no aplicable bajo maquila (verificar).
A27: G15 | B27: Tasa manual del proyecto (método 3) | C27: % | E27: Todo | F27: — | G27: Pendiente de definir
A28: G16 | B28: Tasa ponderada inicial exacta (método 1) | C28: % | D28: =Base_PDF!$E$409 -> 0.094893724 | E28: Histórico | F28: PDF p. 28 | G28: Publicado (PDF) - cálculo exacto
A29: G17 | B29: Tasa de descuento del proyecto aplicada (anual efectiva) | C29: % | D29: =IF(p_MetodoTasa=2,IF(p_DV="",p_TasaPDF,p_DV*p_KdEf+(1-p_DV)*p_Ke),IF(p_MetodoTasa=3,IF(p_TasaManual="",p_TasaPDF,p_TasaManual),p_TasaPDF)) -> 0.094893724 | E29: Todo | F29: Cálculo | G29: Cálculo | H29: Si faltan datos del método elegido, vuelve al método 1 y lo informa en el estado siguiente.
A30: G18 | B30: Estado de la tasa del proyecto | C30: texto | D30: =IF(AND(p_MetodoTasa=2,p_DV=""),"Método 2 sin peso objetivo: se usa ponderada inicial",IF(AND(p_MetodoTasa=3,p_TasaManual=""),"Método 3 sin tasa: se usa ponderada inicial",IF(p_MetodoTasa=1,"Ponderada inicial PDF (histórica)","OK"))) -> Ponderada inicial PDF (histórica) | E30: Todo | F30: Cálculo | G30: Cálculo
A31: G19 | B31: IRE sobre resultado (régimen de maquila) | C31: % | D31: 0 | E31: Todo | F31: PDF p. 7-8 | G31: Publicado (PDF) - verificar Ley 7547/2025 | H31: El plan considera IRE no aplicable. No se aplica escudo fiscal de intereses. Impuesto a dividendos: pendiente de verificar.
A32: G20 | B32: Valor terminal: 1 = liquidación realizable; 2 = negocio en marcha (perpetuidad) | C32: 1/2 | D32: 1 | E32: Fin de horizonte | F32: Prompt 8.9 | G32: Supuesto provisional | H32: En negocio en marcha no se recupera el CT ni se vende el activo (se necesitan para operar).
A33: G21 | B33: Crecimiento perpetuo nominal en USD (solo método 2) | C33: % | D33: 0 | E33: Perpetuidad | F33: — | G33: Supuesto provisional
A34: G22 | B34: Realización de cuentas por cobrar al cierre (liquidación) | C34: % | D34: 1 | E34: Fin de horizonte | F34: — | G34: Supuesto provisional
A35: G23 | B35: Realización de inventarios al cierre (liquidación) | C35: % | D35: 1 | E35: Fin de horizonte | F35: — | G35: Supuesto provisional
A36: G24 | B36: Realización del activo fijo (% del valor neto contable) | C36: % | D36: 1 | E36: Fin de horizonte | F36: — | G36: Supuesto provisional | H36: Un valor contable residual no es automáticamente precio de venta. Reemplazar por tasación.
A37: G25 | B37: Costos e impuestos de cierre / liquidación | C37: USD | D37: 0 | E37: Fin de horizonte | F37: — | G37: Pendiente de estimar
A38: G26 | B38: Modalidad de facturación: 1 = venta de producto (PDF); 2 = servicio de maquila | C38: 1/2 | D38: 1 | E38: Todo | F38: PDF p. 6; contrato pendiente | G38: Pendiente de confirmar | H38: Con 2 los ingresos son tarifa de servicio y los materiales del cliente no son costo ni inventario propio.
A39: G27 | B39: Tarifa de servicio de maquila por gabinete (modalidad 2) | C39: USD/u | E39: Año 1 | F39: Contrato | G39: Pendiente de cargar
A40: G28 | B40: Tarifa de servicio de maquila por caja (modalidad 2) | C40: USD/u | E40: Año 1 | F40: Contrato | G40: Pendiente de cargar
A41: G29 | B41: % de materiales (MP, insumos, flete MP) propiedad del cliente en modalidad 2 | C41: % | D41: 1 | E41: Todo | F41: Contrato | G41: Pendiente de confirmar
A42: G30 | B42: Driver de costos comunes: 1 = kg procesado; 2 = costo directo (criterio PDF); 3 = horas estándar | C42: 1/2/3 | D42: 1 | E42: Todo | F42: Prompt 6.6 | G42: Supuesto provisional | H42: Reparto provisional. Reemplazar por horas máquina/hombre cuando se disponga.
...

Sheet Calendario
A1: Calendario — meses del modelo, años, banderas de operación/horizonte/reales, TC y factores de descuento
A2: Motor único: fórmulas homogéneas por mes. Columna E = total del horizonte o saldo al cierre del horizonte. No editar fórmulas; los supuestos se cambian en Supuestos / Datos_Reales.
B4: Calendario del modelo (meses relativos; fechas solo si se cargó la fecha del mes 0)
A5: m | B5: Mes del modelo (0 = inicio de implantación / desembolso) | C5: n° | F5: 0 | G5: 1 | H5: 2 | I5: 3 | J5: 4 | K5: 5 | L5: 6 | M5: 7 | N5: 8 | O5: 9 | P5: 10 | Q5: 11 | R5: 12 | S5: 13 | T5: 14 | U5: 15 | V5: 16 | W5: 17 | X5: 18 | Y5: 19 | Z5: 20 | AA5: 21 | AB5: 22 | AC5: 23 | AD5: 24 | AE5: 25 | AF5: 26 | AG5: 27 | AH5: 28 | AI5: 29 | AJ5: 30 | AK5: 31 | AL5: 32 | AM5: 33 | AN5: 34 | AO5: 35 | AP5: 36 | AQ5: 37 | AR5: 38 | AS5: 39 | AT5: 40 | AU5: 41 | AV5: 42 | AW5: 43 | AX5: 44 | AY5: 45 | AZ5: 46 | BA5: 47 | BB5: 48 | BC5: 49 | BD5: 50 | BE5: 51 | BF5: 52 | BG5: 53 | BH5: 54 | BI5: 55 | BJ5: 56 | BK5: 57 | BL5: 58 | BM5: 59 | BN5: 60 | BO5: 61 | BP5: 62 | BQ5: 63 | BR5: 64 | BS5: 65 | BT5: 66 | BU5: 67 | BV5: 68 | BW5: 69 | BX5: 70 | BY5: 71 | BZ5: 72 | CA5: 73 | CB5: 74 | CC5: 75 | CD5: 76 | CE5: 77 | CF5: 78 | CG5: 79 | CH5: 80 | CI5: 81 | CJ5: 82 | CK5: 83 | CL5: 84 | CM5: 85 | CN5: 86 | CO5: 87 | CP5: 88 | CQ5: 89 | CR5: 90 | CS5: 91 | CT5: 92 | CU5: 93 | CV5: 94 | CW5: 95 | CX5: 96 | CY5: 97 | CZ5: 98 | DA5: 99 | DB5: 100 | DC5: 101 | DD5: 102 | DE5: 103 | DF5: 104 | DG5: 105 | DH5: 106 | DI5: 107 | DJ5: 108 | DK5: 109 | DL5: 110 | DM5: 111 | DN5: 112 | DO5: 113 | DP5: 114 | DQ5: 115 | DR5: 116 | DS5: 117 | DT5: 118 | DU5: 119 | DV5: 120 | DW5: 121 | DX5: 122 | DY5: 123 | DZ5: 124 | EA5: 125 | EB5: 126 | EC5: 127 | ED5: 128 | EE5: 129 | EF5: 130 | EG5: 131 | EH5: 132 | EI5: 133 | EJ5: 134 | EK5: 135 | EL5: 136 | EM5: 137 | EN5: 138 | EO5: 139 | EP5: 140 | EQ5: 141 | ER5: 142 | ES5: 143 | ET5: 144 | EU5: 145 | EV5: 146 | EW5: 147 | EX5: 148 | EY5: 149 | EZ5: 150 | FA5: 151 | FB5: 152 | FC5: 153 | FD5: 154 | FE5: 155 | FF5: 156
A6: fecha | B6: Fecha de fin de mes | C6: fecha | F6: =IF(p_FechaInicio="","s/f",EOMONTH(p_FechaInicio,0)) -> s/f | G6: =IF(p_FechaInicio="","s/f",EOMONTH(p_FechaInicio,1)) -> s/f | H6: =IF(p_FechaInicio="","s/f",EOMONTH(p_FechaInicio,2)) -> s/f | I6: =IF(p_FechaInicio="","s/f",EOMONTH(p_FechaInicio,3)) -> s/f | J6: =IF(p_FechaInicio="","s/f",EOMONTH(p_FechaInicio,4)) -> s/f | K6: =IF(p_FechaInicio="","s/f",EOMONTH(p_FechaInicio,5)) -> s/f | L6: =IF(p_FechaInicio="","s/f",EOMONTH(p_FechaInicio,6)) -> s/f | M6: =IF(p_FechaInicio="","s/f",EOMONTH(p_FechaInicio,7)) -> s/f | N6: =IF(p_FechaInicio="","s/f",EOMONTH(p_FechaInicio,8)) -> s/f | O6: =IF(p_FechaInicio="","s/f",EOMONTH(p_FechaInicio,9)) -> s/f | P6: =IF(p_FechaInicio="","s/f",EOMONTH(p_FechaInicio,10)) -> s/f | Q6: =IF(p_FechaInicio="","s/f",EOMONTH(p_FechaInicio,11)) -> s/f | R6: =IF(p_FechaInicio="","s/f",EOMONTH(p_FechaInicio,12)) -> s/f | S6: =IF(p_FechaInicio="","s/f",EOMONTH(p_FechaInicio,13)) -> s/f | T6: =IF(p_FechaInicio="","s/f",EOMONTH(p_FechaInicio,14)) -> s/f | U6: =IF(p_FechaInicio="","s/f",EOMONTH(p_FechaInicio,15)) -> s/f | V6: =IF(p_FechaInicio="","s/f",EOMONTH(p_FechaInicio,16)) -> s/f | W6: =IF(p_FechaInicio="","s/f",EOMONTH(p_FechaInicio,17)) -> s/f | X6: =IF(p_FechaInicio="","s/f",EOMONTH(p_FechaInicio,18)) -> s/f | Y6: =IF(p_FechaInicio="","s/f",EOMONTH(p_FechaInicio,19)) -> s/f | Z6: =IF(p_FechaInicio="","s/f",EOMONTH(p_FechaInicio,20)) -> s/f | AA6: =IF(p_FechaInicio="","s/f",EOMONTH(p_FechaInicio,21)) -> s/f | AB6: =IF(p_FechaInicio="","s/f",EOMONTH(p_FechaInicio,22)) -> s/f | AC6: =IF(p_FechaInicio="","s/f",EOMONTH(p_FechaInicio,23)) -> s/f | AD6: =IF(p_FechaInicio="","s/f",EOMONTH(p_FechaInicio,24)) -> s/f | AE6: =IF(p_FechaInicio="","s/f",EOMONTH(p_FechaInicio,25)) -> s/f | AF6: =IF(p_FechaInicio="","s/f",EOMONTH(p_FechaInicio,26)) -> s/f | AG6: =IF(p_FechaInicio="","s/f",EOMONTH(p_FechaInicio,27)) -> s/f | AH6: =IF(p_FechaInicio="","s/f",EOMONTH(p_FechaInicio,28)) -> s/f | AI6: =IF(p_FechaInicio="","s/f",EOMONTH(p_FechaInicio,29)) -> s/f | AJ6: =IF(p_FechaInicio="","s/f",EOMONTH(p_FechaInicio,30)) -> s/f | AK6: =IF(p_FechaInicio="","s/f",EOMONTH(p_FechaInicio,31)) -> s/f | AL6: =IF(p_FechaInicio="","s/f",EOMONTH(p_FechaInicio,32)) -> s/f | AM6: =IF(p_FechaInicio="","s/f",EOMONTH(p_FechaInicio,33)) -> s/f | AN6: =IF(p_FechaInicio="","s/f",EOMONTH(p_FechaInicio,34)) -> s/f | AO6: =IF(p_FechaInicio="","s/f",EOMONTH(p_FechaInicio,35)) -> s/f | AP6: =IF(p_FechaInicio="","s/f",EOMONTH(p_FechaInicio,36)) -> s/f | AQ6: =IF(p_FechaInicio="","s/f",EOMONTH(p_FechaInicio,37)) -> s/f | AR6: =IF(p_FechaInicio="","s/f",EOMONTH(p_FechaInicio,38)) -> s/f | AS6: =IF(p_FechaInicio="","s/f",EOMONTH(p_FechaInicio,39)) -> s/f | AT6: =IF(p_FechaInicio="","s/f",EOMONTH(p_FechaInicio,40)) -> s/f | AU6: =IF(p_FechaInicio="","s/f",EOMONTH(p_FechaInicio,41)) -> s/f | AV6: =IF(p_FechaInicio="","s/f",EOMONTH(p_FechaInicio,42)) -> s/f | AW6: =IF(p_FechaInicio="","s/f",EOMONTH(p_FechaInicio,43)) -> s/f | AX6: =IF(p_FechaInicio="","s/f",EOMONTH(p_FechaInicio,44)) -> s/f | AY6: =IF(p_FechaInicio="","s/f",EOMONTH(p_FechaInicio,45)) -> s/f | AZ6: =IF(p_FechaInicio="","s/f",EOMONTH(p_FechaInicio,46)) -> s/f | BA6: =IF(p_FechaInicio="","s/f",EOMONTH(p_FechaInicio,47)) -> s/f | BB6: =IF(p_FechaInicio="","s/f",EOMONTH(p_FechaInicio,48)) -> s/f | BC6: =IF(p_FechaInicio="","s/f",EOMONTH(p_FechaInicio,49)) -> s/f | BD6: =IF(p_FechaInicio="","s/f",EOMONTH(p_FechaInicio,50)) -> s/f | BE6: =IF(p_FechaInicio="","s/f",EOMONTH(p_FechaInicio,51)) -> s/f | BF6: =IF(p_FechaInicio="","s/f",EOMONTH(p_FechaInicio,52)) -> s/f | BG6: =IF(p_FechaInicio="","s/f",EOMONTH(p_FechaInicio,53)) -> s/f | BH6: =IF(p_FechaInicio="","s/f",EOMONTH(p_FechaInicio,54)) -> s/f | BI6: =IF(p_FechaInicio="","s/f",EOMONTH(p_FechaInicio,55)) -> s/f | BJ6: =IF(p_FechaInicio="","s/f",EOMONTH(p_FechaInicio,56)) -> s/f | BK6: =IF(p_FechaInicio="","s/f",EOMONTH(p_FechaInicio,57)) -> s/f | BL6: =IF(p_FechaInicio="","s/f",EOMONTH(p_FechaInicio,58)) -> s/f | BM6: =IF(p_FechaInicio="","s/f",EOMONTH(p_FechaInicio,59)) -> s/f | BN6: =IF(p_FechaInicio="","s/f",EOMONTH(p_FechaInicio,60)) -> s/f | BO6: =IF(p_FechaInicio="","s/f",EOMONTH(p_FechaInicio,61)) -> s/f | BP6: =IF(p_FechaInicio="","s/f",EOMONTH(p_FechaInicio,62)) -> s/f | BQ6: =IF(p_FechaInicio="","s/f",EOMONTH(p_FechaInicio,63)) -> s/f | BR6: =IF(p_FechaInicio="","s/f",EOMONTH(p_FechaInicio,64)) -> s/f | BS6: =IF(p_FechaInicio="","s/f",EOMONTH(p_FechaInicio,65)) -> s/f | BT6: =IF(p_FechaInicio="","s/f",EOMONTH(p_FechaInicio,66)) -> s/f | BU6: =IF(p_FechaInicio="","s/f",EOMONTH(p_FechaInicio,67)) -> s/f | BV6: =IF(p_FechaInicio="","s/f",EOMONTH(p_FechaInicio,68)) -> s/f | BW6: =IF(p_FechaInicio="","s/f",EOMONTH(p_FechaInicio,69)) -> s/f | BX6: =IF(p_FechaInicio="","s/f",EOMONTH(p_FechaInicio,70)) -> s/f | BY6: =IF(p_FechaInicio="","s/f",EOMONTH(p_FechaInicio,71)) -> s/f | BZ6: =IF(p_FechaInicio="","s/f",EOMONTH(p_FechaInicio,72)) -> s/f | CA6: =IF(p_FechaInicio="","s/f",EOMONTH(p_FechaInicio,73)) -> s/f | CB6: =IF(p_FechaInicio="","s/f",EOMONTH(p_FechaInicio,74)) -> s/f | CC6: =IF(p_FechaInicio="","s/f",EOMONTH(p_FechaInicio,75)) -> s/f | CD6: =IF(p_FechaInicio="","s/f",EOMONTH(p_FechaInicio,76)) -> s/f | CE6: =IF(p_FechaInicio="","s/f",EOMONTH(p_FechaInicio,77)) -> s/f | CF6: =IF(p_FechaInicio="","s/f",EOMONTH(p_FechaInicio,78)) -> s/f | CG6: =IF(p_FechaInicio="","s/f",EOMONTH(p_FechaInicio,79)) -> s/f | CH6: =IF(p_FechaInicio="","s/f",EOMONTH(p_FechaInicio,80)) -> s/f | CI6: =IF(p_FechaInicio="","s/f",EOMONTH(p_FechaInicio,81)) -> s/f | CJ6: =IF(p_FechaInicio="","s/f",EOMONTH(p_FechaInicio,82)) -> s/f | CK6: =IF(p_FechaInicio="","s/f",EOMONTH(p_FechaInicio,83)) -> s/f | CL6: =IF(p_FechaInicio="","s/f",EOMONTH(p_FechaInicio,84)) -> s/f | CM6: =IF(p_FechaInicio="","s/f",EOMONTH(p_FechaInicio,85)) -> s/f | CN6: =IF(p_FechaInicio="","s/f",EOMONTH(p_FechaInicio,86)) -> s/f | CO6: =IF(p_FechaInicio="","s/f",EOMONTH(p_FechaInicio,87)) -> s/f | CP6: =IF(p_FechaInicio="","s/f",EOMONTH(p_FechaInicio,88)) -> s/f | CQ6: =IF(p_FechaInicio="","s/f",EOMONTH(p_FechaInicio,89)) -> s/f | CR6: =IF(p_FechaInicio="","s/f",EOMONTH(p_FechaInicio,90)) -> s/f | CS6: =IF(p_FechaInicio="","s/f",EOMONTH(p_FechaInicio,91)) -> s/f | CT6: =IF(p_FechaInicio="","s/f",EOMONTH(p_FechaInicio,92)) -> s/f | CU6: =IF(p_FechaInicio="","s/f",EOMONTH(p_FechaInicio,93)) -> s/f | CV6: =IF(p_FechaInicio="","s/f",EOMONTH(p_FechaInicio,94)) -> s/f | CW6: =IF(p_FechaInicio="","s/f",EOMONTH(p_FechaInicio,95)) -> s/f | CX6: =IF(p_FechaInicio="","s/f",EOMONTH(p_FechaInicio,96)) -> s/f | CY6: =IF(p_FechaInicio="","s/f",EOMONTH(p_FechaInicio,97)) -> s/f | CZ6: =IF(p_FechaInicio="","s/f",EOMONTH(p_FechaInicio,98)) -> s/f | DA6: =IF(p_FechaInicio="","s/f",EOMONTH(p_FechaInicio,99)) -> s/f | DB6: =IF(p_FechaInicio="","s/f",EOMONTH(p_FechaInicio,100)) -> s/f | DC6: =IF(p_FechaInicio="","s/f",EOMONTH(p_FechaInicio,101)) -> s/f | DD6: =IF(p_FechaInicio="","s/f",EOMONTH(p_FechaInicio,102)) -> s/f | DE6: =IF(p_FechaInicio="","s/f",EOMONTH(p_FechaInicio,103)) -> s/f | DF6: =IF(p_FechaInicio="","s/f",EOMONTH(p_FechaInicio,104)) -> s/f | DG6: =IF(p_FechaInicio="","s/f",EOMONTH(p_FechaInicio,105)) -> s/f | DH6: =IF(p_FechaInicio="","s/f",EOMONTH(p_FechaInicio,106)) -> s/f | DI6: =IF(p_FechaInicio="","s/f",EOMONTH(p_FechaInicio,107)) -> s/f | DJ6: =IF(p_FechaInicio="","s/f",EOMONTH(p_FechaInicio,108)) -> s/f | DK6: =IF(p_FechaInicio="","s/f",EOMONTH(p_FechaInicio,109)) -> s/f | DL6: =IF(p_FechaInicio="","s/f",EOMONTH(p_FechaInicio,110)) -> s/f | DM6: =IF(p_FechaInicio="","s/f",EOMONTH(p_FechaInicio,111)) -> s/f | DN6: =IF(p_FechaInicio="","s/f",EOMONTH(p_FechaInicio,112)) -> s/f | DO6: =IF(p_FechaInicio="","s/f",EOMONTH(p_FechaInicio,113)) -> s/f | DP6: =IF(p_FechaInicio="","s/f",EOMONTH(p_FechaInicio,114)) -> s/f | DQ6: =IF(p_FechaInicio="","s/f",EOMONTH(p_FechaInicio,115)) -> s/f | DR6: =IF(p_FechaInicio="","s/f",EOMONTH(p_FechaInicio,116)) -> s/f | DS6: =IF(p_FechaInicio="","s/f",EOMONTH(p_FechaInicio,117)) -> s/f | DT6: =IF(p_FechaInicio="","s/f",EOMONTH(p_FechaInicio,118)) -> s/f | DU6: =IF(p_FechaInicio="","s/f",EOMONTH(p_FechaInicio,119)) -> s/f | DV6: =IF(p_FechaInicio="","s/f",EOMONTH(p_FechaInicio,120)) -> s/f | DW6: =IF(p_FechaInicio="","s/f",EOMONTH(p_FechaInicio,121)) -> s/f | DX6: =IF(p_FechaInicio="","s/f",EOMONTH(p_FechaInicio,122)) -> s/f | DY6: =IF(p_FechaInicio="","s/f",EOMONTH(p_FechaInicio,123)) -> s/f | DZ6: =IF(p_FechaInicio="","s/f",EOMONTH(p_FechaInicio,124)) -> s/f | EA6: =IF(p_FechaInicio="","s/f",EOMONTH(p_FechaInicio,125)) -> s/f | EB6: =IF(p_FechaInicio="","s/f",EOMONTH(p_FechaInicio,126)) -> s/f | EC6: =IF(p_FechaInicio="","s/f",EOMONTH(p_FechaInicio,127)) -> s/f | ED6: =IF(p_FechaInicio="","s/f",EOMONTH(p_FechaInicio,128)) -> s/f | EE6: =IF(p_FechaInicio="","s/f",EOMONTH(p_FechaInicio,129)) -> s/f | EF6: =IF(p_FechaInicio="","s/f",EOMONTH(p_FechaInicio,130)) -> s/f | EG6: =IF(p_FechaInicio="","s/f",EOMONTH(p_FechaInicio,131)) -> s/f | EH6: =IF(p_FechaInicio="","s/f",EOMONTH(p_FechaInicio,132)) -> s/f | EI6: =IF(p_FechaInicio="","s/f",EOMONTH(p_FechaInicio,133)) -> s/f | EJ6: =IF(p_FechaInicio="","s/f",EOMONTH(p_FechaInicio,134)) -> s/f | EK6: =IF(p_FechaInicio="","s/f",EOMONTH(p_FechaInicio,135)) -> s/f | EL6: =IF(p_FechaInicio="","s/f",EOMONTH(p_FechaInicio,136)) -> s/f | EM6: =IF(p_FechaInicio="","s/f",EOMONTH(p_FechaInicio,137)) -> s/f | EN6: =IF(p_FechaInicio="","s/f",EOMONTH(p_FechaInicio,138)) -> s/f | EO6: =IF(p_FechaInicio="","s/f",EOMONTH(p_FechaInicio,139)) -> s/f | EP6: =IF(p_FechaInicio="","s/f",EOMONTH(p_FechaInicio,140)) -> s/f | EQ6: =IF(p_FechaInicio="","s/f",EOMONTH(p_FechaInicio,141)) -> s/f | ER6: =IF(p_FechaInicio="","s/f",EOMONTH(p_FechaInicio,142)) -> s/f | ES6: =IF(p_FechaInicio="","s/f",EOMONTH(p_FechaInicio,143)) -> s/f | ET6: =IF(p_FechaInicio="","s/f",EOMONTH(p_FechaInicio,144)) -> s/f | EU6: =IF(p_FechaInicio="","s/f",EOMONTH(p_FechaInicio,145)) -> s/f | EV6: =IF(p_FechaInicio="","s/f",EOMONTH(p_FechaInicio,146)) -> s/f | EW6: =IF(p_FechaInicio="","s/f",EOMONTH(p_FechaInicio,147)) -> s/f | EX6: =IF(p_FechaInicio="","s/f",EOMONTH(p_FechaInicio,148)) -> s/f | EY6: =IF(p_FechaInicio="","s/f",EOMONTH(p_FechaInicio,149)) -> s/f | EZ6: =IF(p_FechaInicio="","s/f",EOMONTH(p_FechaInicio,150)) -> s/f | FA6: =IF(p_FechaInicio="","s/f",EOMONTH(p_FechaInicio,151)) -> s/f | FB6: =IF(p_FechaInicio="","s/f",EOMONTH(p_FechaInicio,152)) -> s/f | FC6: =IF(p_FechaInicio="","s/f",EOMONTH(p_FechaInicio,153)) -> s/f | FD6: =IF(p_FechaInicio="","s/f",EOMONTH(p_FechaInicio,154)) -> s/f | FE6: =IF(p_FechaInicio="","s/f",EOMONTH(p_FechaInicio,155)) -> s/f | FF6: =IF(p_FechaInicio="","s/f",EOMONTH(p_FechaInicio,156)) -> s/f
A7: anio | B7: Año de proyecto (0 = implantación) | C7: n° | F7: =IF(0<=p_ImplMeses,0,ROUNDUP((0-p_ImplMeses)/12,0)) -> 0 | G7: =IF(1<=p_ImplMeses,0,ROUNDUP((1-p_ImplMeses)/12,0)) -> 1 | H7: =IF(2<=p_ImplMeses,0,ROUNDUP((2-p_ImplMeses)/12,0)) -> 1 | I7: =IF(3<=p_ImplMeses,0,ROUNDUP((3-p_ImplMeses)/12,0)) -> 1 | J7: =IF(4<=p_ImplMeses,0,ROUNDUP((4-p_ImplMeses)/12,0)) -> 1 | K7: =IF(5<=p_ImplMeses,0,ROUNDUP((5-p_ImplMeses)/12,0)) -> 1 | L7: =IF(6<=p_ImplMeses,0,ROUNDUP((6-p_ImplMeses)/12,0)) -> 1 | M7: =IF(7<=p_ImplMeses,0,ROUNDUP((7-p_ImplMeses)/12,0)) -> 1 | N7: =IF(8<=p_ImplMeses,0,ROUNDUP((8-p_ImplMeses)/12,0)) -> 1 | O7: =IF(9<=p_ImplMeses,0,ROUNDUP((9-p_ImplMeses)/12,0)) -> 1 | P7: =IF(10<=p_ImplMeses,0,ROUNDUP((10-p_ImplMeses)/12,0)) -> 1 | Q7: =IF(11<=p_ImplMeses,0,ROUNDUP((11-p_ImplMeses)/12,0)) -> 1 | R7: =IF(12<=p_ImplMeses,0,ROUNDUP((12-p_ImplMeses)/12,0)) -> 1 | S7: =IF(13<=p_ImplMeses,0,ROUNDUP((13-p_ImplMeses)/12,0)) -> 2 | T7: =IF(14<=p_ImplMeses,0,ROUNDUP((14-p_ImplMeses)/12,0)) -> 2 | U7: =IF(15<=p_ImplMeses,0,ROUNDUP((15-p_ImplMeses)/12,0)) -> 2 | V7: =IF(16<=p_ImplMeses,0,ROUNDUP((16-p_ImplMeses)/12,0)) -> 2 | W7: =IF(17<=p_ImplMeses,0,ROUNDUP((17-p_ImplMeses)/12,0)) -> 2 | X7: =IF(18<=p_ImplMeses,0,ROUNDUP((18-p_ImplMeses)/12,0)) -> 2 | Y7: =IF(19<=p_ImplMeses,0,ROUNDUP((19-p_ImplMeses)/12,0)) -> 2 | Z7: =IF(20<=p_ImplMeses,0,ROUNDUP((20-p_ImplMeses)/12,0)) -> 2 | AA7: =IF(21<=p_ImplMeses,0,ROUNDUP((21-p_ImplMeses)/12,0)) -> 2 | AB7: =IF(22<=p_ImplMeses,0,ROUNDUP((22-p_ImplMeses)/12,0)) -> 2 | AC7: =IF(23<=p_ImplMeses,0,ROUNDUP((23-p_ImplMeses)/12,0)) -> 2 | AD7: =IF(24<=p_ImplMeses,0,ROUNDUP((24-p_ImplMeses)/12,0)) -> 2 | AE7: =IF(25<=p_ImplMeses,0,ROUNDUP((25-p_ImplMeses)/12,0)) -> 3 | AF7: =IF(26<=p_ImplMeses,0,ROUNDUP((26-p_ImplMeses)/12,0)) -> 3 | AG7: =IF(27<=p_ImplMeses,0,ROUNDUP((27-p_ImplMeses)/12,0)) -> 3 | AH7: =IF(28<=p_ImplMeses,0,ROUNDUP((28-p_ImplMeses)/12,0)) -> 3 | AI7: =IF(29<=p_ImplMeses,0,ROUNDUP((29-p_ImplMeses)/12,0)) -> 3 | AJ7: =IF(30<=p_ImplMeses,0,ROUNDUP((30-p_ImplMeses)/12,0)) -> 3 | AK7: =IF(31<=p_ImplMeses,0,ROUNDUP((31-p_ImplMeses)/12,0)) -> 3 | AL7: =IF(32<=p_ImplMeses,0,ROUNDUP((32-p_ImplMeses)/12,0)) -> 3 | AM7: =IF(33<=p_ImplMeses,0,ROUNDUP((33-p_ImplMeses)/12,0)) -> 3 | AN7: =IF(34<=p_ImplMeses,0,ROUNDUP((34-p_ImplMeses)/12,0)) -> 3 | AO7: =IF(35<=p_ImplMeses,0,ROUNDUP((35-p_ImplMeses)/12,0)) -> 3 | AP7: =IF(36<=p_ImplMeses,0,ROUNDUP((36-p_ImplMeses)/12,0)) -> 3 | AQ7: =IF(37<=p_ImplMeses,0,ROUNDUP((37-p_ImplMeses)/12,0)) -> 4 | AR7: =IF(38<=p_ImplMeses,0,ROUNDUP((38-p_ImplMeses)/12,0)) -> 4 | AS7: =IF(39<=p_ImplMeses,0,ROUNDUP((39-p_ImplMeses)/12,0)) -> 4 | AT7: =IF(40<=p_ImplMeses,0,ROUNDUP((40-p_ImplMeses)/12,0)) -> 4 | AU7: =IF(41<=p_ImplMeses,0,ROUNDUP((41-p_ImplMeses)/12,0)) -> 4 | AV7: =IF(42<=p_ImplMeses,0,ROUNDUP((42-p_ImplMeses)/12,0)) -> 4 | AW7: =IF(43<=p_ImplMeses,0,ROUNDUP((43-p_ImplMeses)/12,0)) -> 4 | AX7: =IF(44<=p_ImplMeses,0,ROUNDUP((44-p_ImplMeses)/12,0)) -> 4 | AY7: =IF(45<=p_ImplMeses,0,ROUNDUP((45-p_ImplMeses)/12,0)) -> 4 | AZ7: =IF(46<=p_ImplMeses,0,ROUNDUP((46-p_ImplMeses)/12,0)) -> 4 | BA7: =IF(47<=p_ImplMeses,0,ROUNDUP((47-p_ImplMeses)/12,0)) -> 4 | BB7: =IF(48<=p_ImplMeses,0,ROUNDUP((48-p_ImplMeses)/12,0)) -> 4 | BC7: =IF(49<=p_ImplMeses,0,ROUNDUP((49-p_ImplMeses)/12,0)) -> 5 | BD7: =IF(50<=p_ImplMeses,0,ROUNDUP((50-p_ImplMeses)/12,0)) -> 5 | BE7: =IF(51<=p_ImplMeses,0,ROUNDUP((51-p_ImplMeses)/12,0)) -> 5 | BF7: =IF(52<=p_ImplMeses,0,ROUNDUP((52-p_ImplMeses)/12,0)) -> 5 | BG7: =IF(53<=p_ImplMeses,0,ROUNDUP((53-p_ImplMeses)/12,0)) -> 5 | BH7: =IF(54<=p_ImplMeses,0,ROUNDUP((54-p_ImplMeses)/12,0)) -> 5 | BI7: =IF(55<=p_ImplMeses,0,ROUNDUP((55-p_ImplMeses)/12,0)) -> 5 | BJ7: =IF(56<=p_ImplMeses,0,ROUNDUP((56-p_ImplMeses)/12,0)) -> 5 | BK7: =IF(57<=p_ImplMeses,0,ROUNDUP((57-p_ImplMeses)/12,0)) -> 5 | BL7: =IF(58<=p_ImplMeses,0,ROUNDUP((58-p_ImplMeses)/12,0)) -> 5 | BM7: =IF(59<=p_ImplMeses,0,ROUNDUP((59-p_ImplMeses)/12,0)) -> 5 | BN7: =IF(60<=p_ImplMeses,0,ROUNDUP((60-p_ImplMeses)/12,0)) -> 5 | BO7: =IF(61<=p_ImplMeses,0,ROUNDUP((61-p_ImplMeses)/12,0)) -> 6 | BP7: =IF(62<=p_ImplMeses,0,ROUNDUP((62-p_ImplMeses)/12,0)) -> 6 | BQ7: =IF(63<=p_ImplMeses,0,ROUNDUP((63-p_ImplMeses)/12,0)) -> 6 | BR7: =IF(64<=p_ImplMeses,0,ROUNDUP((64-p_ImplMeses)/12,0)) -> 6 | BS7: =IF(65<=p_ImplMeses,0,ROUNDUP((65-p_ImplMeses)/12,0)) -> 6 | BT7: =IF(66<=p_ImplMeses,0,ROUNDUP((66-p_ImplMeses)/12,0)) -> 6 | BU7: =IF(67<=p_ImplMeses,0,ROUNDUP((67-p_ImplMeses)/12,0)) -> 6 | BV7: =IF(68<=p_ImplMeses,0,ROUNDUP((68-p_ImplMeses)/12,0)) -> 6 | BW7: =IF(69<=p_ImplMeses,0,ROUNDUP((69-p_ImplMeses)/12,0)) -> 6 | BX7: =IF(70<=p_ImplMeses,0,ROUNDUP((70-p_ImplMeses)/12,0)) -> 6 | BY7: =IF(71<=p_ImplMeses,0,ROUNDUP((71-p_ImplMeses)/12,0)) -> 6 | BZ7: =IF(72<=p_ImplMeses,0,ROUNDUP((72-p_ImplMeses)/12,0)) -> 6 | CA7: =IF(73<=p_ImplMeses,0,ROUNDUP((73-p_ImplMeses)/12,0)) -> 7 | CB7: =IF(74<=p_ImplMeses,0,ROUNDUP((74-p_ImplMeses)/12,0)) -> 7 | CC7: =IF(75<=p_ImplMeses,0,ROUNDUP((75-p_ImplMeses)/12,0)) -> 7 | CD7: =IF(76<=p_ImplMeses,0,ROUNDUP((76-p_ImplMeses)/12,0)) -> 7 | CE7: =IF(77<=p_ImplMeses,0,ROUNDUP((77-p_ImplMeses)/12,0)) -> 7 | CF7: =IF(78<=p_ImplMeses,0,ROUNDUP((78-p_ImplMeses)/12,0)) -> 7 | CG7: =IF(79<=p_ImplMeses,0,ROUNDUP((79-p_ImplMeses)/12,0)) -> 7 | CH7: =IF(80<=p_ImplMeses,0,ROUNDUP((80-p_ImplMeses)/12,0)) -> 7 | CI7: =IF(81<=p_ImplMeses,0,ROUNDUP((81-p_ImplMeses)/12,0)) -> 7 | CJ7: =IF(82<=p_ImplMeses,0,ROUNDUP((82-p_ImplMeses)/12,0)) -> 7 | CK7: =IF(83<=p_ImplMeses,0,ROUNDUP((83-p_ImplMeses)/12,0)) -> 7 | CL7: =IF(84<=p_ImplMeses,0,ROUNDUP((84-p_ImplMeses)/12,0)) -> 7 | CM7: =IF(85<=p_ImplMeses,0,ROUNDUP((85-p_ImplMeses)/12,0)) -> 8 | CN7: =IF(86<=p_ImplMeses,0,ROUNDUP((86-p_ImplMeses)/12,0)) -> 8 | CO7: =IF(87<=p_ImplMeses,0,ROUNDUP((87-p_ImplMeses)/12,0)) -> 8 | CP7: =IF(88<=p_ImplMeses,0,ROUNDUP((88-p_ImplMeses)/12,0)) -> 8 | CQ7: =IF(89<=p_ImplMeses,0,ROUNDUP((89-p_ImplMeses)/12,0)) -> 8 | CR7: =IF(90<=p_ImplMeses,0,ROUNDUP((90-p_ImplMeses)/12,0)) -> 8 | CS7: =IF(91<=p_ImplMeses,0,ROUNDUP((91-p_ImplMeses)/12,0)) -> 8 | CT7: =IF(92<=p_ImplMeses,0,ROUNDUP((92-p_ImplMeses)/12,0)) -> 8 | CU7: =IF(93<=p_ImplMeses,0,ROUNDUP((93-p_ImplMeses)/12,0)) -> 8 | CV7: =IF(94<=p_ImplMeses,0,ROUNDUP((94-p_ImplMeses)/12,0)) -> 8 | CW7: =IF(95<=p_ImplMeses,0,ROUNDUP((95-p_ImplMeses)/12,0)) -> 8 | CX7: =IF(96<=p_ImplMeses,0,ROUNDUP((96-p_ImplMeses)/12,0)) -> 8 | CY7: =IF(97<=p_ImplMeses,0,ROUNDUP((97-p_ImplMeses)/12,0)) -> 9 | CZ7: =IF(98<=p_ImplMeses,0,ROUNDUP((98-p_ImplMeses)/12,0)) -> 9 | DA7: =IF(99<=p_ImplMeses,0,ROUNDUP((99-p_ImplMeses)/12,0)) -> 9 | DB7: =IF(100<=p_ImplMeses,0,ROUNDUP((100-p_ImplMeses)/12,0)) -> 9 | DC7: =IF(101<=p_ImplMeses,0,ROUNDUP((101-p_ImplMeses)/12,0)) -> 9 | DD7: =IF(102<=p_ImplMeses,0,ROUNDUP((102-p_ImplMeses)/12,0)) -> 9 | DE7: =IF(103<=p_ImplMeses,0,ROUNDUP((103-p_ImplMeses)/12,0)) -> 9 | DF7: =IF(104<=p_ImplMeses,0,ROUNDUP((104-p_ImplMeses)/12,0)) -> 9 | DG7: =IF(105<=p_ImplMeses,0,ROUNDUP((105-p_ImplMeses)/12,0)) -> 9 | DH7: =IF(106<=p_ImplMeses,0,ROUNDUP((106-p_ImplMeses)/12,0)) -> 9 | DI7: =IF(107<=p_ImplMeses,0,ROUNDUP((107-p_ImplMeses)/12,0)) -> 9 | DJ7: =IF(108<=p_ImplMeses,0,ROUNDUP((108-p_ImplMeses)/12,0)) -> 9 | DK7: =IF(109<=p_ImplMeses,0,ROUNDUP((109-p_ImplMeses)/12,0)) -> 10 | DL7: =IF(110<=p_ImplMeses,0,ROUNDUP((110-p_ImplMeses)/12,0)) -> 10 | DM7: =IF(111<=p_ImplMeses,0,ROUNDUP((111-p_ImplMeses)/12,0)) -> 10 | DN7: =IF(112<=p_ImplMeses,0,ROUNDUP((112-p_ImplMeses)/12,0)) -> 10 | DO7: =IF(113<=p_ImplMeses,0,ROUNDUP((113-p_ImplMeses)/12,0)) -> 10 | DP7: =IF(114<=p_ImplMeses,0,ROUNDUP((114-p_ImplMeses)/12,0)) -> 10 | DQ7: =IF(115<=p_ImplMeses,0,ROUNDUP((115-p_ImplMeses)/12,0)) -> 10 | DR7: =IF(116<=p_ImplMeses,0,ROUNDUP((116-p_ImplMeses)/12,0)) -> 10 | DS7: =IF(117<=p_ImplMeses,0,ROUNDUP((117-p_ImplMeses)/12,0)) -> 10 | DT7: =IF(118<=p_ImplMeses,0,ROUNDUP((118-p_ImplMeses)/12,0)) -> 10 | DU7: =IF(119<=p_ImplMeses,0,ROUNDUP((119-p_ImplMeses)/12,0)) -> 10 | DV7: =IF(120<=p_ImplMeses,0,ROUNDUP((120-p_ImplMeses)/12,0)) -> 10 | DW7: =IF(121<=p_ImplMeses,0,ROUNDUP((121-p_ImplMeses)/12,0)) -> 11 | DX7: =IF(122<=p_ImplMeses,0,ROUNDUP((122-p_ImplMeses)/12,0)) -> 11 | DY7: =IF(123<=p_ImplMeses,0,ROUNDUP((123-p_ImplMeses)/12,0)) -> 11 | DZ7: =IF(124<=p_ImplMeses,0,ROUNDUP((124-p_ImplMeses)/12,0)) -> 11 | EA7: =IF(125<=p_ImplMeses,0,ROUNDUP((125-p_ImplMeses)/12,0)) -> 11 | EB7: =IF(126<=p_ImplMeses,0,ROUNDUP((126-p_ImplMeses)/12,0)) -> 11 | EC7: =IF(127<=p_ImplMeses,0,ROUNDUP((127-p_ImplMeses)/12,0)) -> 11 | ED7: =IF(128<=p_ImplMeses,0,ROUNDUP((128-p_ImplMeses)/12,0)) -> 11 | EE7: =IF(129<=p_ImplMeses,0,ROUNDUP((129-p_ImplMeses)/12,0)) -> 11 | EF7: =IF(130<=p_ImplMeses,0,ROUNDUP((130-p_ImplMeses)/12,0)) -> 11 | EG7: =IF(131<=p_ImplMeses,0,ROUNDUP((131-p_ImplMeses)/12,0)) -> 11 | EH7: =IF(132<=p_ImplMeses,0,ROUNDUP((132-p_ImplMeses)/12,0)) -> 11 | EI7: =IF(133<=p_ImplMeses,0,ROUNDUP((133-p_ImplMeses)/12,0)) -> 12 | EJ7: =IF(134<=p_ImplMeses,0,ROUNDUP((134-p_ImplMeses)/12,0)) -> 12 | EK7: =IF(135<=p_ImplMeses,0,ROUNDUP((135-p_ImplMeses)/12,0)) -> 12 | EL7: =IF(136<=p_ImplMeses,0,ROUNDUP((136-p_ImplMeses)/12,0)) -> 12 | EM7: =IF(137<=p_ImplMeses,0,ROUNDUP((137-p_ImplMeses)/12,0)) -> 12 | EN7: =IF(138<=p_ImplMeses,0,ROUNDUP((138-p_ImplMeses)/12,0)) -> 12 | EO7: =IF(139<=p_ImplMeses,0,ROUNDUP((139-p_ImplMeses)/12,0)) -> 12 | EP7: =IF(140<=p_ImplMeses,0,ROUNDUP((140-p_ImplMeses)/12,0)) -> 12 | EQ7: =IF(141<=p_ImplMeses,0,ROUNDUP((141-p_ImplMeses)/12,0)) -> 12 | ER7: =IF(142<=p_ImplMeses,0,ROUNDUP((142-p_ImplMeses)/12,0)) -> 12 | ES7: =IF(143<=p_ImplMeses,0,ROUNDUP((143-p_ImplMeses)/12,0)) -> 12 | ET7: =IF(144<=p_ImplMeses,0,ROUNDUP((144-p_ImplMeses)/12,0)) -> 12 | EU7: =IF(145<=p_ImplMeses,0,ROUNDUP((145-p_ImplMeses)/12,0)) -> 13 | EV7: =IF(146<=p_ImplMeses,0,ROUNDUP((146-p_ImplMeses)/12,0)) -> 13 | EW7: =IF(147<=p_ImplMeses,0,ROUNDUP((147-p_ImplMeses)/12,0)) -> 13 | EX7: =IF(148<=p_ImplMeses,0,ROUNDUP((148-p_ImplMeses)/12,0)) -> 13 | EY7: =IF(149<=p_ImplMeses,0,ROUNDUP((149-p_ImplMeses)/12,0)) -> 13 | EZ7: =IF(150<=p_ImplMeses,0,ROUNDUP((150-p_ImplMeses)/12,0)) -> 13 | FA7: =IF(151<=p_ImplMeses,0,ROUNDUP((151-p_ImplMeses)/12,0)) -> 13 | FB7: =IF(152<=p_ImplMeses,0,ROUNDUP((152-p_ImplMeses)/12,0)) -> 13 | FC7: =IF(153<=p_ImplMeses,0,ROUNDUP((153-p_ImplMeses)/12,0)) -> 13 | FD7: =IF(154<=p_ImplMeses,0,ROUNDUP((154-p_ImplMeses)/12,0)) -> 13 | FE7: =IF(155<=p_ImplMeses,0,ROUNDUP((155-p_ImplMeses)/12,0)) -> 13 | FF7: =IF(156<=p_ImplMeses,0,ROUNDUP((156-p_ImplMeses)/12,0)) -> 13
A8: ini | B8: Inicio de año de proyecto (1/0) | C8: 1/0 | F8: =IF(AND(0>p_ImplMeses,MOD(0-p_ImplMeses-1,12)=0),1,0) -> 0 | G8: =IF(AND(1>p_ImplMeses,MOD(1-p_ImplMeses-1,12)=0),1,0) -> 1 | H8: =IF(AND(2>p_ImplMeses,MOD(2-p_ImplMeses-1,12)=0),1,0) -> 0 | I8: =IF(AND(3>p_ImplMeses,MOD(3-p_ImplMeses-1,12)=0),1,0) -> 0 | J8: =IF(AND(4>p_ImplMeses,MOD(4-p_ImplMeses-1,12)=0),1,0) -> 0 | K8: =IF(AND(5>p_ImplMeses,MOD(5-p_ImplMeses-1,12)=0),1,0) -> 0 | L8: =IF(AND(6>p_ImplMeses,MOD(6-p_ImplMeses-1,12)=0),1,0) -> 0 | M8: =IF(AND(7>p_ImplMeses,MOD(7-p_ImplMeses-1,12)=0),1,0) -> 0 | N8: =IF(AND(8>p_ImplMeses,MOD(8-p_ImplMeses-1,12)=0),1,0) -> 0 | O8: =IF(AND(9>p_ImplMeses,MOD(9-p_ImplMeses-1,12)=0),1,0) -> 0 | P8: =IF(AND(10>p_ImplMeses,MOD(10-p_ImplMeses-1,12)=0),1,0) -> 0 | Q8: =IF(AND(11>p_ImplMeses,MOD(11-p_ImplMeses-1,12)=0),1,0) -> 0 | R8: =IF(AND(12>p_ImplMeses,MOD(12-p_ImplMeses-1,12)=0),1,0) -> 0 | S8: =IF(AND(13>p_ImplMeses,MOD(13-p_ImplMeses-1,12)=0),1,0) -> 1 | T8: =IF(AND(14>p_ImplMeses,MOD(14-p_ImplMeses-1,12)=0),1,0) -> 0 | U8: =IF(AND(15>p_ImplMeses,MOD(15-p_ImplMeses-1,12)=0),1,0) -> 0 | V8: =IF(AND(16>p_ImplMeses,MOD(16-p_ImplMeses-1,12)=0),1,0) -> 0 | W8: =IF(AND(17>p_ImplMeses,MOD(17-p_ImplMeses-1,12)=0),1,0) -> 0 | X8: =IF(AND(18>p_ImplMeses,MOD(18-p_ImplMeses-1,12)=0),1,0) -> 0 | Y8: =IF(AND(19>p_ImplMeses,MOD(19-p_ImplMeses-1,12)=0),1,0) -> 0 | Z8: =IF(AND(20>p_ImplMeses,MOD(20-p_ImplMeses-1,12)=0),1,0) -> 0 | AA8: =IF(AND(21>p_ImplMeses,MOD(21-p_ImplMeses-1,12)=0),1,0) -> 0 | AB8: =IF(AND(22>p_ImplMeses,MOD(22-p_ImplMeses-1,12)=0),1,0) -> 0 | AC8: =IF(AND(23>p_ImplMeses,MOD(23-p_ImplMeses-1,12)=0),1,0) -> 0 | AD8: =IF(AND(24>p_ImplMeses,MOD(24-p_ImplMeses-1,12)=0),1,0) -> 0 | AE8: =IF(AND(25>p_ImplMeses,MOD(25-p_ImplMeses-1,12)=0),1,0) -> 1 | AF8: =IF(AND(26>p_ImplMeses,MOD(26-p_ImplMeses-1,12)=0),1,0) -> 0 | AG8: =IF(AND(27>p_ImplMeses,MOD(27-p_ImplMeses-1,12)=0),1,0) -> 0 | AH8: =IF(AND(28>p_ImplMeses,MOD(28-p_ImplMeses-1,12)=0),1,0) -> 0 | AI8: =IF(AND(29>p_ImplMeses,MOD(29-p_ImplMeses-1,12)=0),1,0) -> 0 | AJ8: =IF(AND(30>p_ImplMeses,MOD(30-p_ImplMeses-1,12)=0),1,0) -> 0 | AK8: =IF(AND(31>p_ImplMeses,MOD(31-p_ImplMeses-1,12)=0),1,0) -> 0 | AL8: =IF(AND(32>p_ImplMeses,MOD(32-p_ImplMeses-1,12)=0),1,0) -> 0 | AM8: =IF(AND(33>p_ImplMeses,MOD(33-p_ImplMeses-1,12)=0),1,0) -> 0 | AN8: =IF(AND(34>p_ImplMeses,MOD(34-p_ImplMeses-1,12)=0),1,0) -> 0 | AO8: =IF(AND(35>p_ImplMeses,MOD(35-p_ImplMeses-1,12)=0),1,0) -> 0 | AP8: =IF(AND(36>p_ImplMeses,MOD(36-p_ImplMeses-1,12)=0),1,0) -> 0 | AQ8: =IF(AND(37>p_ImplMeses,MOD(37-p_ImplMeses-1,12)=0),1,0) -> 1 | AR8: =IF(AND(38>p_ImplMeses,MOD(38-p_ImplMeses-1,12)=0),1,0) -> 0 | AS8: =IF(AND(39>p_ImplMeses,MOD(39-p_ImplMeses-1,12)=0),1,0) -> 0 | AT8: =IF(AND(40>p_ImplMeses,MOD(40-p_ImplMeses-1,12)=0),1,0) -> 0 | AU8: =IF(AND(41>p_ImplMeses,MOD(41-p_ImplMeses-1,12)=0),1,0) -> 0 | AV8: =IF(AND(42>p_ImplMeses,MOD(42-p_ImplMeses-1,12)=0),1,0) -> 0 | AW8: =IF(AND(43>p_ImplMeses,MOD(43-p_ImplMeses-1,12)=0),1,0) -> 0 | AX8: =IF(AND(44>p_ImplMeses,MOD(44-p_ImplMeses-1,12)=0),1,0) -> 0 | AY8: =IF(AND(45>p_ImplMeses,MOD(45-p_ImplMeses-1,12)=0),1,0) -> 0 | AZ8: =IF(AND(46>p_ImplMeses,MOD(46-p_ImplMeses-1,12)=0),1,0) -> 0 | BA8: =IF(AND(47>p_ImplMeses,MOD(47-p_ImplMeses-1,12)=0),1,0) -> 0 | BB8: =IF(AND(48>p_ImplMeses,MOD(48-p_ImplMeses-1,12)=0),1,0) -> 0 | BC8: =IF(AND(49>p_ImplMeses,MOD(49-p_ImplMeses-1,12)=0),1,0) -> 1 | BD8: =IF(AND(50>p_ImplMeses,MOD(50-p_ImplMeses-1,12)=0),1,0) -> 0 | BE8: =IF(AND(51>p_ImplMeses,MOD(51-p_ImplMeses-1,12)=0),1,0) -> 0 | BF8: =IF(AND(52>p_ImplMeses,MOD(52-p_ImplMeses-1,12)=0),1,0) -> 0 | BG8: =IF(AND(53>p_ImplMeses,MOD(53-p_ImplMeses-1,12)=0),1,0) -> 0 | BH8: =IF(AND(54>p_ImplMeses,MOD(54-p_ImplMeses-1,12)=0),1,0) -> 0 | BI8: =IF(AND(55>p_ImplMeses,MOD(55-p_ImplMeses-1,12)=0),1,0) -> 0 | BJ8: =IF(AND(56>p_ImplMeses,MOD(56-p_ImplMeses-1,12)=0),1,0) -> 0 | BK8: =IF(AND(57>p_ImplMeses,MOD(57-p_ImplMeses-1,12)=0),1,0) -> 0 | BL8: =IF(AND(58>p_ImplMeses,MOD(58-p_ImplMeses-1,12)=0),1,0) -> 0 | BM8: =IF(AND(59>p_ImplMeses,MOD(59-p_ImplMeses-1,12)=0),1,0) -> 0 | BN8: =IF(AND(60>p_ImplMeses,MOD(60-p_ImplMeses-1,12)=0),1,0) -> 0 | BO8: =IF(AND(61>p_ImplMeses,MOD(61-p_ImplMeses-1,12)=0),1,0) -> 1 | BP8: =IF(AND(62>p_ImplMeses,MOD(62-p_ImplMeses-1,12)=0),1,0) -> 0 | BQ8: =IF(AND(63>p_ImplMeses,MOD(63-p_ImplMeses-1,12)=0),1,0) -> 0 | BR8: =IF(AND(64>p_ImplMeses,MOD(64-p_ImplMeses-1,12)=0),1,0) -> 0 | BS8: =IF(AND(65>p_ImplMeses,MOD(65-p_ImplMeses-1,12)=0),1,0) -> 0 | BT8: =IF(AND(66>p_ImplMeses,MOD(66-p_ImplMeses-1,12)=0),1,0) -> 0 | BU8: =IF(AND(67>p_ImplMeses,MOD(67-p_ImplMeses-1,12)=0),1,0) -> 0 | BV8: =IF(AND(68>p_ImplMeses,MOD(68-p_ImplMeses-1,12)=0),1,0) -> 0 | BW8: =IF(AND(69>p_ImplMeses,MOD(69-p_ImplMeses-1,12)=0),1,0) -> 0 | BX8: =IF(AND(70>p_ImplMeses,MOD(70-p_ImplMeses-1,12)=0),1,0) -> 0 | BY8: =IF(AND(71>p_ImplMeses,MOD(71-p_ImplMeses-1,12)=0),1,0) -> 0 | BZ8: =IF(AND(72>p_ImplMeses,MOD(72-p_ImplMeses-1,12)=0),1,0) -> 0 | CA8: =IF(AND(73>p_ImplMeses,MOD(73-p_ImplMeses-1,12)=0),1,0) -> 1 | CB8: =IF(AND(74>p_ImplMeses,MOD(74-p_ImplMeses-1,12)=0),1,0) -> 0 | CC8: =IF(AND(75>p_ImplMeses,MOD(75-p_ImplMeses-1,12)=0),1,0) -> 0 | CD8: =IF(AND(76>p_ImplMeses,MOD(76-p_ImplMeses-1,12)=0),1,0) -> 0 | CE8: =IF(AND(77>p_ImplMeses,MOD(77-p_ImplMeses-1,12)=0),1,0) -> 0 | CF8: =IF(AND(78>p_ImplMeses,MOD(78-p_ImplMeses-1,12)=0),1,0) -> 0 | CG8: =IF(AND(79>p_ImplMeses,MOD(79-p_ImplMeses-1,12)=0),1,0) -> 0 | CH8: =IF(AND(80>p_ImplMeses,MOD(80-p_ImplMeses-1,12)=0),1,0) -> 0 | CI8: =IF(AND(81>p_ImplMeses,MOD(81-p_ImplMeses-1,12)=0),1,0) -> 0 | CJ8: =IF(AND(82>p_ImplMeses,MOD(82-p_ImplMeses-1,12)=0),1,0) -> 0 | CK8: =IF(AND(83>p_ImplMeses,MOD(83-p_ImplMeses-1,12)=0),1,0) -> 0 | CL8: =IF(AND(84>p_ImplMeses,MOD(84-p_ImplMeses-1,12)=0),1,0) -> 0 | CM8: =IF(AND(85>p_ImplMeses,MOD(85-p_ImplMeses-1,12)=0),1,0) -> 1 | CN8: =IF(AND(86>p_ImplMeses,MOD(86-p_ImplMeses-1,12)=0),1,0) -> 0 | CO8: =IF(AND(87>p_ImplMeses,MOD(87-p_ImplMeses-1,12)=0),1,0) -> 0 | CP8: =IF(AND(88>p_ImplMeses,MOD(88-p_ImplMeses-1,12)=0),1,0) -> 0 | CQ8: =IF(AND(89>p_ImplMeses,MOD(89-p_ImplMeses-1,12)=0),1,0) -> 0 | CR8: =IF(AND(90>p_ImplMeses,MOD(90-p_ImplMeses-1,12)=0),1,0) -> 0 | CS8: =IF(AND(91>p_ImplMeses,MOD(91-p_ImplMeses-1,12)=0),1,0) -> 0 | CT8: =IF(AND(92>p_ImplMeses,MOD(92-p_ImplMeses-1,12)=0),1,0) -> 0 | CU8: =IF(AND(93>p_ImplMeses,MOD(93-p_ImplMeses-1,12)=0),1,0) -> 0 | CV8: =IF(AND(94>p_ImplMeses,MOD(94-p_ImplMeses-1,12)=0),1,0) -> 0 | CW8: =IF(AND(95>p_ImplMeses,MOD(95-p_ImplMeses-1,12)=0),1,0) -> 0 | CX8: =IF(AND(96>p_ImplMeses,MOD(96-p_ImplMeses-1,12)=0),1,0) -> 0 | CY8: =IF(AND(97>p_ImplMeses,MOD(97-p_ImplMeses-1,12)=0),1,0) -> 1 | CZ8: =IF(AND(98>p_ImplMeses,MOD(98-p_ImplMeses-1,12)=0),1,0) -> 0 | DA8: =IF(AND(99>p_ImplMeses,MOD(99-p_ImplMeses-1,12)=0),1,0) -> 0 | DB8: =IF(AND(100>p_ImplMeses,MOD(100-p_ImplMeses-1,12)=0),1,0) -> 0 | DC8: =IF(AND(101>p_ImplMeses,MOD(101-p_ImplMeses-1,12)=0),1,0) -> 0 | DD8: =IF(AND(102>p_ImplMeses,MOD(102-p_ImplMeses-1,12)=0),1,0) -> 0 | DE8: =IF(AND(103>p_ImplMeses,MOD(103-p_ImplMeses-1,12)=0),1,0) -> 0 | DF8: =IF(AND(104>p_ImplMeses,MOD(104-p_ImplMeses-1,12)=0),1,0) -> 0 | DG8: =IF(AND(105>p_ImplMeses,MOD(105-p_ImplMeses-1,12)=0),1,0) -> 0 | DH8: =IF(AND(106>p_ImplMeses,MOD(106-p_ImplMeses-1,12)=0),1,0) -> 0 | DI8: =IF(AND(107>p_ImplMeses,MOD(107-p_ImplMeses-1,12)=0),1,0) -> 0 | DJ8: =IF(AND(108>p_ImplMeses,MOD(108-p_ImplMeses-1,12)=0),1,0) -> 0 | DK8: =IF(AND(109>p_ImplMeses,MOD(109-p_ImplMeses-1,12)=0),1,0) -> 1 | DL8: =IF(AND(110>p_ImplMeses,MOD(110-p_ImplMeses-1,12)=0),1,0) -> 0 | DM8: =IF(AND(111>p_ImplMeses,MOD(111-p_ImplMeses-1,12)=0),1,0) -> 0 | DN8: =IF(AND(112>p_ImplMeses,MOD(112-p_ImplMeses-1,12)=0),1,0) -> 0 | DO8: =IF(AND(113>p_ImplMeses,MOD(113-p_ImplMeses-1,12)=0),1,0) -> 0 | DP8: =IF(AND(114>p_ImplMeses,MOD(114-p_ImplMeses-1,12)=0),1,0) -> 0 | DQ8: =IF(AND(115>p_ImplMeses,MOD(115-p_ImplMeses-1,12)=0),1,0) -> 0 | DR8: =IF(AND(116>p_ImplMeses,MOD(116-p_ImplMeses-1,12)=0),1,0) -> 0 | DS8: =IF(AND(117>p_ImplMeses,MOD(117-p_ImplMeses-1,12)=0),1,0) -> 0 | DT8: =IF(AND(118>p_ImplMeses,MOD(118-p_ImplMeses-1,12)=0),1,0) -> 0 | DU8: =IF(AND(119>p_ImplMeses,MOD(119-p_ImplMeses-1,12)=0),1,0) -> 0 | DV8: =IF(AND(120>p_ImplMeses,MOD(120-p_ImplMeses-1,12)=0),1,0) -> 0 | DW8: =IF(AND(121>p_ImplMeses,MOD(121-p_ImplMeses-1,12)=0),1,0) -> 1 | DX8: =IF(AND(122>p_ImplMeses,MOD(122-p_ImplMeses-1,12)=0),1,0) -> 0 | DY8: =IF(AND(123>p_ImplMeses,MOD(123-p_ImplMeses-1,12)=0),1,0) -> 0 | DZ8: =IF(AND(124>p_ImplMeses,MOD(124-p_ImplMeses-1,12)=0),1,0) -> 0 | EA8: =IF(AND(125>p_ImplMeses,MOD(125-p_ImplMeses-1,12)=0),1,0) -> 0 | EB8: =IF(AND(126>p_ImplMeses,MOD(126-p_ImplMeses-1,12)=0),1,0) -> 0 | EC8: =IF(AND(127>p_ImplMeses,MOD(127-p_ImplMeses-1,12)=0),1,0) -> 0 | ED8: =IF(AND(128>p_ImplMeses,MOD(128-p_ImplMeses-1,12)=0),1,0) -> 0 | EE8: =IF(AND(129>p_ImplMeses,MOD(129-p_ImplMeses-1,12)=0),1,0) -> 0 | EF8: =IF(AND(130>p_ImplMeses,MOD(130-p_ImplMeses-1,12)=0),1,0) -> 0 | EG8: =IF(AND(131>p_ImplMeses,MOD(131-p_ImplMeses-1,12)=0),1,0) -> 0 | EH8: =IF(AND(132>p_ImplMeses,MOD(132-p_ImplMeses-1,12)=0),1,0) -> 0 | EI8: =IF(AND(133>p_ImplMeses,MOD(133-p_ImplMeses-1,12)=0),1,0) -> 1 | EJ8: =IF(AND(134>p_ImplMeses,MOD(134-p_ImplMeses-1,12)=0),1,0) -> 0 | EK8: =IF(AND(135>p_ImplMeses,MOD(135-p_ImplMeses-1,12)=0),1,0) -> 0 | EL8: =IF(AND(136>p_ImplMeses,MOD(136-p_ImplMeses-1,12)=0),1,0) -> 0 | EM8: =IF(AND(137>p_ImplMeses,MOD(137-p_ImplMeses-1,12)=0),1,0) -> 0 | EN8: =IF(AND(138>p_ImplMeses,MOD(138-p_ImplMeses-1,12)=0),1,0) -> 0 | EO8: =IF(AND(139>p_ImplMeses,MOD(139-p_ImplMeses-1,12)=0),1,0) -> 0 | EP8: =IF(AND(140>p_ImplMeses,MOD(140-p_ImplMeses-1,12)=0),1,0) -> 0 | EQ8: =IF(AND(141>p_ImplMeses,MOD(141-p_ImplMeses-1,12)=0),1,0) -> 0 | ER8: =IF(AND(142>p_ImplMeses,MOD(142-p_ImplMeses-1,12)=0),1,0) -> 0 | ES8: =IF(AND(143>p_ImplMeses,MOD(143-p_ImplMeses-1,12)=0),1,0) -> 0 | ET8: =IF(AND(144>p_ImplMeses,MOD(144-p_ImplMeses-1,12)=0),1,0) -> 0 | EU8: =IF(AND(145>p_ImplMeses,MOD(145-p_ImplMeses-1,12)=0),1,0) -> 1 | EV8: =IF(AND(146>p_ImplMeses,MOD(146-p_ImplMeses-1,12)=0),1,0) -> 0 | EW8: =IF(AND(147>p_ImplMeses,MOD(147-p_ImplMeses-1,12)=0),1,0) -> 0 | EX8: =IF(AND(148>p_ImplMeses,MOD(148-p_ImplMeses-1,12)=0),1,0) -> 0 | EY8: =IF(AND(149>p_ImplMeses,MOD(149-p_ImplMeses-1,12)=0),1,0) -> 0 | EZ8: =IF(AND(150>p_ImplMeses,MOD(150-p_ImplMeses-1,12)=0),1,0) -> 0 | FA8: =IF(AND(151>p_ImplMeses,MOD(151-p_ImplMeses-1,12)=0),1,0) -> 0 | FB8: =IF(AND(152>p_ImplMeses,MOD(152-p_ImplMeses-1,12)=0),1,0) -> 0 | FC8: =IF(AND(153>p_ImplMeses,MOD(153-p_ImplMeses-1,12)=0),1,0) -> 0 | FD8: =IF(AND(154>p_ImplMeses,MOD(154-p_ImplMeses-1,12)=0),1,0) -> 0 | FE8: =IF(AND(155>p_ImplMeses,MOD(155-p_ImplMeses-1,12)=0),1,0) -> 0 | FF8: =IF(AND(156>p_ImplMeses,MOD(156-p_ImplMeses-1,12)=0),1,0) -> 0
